2024-09-29 15:29:10,402 INFO    StreamThr :2235191 [internal.py:wandb_internal():85] W&B internal server running at pid: 2235191, started at: 2024-09-29 15:29:10.401246
2024-09-29 15:29:10,403 DEBUG   HandlerThread:2235191 [handler.py:handle_request():158] handle_request: status
2024-09-29 15:29:10,418 INFO    WriterThread:2235191 [datastore.py:open_for_write():87] open: /home/yyang-infobai/AVDC_whl/flowdiffusion/wandb/run-20240929_152910-doy8fsug/run-doy8fsug.wandb
2024-09-29 15:29:10,421 DEBUG   SenderThread:2235191 [sender.py:send():391] send: header
2024-09-29 15:29:10,460 DEBUG   SenderThread:2235191 [sender.py:send():391] send: run
2024-09-29 15:29:10,891 ERROR   SenderThread:2235191 [internal_api.py:execute():349] 404 response executing GraphQL.
2024-09-29 15:29:10,891 ERROR   SenderThread:2235191 [internal_api.py:execute():350] {"errors":[{"message":"project not found","path":["upsertBucket"]}],"data":{"upsertBucket":null}}
2024-09-29 15:29:10,892 ERROR   SenderThread:2235191 [sender.py:send_run():1021] It appears that you do not have permission to access the requested resource. Please reach out to the project owner to grant you access. If you have the correct permissions, verify that there are no issues with your networking setup.(Error 404: Not Found)
Traceback (most recent call last):
  File "/group/ycyang/anaconda3/envs/avdc/lib/python3.9/site-packages/wandb/sdk/lib/retry.py", line 131, in __call__
    result = self._call_fn(*args, **kwargs)
  File "/group/ycyang/anaconda3/envs/avdc/lib/python3.9/site-packages/wandb/sdk/internal/internal_api.py", line 345, in execute
    return self.client.execute(*args, **kwargs)  # type: ignore
  File "/group/ycyang/anaconda3/envs/avdc/lib/python3.9/site-packages/wandb/vendor/gql-0.2.0/wandb_gql/client.py", line 52, in execute
    result = self._get_result(document, *args, **kwargs)
  File "/group/ycyang/anaconda3/envs/avdc/lib/python3.9/site-packages/wandb/vendor/gql-0.2.0/wandb_gql/client.py", line 60, in _get_result
    return self.transport.execute(document, *args, **kwargs)
  File "/group/ycyang/anaconda3/envs/avdc/lib/python3.9/site-packages/wandb/sdk/lib/gql_request.py", line 59, in execute
    request.raise_for_status()
  File "/group/ycyang/anaconda3/envs/avdc/lib/python3.9/site-packages/requests/models.py", line 1024, in raise_for_status
    raise HTTPError(http_error_msg, response=self)
requests.exceptions.HTTPError: 404 Client Error: Not Found for url: https://api.wandb.ai/graphql

During handling of the above exception, another exception occurred:

Traceback (most recent call last):
  File "/group/ycyang/anaconda3/envs/avdc/lib/python3.9/site-packages/wandb/sdk/internal/sender.py", line 1019, in send_run
    server_run = self._init_run(run, config_value_dict)
  File "/group/ycyang/anaconda3/envs/avdc/lib/python3.9/site-packages/wandb/sdk/internal/sender.py", line 1091, in _init_run
    server_run, inserted, server_messages = self._api.upsert_run(
  File "/group/ycyang/anaconda3/envs/avdc/lib/python3.9/site-packages/wandb/apis/normalize.py", line 73, in wrapper
    raise err
  File "/group/ycyang/anaconda3/envs/avdc/lib/python3.9/site-packages/wandb/apis/normalize.py", line 41, in wrapper
    return func(*args, **kwargs)
  File "/group/ycyang/anaconda3/envs/avdc/lib/python3.9/site-packages/wandb/sdk/internal/internal_api.py", line 2224, in upsert_run
    response = self.gql(
  File "/group/ycyang/anaconda3/envs/avdc/lib/python3.9/site-packages/wandb/sdk/internal/internal_api.py", line 317, in gql
    ret = self._retry_gql(
  File "/group/ycyang/anaconda3/envs/avdc/lib/python3.9/site-packages/wandb/sdk/lib/retry.py", line 147, in __call__
    retry_timedelta_triggered = check_retry_fn(e)
  File "/group/ycyang/anaconda3/envs/avdc/lib/python3.9/site-packages/wandb/util.py", line 968, in check_retry_fn
    return fallback_retry_fn(e)
  File "/group/ycyang/anaconda3/envs/avdc/lib/python3.9/site-packages/wandb/util.py", line 910, in no_retry_auth
    raise CommError(
wandb.errors.CommError: It appears that you do not have permission to access the requested resource. Please reach out to the project owner to grant you access. If you have the correct permissions, verify that there are no issues with your networking setup.(Error 404: Not Found)
2024-09-29 15:29:11,016 DEBUG   HandlerThread:2235191 [handler.py:handle_request():158] handle_request: shutdown
2024-09-29 15:29:11,016 INFO    HandlerThread:2235191 [handler.py:finish():882] shutting down handler
2024-09-29 15:29:11,460 INFO    WriterThread:2235191 [datastore.py:close():296] close: /home/yyang-infobai/AVDC_whl/flowdiffusion/wandb/run-20240929_152910-doy8fsug/run-doy8fsug.wandb
2024-09-29 15:29:11,898 INFO    SenderThread:2235191 [sender.py:finish():1631] shutting down sender
