2024-11-27 15:02:36,349 INFO    StreamThr :1062329 [internal.py:wandb_internal():85] W&B internal server running at pid: 1062329, started at: 2024-11-27 15:02:36.348408
2024-11-27 15:02:36,350 DEBUG   HandlerThread:1062329 [handler.py:handle_request():158] handle_request: status
2024-11-27 15:02:36,358 INFO    WriterThread:1062329 [datastore.py:open_for_write():87] open: /home/yyang-infobai/AVDC_whl/flowdiffusion/wandb/run-20241127_150236-bqglt27g/run-bqglt27g.wandb
2024-11-27 15:02:36,359 DEBUG   SenderThread:1062329 [sender.py:send():391] send: header
2024-11-27 15:02:36,380 DEBUG   SenderThread:1062329 [sender.py:send():391] send: run
2024-11-27 15:02:39,874 INFO    SenderThread:1062329 [retry.py:__call__():172] Retry attempt failed:
Traceback (most recent call last):
  File "/group/ycyang/anaconda3/envs/avdc/lib/python3.9/site-packages/urllib3/connection.py", line 196, in _new_conn
    sock = connection.create_connection(
  File "/group/ycyang/anaconda3/envs/avdc/lib/python3.9/site-packages/urllib3/util/connection.py", line 60, in create_connection
    for res in socket.getaddrinfo(host, port, family, socket.SOCK_STREAM):
  File "/group/ycyang/anaconda3/envs/avdc/lib/python3.9/socket.py", line 954, in getaddrinfo
    for res in _socket.getaddrinfo(host, port, family, type, proto, flags):
socket.gaierror: [Errno -2] Name or service not known

The above exception was the direct cause of the following exception:

Traceback (most recent call last):
  File "/group/ycyang/anaconda3/envs/avdc/lib/python3.9/site-packages/urllib3/connectionpool.py", line 775, in urlopen
    self._prepare_proxy(conn)
  File "/group/ycyang/anaconda3/envs/avdc/lib/python3.9/site-packages/urllib3/connectionpool.py", line 1044, in _prepare_proxy
    conn.connect()
  File "/group/ycyang/anaconda3/envs/avdc/lib/python3.9/site-packages/urllib3/connection.py", line 615, in connect
    self.sock = sock = self._new_conn()
  File "/group/ycyang/anaconda3/envs/avdc/lib/python3.9/site-packages/urllib3/connection.py", line 203, in _new_conn
    raise NameResolutionError(self.host, self, e) from e
urllib3.exceptions.NameResolutionError: <urllib3.connection.HTTPSConnection object at 0x7f474b93a940>: Failed to resolve 'proxy-vlan448-a.cs.hku.hk' ([Errno -2] Name or service not known)

The above exception was the direct cause of the following exception:

urllib3.exceptions.ProxyError: ('Unable to connect to proxy', NameResolutionError("<urllib3.connection.HTTPSConnection object at 0x7f474b93a940>: Failed to resolve 'proxy-vlan448-a.cs.hku.hk' ([Errno -2] Name or service not known)"))

The above exception was the direct cause of the following exception:

Traceback (most recent call last):
  File "/group/ycyang/anaconda3/envs/avdc/lib/python3.9/site-packages/requests/adapters.py", line 667, in send
    resp = conn.urlopen(
  File "/group/ycyang/anaconda3/envs/avdc/lib/python3.9/site-packages/urllib3/connectionpool.py", line 843, in urlopen
    retries = retries.increment(
  File "/group/ycyang/anaconda3/envs/avdc/lib/python3.9/site-packages/urllib3/util/retry.py", line 519, in increment
    raise MaxRetryError(_pool, url, reason) from reason  # type: ignore[arg-type]
urllib3.exceptions.MaxRetryError: HTTPSConnectionPool(host='api.wandb.ai', port=443): Max retries exceeded with url: /graphql (Caused by ProxyError('Unable to connect to proxy', NameResolutionError("<urllib3.connection.HTTPSConnection object at 0x7f474b93a940>: Failed to resolve 'proxy-vlan448-a.cs.hku.hk' ([Errno -2] Name or service not known)")))

During handling of the above exception, another exception occurred:

Traceback (most recent call last):
  File "/group/ycyang/anaconda3/envs/avdc/lib/python3.9/site-packages/wandb/sdk/lib/retry.py", line 131, in __call__
    result = self._call_fn(*args, **kwargs)
  File "/group/ycyang/anaconda3/envs/avdc/lib/python3.9/site-packages/wandb/sdk/internal/internal_api.py", line 345, in execute
    return self.client.execute(*args, **kwargs)  # type: ignore
  File "/group/ycyang/anaconda3/envs/avdc/lib/python3.9/site-packages/wandb/vendor/gql-0.2.0/wandb_gql/client.py", line 52, in execute
    result = self._get_result(document, *args, **kwargs)
  File "/group/ycyang/anaconda3/envs/avdc/lib/python3.9/site-packages/wandb/vendor/gql-0.2.0/wandb_gql/client.py", line 60, in _get_result
    return self.transport.execute(document, *args, **kwargs)
  File "/group/ycyang/anaconda3/envs/avdc/lib/python3.9/site-packages/wandb/sdk/lib/gql_request.py", line 58, in execute
    request = self.session.post(self.url, **post_args)
  File "/group/ycyang/anaconda3/envs/avdc/lib/python3.9/site-packages/requests/sessions.py", line 637, in post
    return self.request("POST", url, data=data, json=json, **kwargs)
  File "/group/ycyang/anaconda3/envs/avdc/lib/python3.9/site-packages/requests/sessions.py", line 589, in request
    resp = self.send(prep, **send_kwargs)
  File "/group/ycyang/anaconda3/envs/avdc/lib/python3.9/site-packages/requests/sessions.py", line 703, in send
    r = adapter.send(request, **kwargs)
  File "/group/ycyang/anaconda3/envs/avdc/lib/python3.9/site-packages/requests/adapters.py", line 694, in send
    raise ProxyError(e, request=request)
requests.exceptions.ProxyError: HTTPSConnectionPool(host='api.wandb.ai', port=443): Max retries exceeded with url: /graphql (Caused by ProxyError('Unable to connect to proxy', NameResolutionError("<urllib3.connection.HTTPSConnection object at 0x7f474b93a940>: Failed to resolve 'proxy-vlan448-a.cs.hku.hk' ([Errno -2] Name or service not known)")))
2024-11-27 15:02:41,381 DEBUG   HandlerThread:1062329 [handler.py:handle_request():158] handle_request: keepalive
2024-11-27 15:02:46,381 DEBUG   HandlerThread:1062329 [handler.py:handle_request():158] handle_request: keepalive
2024-11-27 15:02:51,382 DEBUG   HandlerThread:1062329 [handler.py:handle_request():158] handle_request: keepalive
2024-11-27 15:02:56,383 DEBUG   HandlerThread:1062329 [handler.py:handle_request():158] handle_request: keepalive
2024-11-27 15:03:01,384 DEBUG   HandlerThread:1062329 [handler.py:handle_request():158] handle_request: keepalive
2024-11-27 15:03:06,385 DEBUG   HandlerThread:1062329 [handler.py:handle_request():158] handle_request: keepalive
2024-11-27 15:03:11,386 DEBUG   HandlerThread:1062329 [handler.py:handle_request():158] handle_request: keepalive
2024-11-27 15:03:16,387 DEBUG   HandlerThread:1062329 [handler.py:handle_request():158] handle_request: keepalive
2024-11-27 15:03:21,387 DEBUG   HandlerThread:1062329 [handler.py:handle_request():158] handle_request: keepalive
2024-11-27 15:03:26,388 DEBUG   HandlerThread:1062329 [handler.py:handle_request():158] handle_request: keepalive
2024-11-27 15:03:31,389 DEBUG   HandlerThread:1062329 [handler.py:handle_request():158] handle_request: keepalive
2024-11-27 15:03:36,390 DEBUG   HandlerThread:1062329 [handler.py:handle_request():158] handle_request: keepalive
2024-11-27 15:03:41,390 DEBUG   HandlerThread:1062329 [handler.py:handle_request():158] handle_request: keepalive
2024-11-27 15:03:46,391 DEBUG   HandlerThread:1062329 [handler.py:handle_request():158] handle_request: keepalive
2024-11-27 15:03:51,392 DEBUG   HandlerThread:1062329 [handler.py:handle_request():158] handle_request: keepalive
2024-11-27 15:03:56,393 DEBUG   HandlerThread:1062329 [handler.py:handle_request():158] handle_request: keepalive
2024-11-27 15:04:01,393 DEBUG   HandlerThread:1062329 [handler.py:handle_request():158] handle_request: keepalive
2024-11-27 15:04:06,394 DEBUG   HandlerThread:1062329 [handler.py:handle_request():158] handle_request: cancel
2024-11-27 15:04:06,394 DEBUG   HandlerThread:1062329 [handler.py:handle_request():158] handle_request: cancel
2024-11-27 15:04:06,394 DEBUG   SenderThread:1062329 [sender.py:send():400] Record cancelled: run
2024-11-27 15:04:06,395 DEBUG   HandlerThread:1062329 [handler.py:handle_request():158] handle_request: status_report
2024-11-27 15:04:06,416 DEBUG   HandlerThread:1062329 [handler.py:handle_request():158] handle_request: shutdown
2024-11-27 15:04:06,416 INFO    HandlerThread:1062329 [handler.py:finish():882] shutting down handler
2024-11-27 15:04:07,395 INFO    SenderThread:1062329 [sender.py:finish():1631] shutting down sender
2024-11-27 15:04:07,395 INFO    WriterThread:1062329 [datastore.py:close():296] close: /home/yyang-infobai/AVDC_whl/flowdiffusion/wandb/run-20241127_150236-bqglt27g/run-bqglt27g.wandb
