Preparing dataset...
Done
  0%|                                                                                             | 3/30000 [00:03<9:26:26,  1.13s/it]
Traceback (most recent call last):
  File "/home/hlwang/AVDC_change/flowdiffusion/pretrain.py", line 100, in <module>
    main(cfg)
  File "/home/hlwang/AVDC_change/flowdiffusion/pretrain.py", line 75, in main
    x, x_cond, goal, action = next(dl)
Exception in thread   File "/home/hlwang/AVDC_change/flowdiffusion/pretrain.py", line 24, in cycle
    for data in dl:
Thread-5:
  File "/home/hlwang/miniconda3/envs/env/lib/python3.9/site-packages/torch/utils/data/dataloader.py", line 631, in __next__
    data = self._next_data()
Traceback (most recent call last):
  File "/home/hlwang/miniconda3/envs/env/lib/python3.9/site-packages/torch/utils/data/dataloader.py", line 1329, in _next_data
    idx, data = self._get_data()
  File "/home/hlwang/miniconda3/envs/env/lib/python3.9/threading.py", line 980, in _bootstrap_inner
  File "/home/hlwang/miniconda3/envs/env/lib/python3.9/site-packages/torch/utils/data/dataloader.py", line 1285, in _get_data
    success, data = self._try_get_data()
  File "/home/hlwang/miniconda3/envs/env/lib/python3.9/site-packages/torch/utils/data/dataloader.py", line 1133, in _try_get_data
    data = self._data_queue.get(timeout=timeout)
  File "/home/hlwang/miniconda3/envs/env/lib/python3.9/queue.py", line 180, in get
    self.not_empty.wait(remaining)
  File "/home/hlwang/miniconda3/envs/env/lib/python3.9/threading.py", line 316, in wait
    gotit = waiter.acquire(True, timeout)
KeyboardInterrupt
    self.run()
  File "/home/hlwang/miniconda3/envs/env/lib/python3.9/threading.py", line 917, in run