Preparing dataset...
Done
  0%|                                                                                                 | 0/30000 [00:00<?, ?it/s]
Traceback (most recent call last):
  File "/home/hlwang/AVDC_change/flowdiffusion/pretrain.py", line 99, in <module>
    main(cfg)
  File "/home/hlwang/AVDC_change/flowdiffusion/pretrain.py", line 74, in main
    x, x_cond, goal, action = next(dl)
  File "/home/hlwang/AVDC_change/flowdiffusion/pretrain.py", line 24, in cycle
    for data in dl:
  File "/home/hlwang/miniconda3/envs/env/lib/python3.9/site-packages/torch/utils/data/dataloader.py", line 631, in __next__
    data = self._next_data()
  File "/home/hlwang/miniconda3/envs/env/lib/python3.9/site-packages/torch/utils/data/dataloader.py", line 1346, in _next_data
    return self._process_data(data)
  File "/home/hlwang/miniconda3/envs/env/lib/python3.9/site-packages/torch/utils/data/dataloader.py", line 1372, in _process_data
    data.reraise()
  File "/home/hlwang/miniconda3/envs/env/lib/python3.9/site-packages/torch/_utils.py", line 705, in reraise
    raise exception
RecursionError: Caught RecursionError in DataLoader worker process 0.
Original Chained exceptions have been truncated to avoid stack overflow in traceback formatting:
Traceback (most recent call last):
  File "/home/hlwang/AVDC_change/flowdiffusion/datasets.py", line 406, in __getitem__
    samples, actions = self.get_samples(idx)
  File "/home/hlwang/AVDC_change/flowdiffusion/datasets.py", line 391, in get_samples
    seq = self.sequences[idx] # 取某一个目录下的所有图片
IndexError: list index out of range
During handling of the above exception, another exception occurred:
Traceback (most recent call last):
  File "/home/hlwang/AVDC_change/flowdiffusion/datasets.py", line 406, in __getitem__
    samples, actions = self.get_samples(idx)
  File "/home/hlwang/AVDC_change/flowdiffusion/datasets.py", line 391, in get_samples
    seq = self.sequences[idx] # 取某一个目录下的所有图片
IndexError: list index out of range
During handling of the above exception, another exception occurred:
Traceback (most recent call last):
  File "/home/hlwang/AVDC_change/flowdiffusion/datasets.py", line 406, in __getitem__
    samples, actions = self.get_samples(idx)
  File "/home/hlwang/AVDC_change/flowdiffusion/datasets.py", line 391, in get_samples
    seq = self.sequences[idx] # 取某一个目录下的所有图片
IndexError: list index out of range
During handling of the above exception, another exception occurred:
Traceback (most recent call last):
  File "/home/hlwang/AVDC_change/flowdiffusion/datasets.py", line 406, in __getitem__
    samples, actions = self.get_samples(idx)
  File "/home/hlwang/AVDC_change/flowdiffusion/datasets.py", line 391, in get_samples
    seq = self.sequences[idx] # 取某一个目录下的所有图片
IndexError: list index out of range
During handling of the above exception, another exception occurred:
Traceback (most recent call last):
  File "/home/hlwang/AVDC_change/flowdiffusion/datasets.py", line 406, in __getitem__
    samples, actions = self.get_samples(idx)
  File "/home/hlwang/AVDC_change/flowdiffusion/datasets.py", line 391, in get_samples
    seq = self.sequences[idx] # 取某一个目录下的所有图片
IndexError: list index out of range
During handling of the above exception, another exception occurred:
Traceback (most recent call last):
  File "/home/hlwang/AVDC_change/flowdiffusion/datasets.py", line 406, in __getitem__
    samples, actions = self.get_samples(idx)
  File "/home/hlwang/AVDC_change/flowdiffusion/datasets.py", line 391, in get_samples
    seq = self.sequences[idx] # 取某一个目录下的所有图片
IndexError: list index out of range
During handling of the above exception, another exception occurred:
Traceback (most recent call last):
  File "/home/hlwang/AVDC_change/flowdiffusion/datasets.py", line 406, in __getitem__
    samples, actions = self.get_samples(idx)
  File "/home/hlwang/AVDC_change/flowdiffusion/datasets.py", line 391, in get_samples
    seq = self.sequences[idx] # 取某一个目录下的所有图片
IndexError: list index out of range
During handling of the above exception, another exception occurred:
Traceback (most recent call last):
  File "/home/hlwang/AVDC_change/flowdiffusion/datasets.py", line 406, in __getitem__
    samples, actions = self.get_samples(idx)
  File "/home/hlwang/AVDC_change/flowdiffusion/datasets.py", line 391, in get_samples
    seq = self.sequences[idx] # 取某一个目录下的所有图片
IndexError: list index out of range
During handling of the above exception, another exception occurred:
Traceback (most recent call last):
  File "/home/hlwang/AVDC_change/flowdiffusion/datasets.py", line 406, in __getitem__
    samples, actions = self.get_samples(idx)
  File "/home/hlwang/AVDC_change/flowdiffusion/datasets.py", line 391, in get_samples
    seq = self.sequences[idx] # 取某一个目录下的所有图片
IndexError: list index out of range
During handling of the above exception, another exception occurred:
Traceback (most recent call last):
  File "/home/hlwang/AVDC_change/flowdiffusion/datasets.py", line 406, in __getitem__
    samples, actions = self.get_samples(idx)
  File "/home/hlwang/AVDC_change/flowdiffusion/datasets.py", line 391, in get_samples
    seq = self.sequences[idx] # 取某一个目录下的所有图片
IndexError: list index out of range
During handling of the above exception, another exception occurred:
Traceback (most recent call last):
  File "/home/hlwang/AVDC_change/flowdiffusion/datasets.py", line 406, in __getitem__
    samples, actions = self.get_samples(idx)
  File "/home/hlwang/AVDC_change/flowdiffusion/datasets.py", line 391, in get_samples
    seq = self.sequences[idx] # 取某一个目录下的所有图片
IndexError: list index out of range
During handling of the above exception, another exception occurred:
Traceback (most recent call last):
  File "/home/hlwang/AVDC_change/flowdiffusion/datasets.py", line 406, in __getitem__
    samples, actions = self.get_samples(idx)
  File "/home/hlwang/AVDC_change/flowdiffusion/datasets.py", line 391, in get_samples
    seq = self.sequences[idx] # 取某一个目录下的所有图片
IndexError: list index out of range
During handling of the above exception, another exception occurred:
Traceback (most recent call last):
  File "/home/hlwang/AVDC_change/flowdiffusion/datasets.py", line 406, in __getitem__
    samples, actions = self.get_samples(idx)
  File "/home/hlwang/AVDC_change/flowdiffusion/datasets.py", line 391, in get_samples
    seq = self.sequences[idx] # 取某一个目录下的所有图片
IndexError: list index out of range
During handling of the above exception, another exception occurred:
Traceback (most recent call last):
  File "/home/hlwang/AVDC_change/flowdiffusion/datasets.py", line 406, in __getitem__
    samples, actions = self.get_samples(idx)
  File "/home/hlwang/AVDC_change/flowdiffusion/datasets.py", line 391, in get_samples
    seq = self.sequences[idx] # 取某一个目录下的所有图片
IndexError: list index out of range
During handling of the above exception, another exception occurred:
Traceback (most recent call last):
  File "/home/hlwang/AVDC_change/flowdiffusion/datasets.py", line 406, in __getitem__
    samples, actions = self.get_samples(idx)
  File "/home/hlwang/AVDC_change/flowdiffusion/datasets.py", line 391, in get_samples
    seq = self.sequences[idx] # 取某一个目录下的所有图片
IndexError: list index out of range
During handling of the above exception, another exception occurred:
Traceback (most recent call last):
  File "/home/hlwang/AVDC_change/flowdiffusion/datasets.py", line 406, in __getitem__
    samples, actions = self.get_samples(idx)
  File "/home/hlwang/AVDC_change/flowdiffusion/datasets.py", line 391, in get_samples
    seq = self.sequences[idx] # 取某一个目录下的所有图片
IndexError: list index out of range
During handling of the above exception, another exception occurred:
Traceback (most recent call last):
  File "/home/hlwang/AVDC_change/flowdiffusion/datasets.py", line 406, in __getitem__
    samples, actions = self.get_samples(idx)
  File "/home/hlwang/AVDC_change/flowdiffusion/datasets.py", line 391, in get_samples
    seq = self.sequences[idx] # 取某一个目录下的所有图片
IndexError: list index out of range
During handling of the above exception, another exception occurred:
Traceback (most recent call last):
  File "/home/hlwang/AVDC_change/flowdiffusion/datasets.py", line 406, in __getitem__
    samples, actions = self.get_samples(idx)
  File "/home/hlwang/AVDC_change/flowdiffusion/datasets.py", line 391, in get_samples
    seq = self.sequences[idx] # 取某一个目录下的所有图片
IndexError: list index out of range
During handling of the above exception, another exception occurred:
Traceback (most recent call last):
  File "/home/hlwang/AVDC_change/flowdiffusion/datasets.py", line 406, in __getitem__
    samples, actions = self.get_samples(idx)
  File "/home/hlwang/AVDC_change/flowdiffusion/datasets.py", line 391, in get_samples
    seq = self.sequences[idx] # 取某一个目录下的所有图片
IndexError: list index out of range
During handling of the above exception, another exception occurred:
Traceback (most recent call last):
  File "/home/hlwang/AVDC_change/flowdiffusion/datasets.py", line 406, in __getitem__
    samples, actions = self.get_samples(idx)
  File "/home/hlwang/AVDC_change/flowdiffusion/datasets.py", line 391, in get_samples
    seq = self.sequences[idx] # 取某一个目录下的所有图片
IndexError: list index out of range
During handling of the above exception, another exception occurred:
Traceback (most recent call last):
  File "/home/hlwang/AVDC_change/flowdiffusion/datasets.py", line 406, in __getitem__
    samples, actions = self.get_samples(idx)
  File "/home/hlwang/AVDC_change/flowdiffusion/datasets.py", line 391, in get_samples
    seq = self.sequences[idx] # 取某一个目录下的所有图片
IndexError: list index out of range
During handling of the above exception, another exception occurred:
Traceback (most recent call last):
  File "/home/hlwang/AVDC_change/flowdiffusion/datasets.py", line 406, in __getitem__
    samples, actions = self.get_samples(idx)
  File "/home/hlwang/AVDC_change/flowdiffusion/datasets.py", line 391, in get_samples
    seq = self.sequences[idx] # 取某一个目录下的所有图片
IndexError: list index out of range
During handling of the above exception, another exception occurred:
Traceback (most recent call last):
  File "/home/hlwang/AVDC_change/flowdiffusion/datasets.py", line 406, in __getitem__
    samples, actions = self.get_samples(idx)
  File "/home/hlwang/AVDC_change/flowdiffusion/datasets.py", line 391, in get_samples
    seq = self.sequences[idx] # 取某一个目录下的所有图片
IndexError: list index out of range
During handling of the above exception, another exception occurred:
Traceback (most recent call last):
  File "/home/hlwang/AVDC_change/flowdiffusion/datasets.py", line 406, in __getitem__
    samples, actions = self.get_samples(idx)
  File "/home/hlwang/AVDC_change/flowdiffusion/datasets.py", line 391, in get_samples
    seq = self.sequences[idx] # 取某一个目录下的所有图片
IndexError: list index out of range
During handling of the above exception, another exception occurred:
Traceback (most recent call last):
  File "/home/hlwang/AVDC_change/flowdiffusion/datasets.py", line 406, in __getitem__
    samples, actions = self.get_samples(idx)
  File "/home/hlwang/AVDC_change/flowdiffusion/datasets.py", line 391, in get_samples
    seq = self.sequences[idx] # 取某一个目录下的所有图片
IndexError: list index out of range
During handling of the above exception, another exception occurred:
Traceback (most recent call last):
  File "/home/hlwang/AVDC_change/flowdiffusion/datasets.py", line 406, in __getitem__
    samples, actions = self.get_samples(idx)
  File "/home/hlwang/AVDC_change/flowdiffusion/datasets.py", line 391, in get_samples
    seq = self.sequences[idx] # 取某一个目录下的所有图片
IndexError: list index out of range
During handling of the above exception, another exception occurred:
Traceback (most recent call last):
  File "/home/hlwang/AVDC_change/flowdiffusion/datasets.py", line 406, in __getitem__
    samples, actions = self.get_samples(idx)
  File "/home/hlwang/AVDC_change/flowdiffusion/datasets.py", line 391, in get_samples
    seq = self.sequences[idx] # 取某一个目录下的所有图片
IndexError: list index out of range
During handling of the above exception, another exception occurred:
Traceback (most recent call last):
  File "/home/hlwang/AVDC_change/flowdiffusion/datasets.py", line 406, in __getitem__
    samples, actions = self.get_samples(idx)
  File "/home/hlwang/AVDC_change/flowdiffusion/datasets.py", line 391, in get_samples
    seq = self.sequences[idx] # 取某一个目录下的所有图片
IndexError: list index out of range
During handling of the above exception, another exception occurred:
Traceback (most recent call last):
  File "/home/hlwang/AVDC_change/flowdiffusion/datasets.py", line 406, in __getitem__
    samples, actions = self.get_samples(idx)
  File "/home/hlwang/AVDC_change/flowdiffusion/datasets.py", line 391, in get_samples
    seq = self.sequences[idx] # 取某一个目录下的所有图片
IndexError: list index out of range
During handling of the above exception, another exception occurred:
Traceback (most recent call last):
  File "/home/hlwang/AVDC_change/flowdiffusion/datasets.py", line 406, in __getitem__
    samples, actions = self.get_samples(idx)
  File "/home/hlwang/AVDC_change/flowdiffusion/datasets.py", line 391, in get_samples
    seq = self.sequences[idx] # 取某一个目录下的所有图片
IndexError: list index out of range
During handling of the above exception, another exception occurred:
Traceback (most recent call last):
  File "/home/hlwang/AVDC_change/flowdiffusion/datasets.py", line 406, in __getitem__
    samples, actions = self.get_samples(idx)
  File "/home/hlwang/AVDC_change/flowdiffusion/datasets.py", line 391, in get_samples
    seq = self.sequences[idx] # 取某一个目录下的所有图片
IndexError: list index out of range
During handling of the above exception, another exception occurred:
Traceback (most recent call last):
  File "/home/hlwang/AVDC_change/flowdiffusion/datasets.py", line 406, in __getitem__
    samples, actions = self.get_samples(idx)
  File "/home/hlwang/AVDC_change/flowdiffusion/datasets.py", line 391, in get_samples
    seq = self.sequences[idx] # 取某一个目录下的所有图片
IndexError: list index out of range
During handling of the above exception, another exception occurred:
Traceback (most recent call last):
  File "/home/hlwang/AVDC_change/flowdiffusion/datasets.py", line 406, in __getitem__
    samples, actions = self.get_samples(idx)
  File "/home/hlwang/AVDC_change/flowdiffusion/datasets.py", line 391, in get_samples
    seq = self.sequences[idx] # 取某一个目录下的所有图片
IndexError: list index out of range
During handling of the above exception, another exception occurred:
Traceback (most recent call last):
  File "/home/hlwang/AVDC_change/flowdiffusion/datasets.py", line 406, in __getitem__
    samples, actions = self.get_samples(idx)
  File "/home/hlwang/AVDC_change/flowdiffusion/datasets.py", line 391, in get_samples
    seq = self.sequences[idx] # 取某一个目录下的所有图片
IndexError: list index out of range
During handling of the above exception, another exception occurred:
Traceback (most recent call last):
  File "/home/hlwang/AVDC_change/flowdiffusion/datasets.py", line 406, in __getitem__
    samples, actions = self.get_samples(idx)
  File "/home/hlwang/AVDC_change/flowdiffusion/datasets.py", line 391, in get_samples
    seq = self.sequences[idx] # 取某一个目录下的所有图片
IndexError: list index out of range
During handling of the above exception, another exception occurred:
Traceback (most recent call last):
  File "/home/hlwang/AVDC_change/flowdiffusion/datasets.py", line 406, in __getitem__
    samples, actions = self.get_samples(idx)
  File "/home/hlwang/AVDC_change/flowdiffusion/datasets.py", line 391, in get_samples
    seq = self.sequences[idx] # 取某一个目录下的所有图片
IndexError: list index out of range
During handling of the above exception, another exception occurred:
Traceback (most recent call last):
  File "/home/hlwang/AVDC_change/flowdiffusion/datasets.py", line 406, in __getitem__
    samples, actions = self.get_samples(idx)
  File "/home/hlwang/AVDC_change/flowdiffusion/datasets.py", line 391, in get_samples
    seq = self.sequences[idx] # 取某一个目录下的所有图片
IndexError: list index out of range
During handling of the above exception, another exception occurred:
Traceback (most recent call last):
  File "/home/hlwang/AVDC_change/flowdiffusion/datasets.py", line 406, in __getitem__
    samples, actions = self.get_samples(idx)
  File "/home/hlwang/AVDC_change/flowdiffusion/datasets.py", line 391, in get_samples
    seq = self.sequences[idx] # 取某一个目录下的所有图片
IndexError: list index out of range
During handling of the above exception, another exception occurred:
Traceback (most recent call last):
  File "/home/hlwang/AVDC_change/flowdiffusion/datasets.py", line 406, in __getitem__
    samples, actions = self.get_samples(idx)
  File "/home/hlwang/AVDC_change/flowdiffusion/datasets.py", line 391, in get_samples
    seq = self.sequences[idx] # 取某一个目录下的所有图片
IndexError: list index out of range
During handling of the above exception, another exception occurred:
Traceback (most recent call last):
  File "/home/hlwang/AVDC_change/flowdiffusion/datasets.py", line 406, in __getitem__
    samples, actions = self.get_samples(idx)
  File "/home/hlwang/AVDC_change/flowdiffusion/datasets.py", line 391, in get_samples
    seq = self.sequences[idx] # 取某一个目录下的所有图片
IndexError: list index out of range
During handling of the above exception, another exception occurred:
Traceback (most recent call last):
  File "/home/hlwang/AVDC_change/flowdiffusion/datasets.py", line 406, in __getitem__
    samples, actions = self.get_samples(idx)
  File "/home/hlwang/AVDC_change/flowdiffusion/datasets.py", line 391, in get_samples
    seq = self.sequences[idx] # 取某一个目录下的所有图片
IndexError: list index out of range
During handling of the above exception, another exception occurred:
Traceback (most recent call last):
  File "/home/hlwang/AVDC_change/flowdiffusion/datasets.py", line 406, in __getitem__
    samples, actions = self.get_samples(idx)
  File "/home/hlwang/AVDC_change/flowdiffusion/datasets.py", line 391, in get_samples
    seq = self.sequences[idx] # 取某一个目录下的所有图片
IndexError: list index out of range
During handling of the above exception, another exception occurred:
Traceback (most recent call last):
  File "/home/hlwang/AVDC_change/flowdiffusion/datasets.py", line 406, in __getitem__
    samples, actions = self.get_samples(idx)
  File "/home/hlwang/AVDC_change/flowdiffusion/datasets.py", line 391, in get_samples
    seq = self.sequences[idx] # 取某一个目录下的所有图片
IndexError: list index out of range
During handling of the above exception, another exception occurred:
Traceback (most recent call last):
  File "/home/hlwang/AVDC_change/flowdiffusion/datasets.py", line 406, in __getitem__
    samples, actions = self.get_samples(idx)
  File "/home/hlwang/AVDC_change/flowdiffusion/datasets.py", line 391, in get_samples
    seq = self.sequences[idx] # 取某一个目录下的所有图片
IndexError: list index out of range
During handling of the above exception, another exception occurred:
Traceback (most recent call last):
  File "/home/hlwang/AVDC_change/flowdiffusion/datasets.py", line 406, in __getitem__
    samples, actions = self.get_samples(idx)
  File "/home/hlwang/AVDC_change/flowdiffusion/datasets.py", line 391, in get_samples
    seq = self.sequences[idx] # 取某一个目录下的所有图片
IndexError: list index out of range
During handling of the above exception, another exception occurred:
Traceback (most recent call last):
  File "/home/hlwang/AVDC_change/flowdiffusion/datasets.py", line 406, in __getitem__
    samples, actions = self.get_samples(idx)
  File "/home/hlwang/AVDC_change/flowdiffusion/datasets.py", line 391, in get_samples
    seq = self.sequences[idx] # 取某一个目录下的所有图片
IndexError: list index out of range
During handling of the above exception, another exception occurred:
Traceback (most recent call last):
  File "/home/hlwang/AVDC_change/flowdiffusion/datasets.py", line 406, in __getitem__
    samples, actions = self.get_samples(idx)
  File "/home/hlwang/AVDC_change/flowdiffusion/datasets.py", line 391, in get_samples
    seq = self.sequences[idx] # 取某一个目录下的所有图片
IndexError: list index out of range
During handling of the above exception, another exception occurred:
Traceback (most recent call last):
  File "/home/hlwang/AVDC_change/flowdiffusion/datasets.py", line 406, in __getitem__
    samples, actions = self.get_samples(idx)
  File "/home/hlwang/AVDC_change/flowdiffusion/datasets.py", line 391, in get_samples
    seq = self.sequences[idx] # 取某一个目录下的所有图片
IndexError: list index out of range
During handling of the above exception, another exception occurred:
Traceback (most recent call last):
  File "/home/hlwang/AVDC_change/flowdiffusion/datasets.py", line 406, in __getitem__
    samples, actions = self.get_samples(idx)
  File "/home/hlwang/AVDC_change/flowdiffusion/datasets.py", line 391, in get_samples
    seq = self.sequences[idx] # 取某一个目录下的所有图片
IndexError: list index out of range
During handling of the above exception, another exception occurred:
Traceback (most recent call last):
  File "/home/hlwang/AVDC_change/flowdiffusion/datasets.py", line 406, in __getitem__
    samples, actions = self.get_samples(idx)
  File "/home/hlwang/AVDC_change/flowdiffusion/datasets.py", line 391, in get_samples
    seq = self.sequences[idx] # 取某一个目录下的所有图片
IndexError: list index out of range
During handling of the above exception, another exception occurred:
Traceback (most recent call last):
  File "/home/hlwang/AVDC_change/flowdiffusion/datasets.py", line 406, in __getitem__
    samples, actions = self.get_samples(idx)
  File "/home/hlwang/AVDC_change/flowdiffusion/datasets.py", line 391, in get_samples
    seq = self.sequences[idx] # 取某一个目录下的所有图片
IndexError: list index out of range
During handling of the above exception, another exception occurred:
Traceback (most recent call last):
  File "/home/hlwang/AVDC_change/flowdiffusion/datasets.py", line 406, in __getitem__
    samples, actions = self.get_samples(idx)
  File "/home/hlwang/AVDC_change/flowdiffusion/datasets.py", line 391, in get_samples
    seq = self.sequences[idx] # 取某一个目录下的所有图片
IndexError: list index out of range
During handling of the above exception, another exception occurred:
Traceback (most recent call last):
  File "/home/hlwang/AVDC_change/flowdiffusion/datasets.py", line 406, in __getitem__
    samples, actions = self.get_samples(idx)
  File "/home/hlwang/AVDC_change/flowdiffusion/datasets.py", line 391, in get_samples
    seq = self.sequences[idx] # 取某一个目录下的所有图片
IndexError: list index out of range
During handling of the above exception, another exception occurred:
Traceback (most recent call last):
  File "/home/hlwang/AVDC_change/flowdiffusion/datasets.py", line 406, in __getitem__
    samples, actions = self.get_samples(idx)
  File "/home/hlwang/AVDC_change/flowdiffusion/datasets.py", line 391, in get_samples
    seq = self.sequences[idx] # 取某一个目录下的所有图片
IndexError: list index out of range
During handling of the above exception, another exception occurred:
Traceback (most recent call last):
  File "/home/hlwang/AVDC_change/flowdiffusion/datasets.py", line 406, in __getitem__
    samples, actions = self.get_samples(idx)
  File "/home/hlwang/AVDC_change/flowdiffusion/datasets.py", line 391, in get_samples
    seq = self.sequences[idx] # 取某一个目录下的所有图片
IndexError: list index out of range
During handling of the above exception, another exception occurred:
Traceback (most recent call last):
  File "/home/hlwang/AVDC_change/flowdiffusion/datasets.py", line 406, in __getitem__
    samples, actions = self.get_samples(idx)
  File "/home/hlwang/AVDC_change/flowdiffusion/datasets.py", line 391, in get_samples
    seq = self.sequences[idx] # 取某一个目录下的所有图片
IndexError: list index out of range
During handling of the above exception, another exception occurred:
Traceback (most recent call last):
  File "/home/hlwang/AVDC_change/flowdiffusion/datasets.py", line 406, in __getitem__
    samples, actions = self.get_samples(idx)
  File "/home/hlwang/AVDC_change/flowdiffusion/datasets.py", line 391, in get_samples
    seq = self.sequences[idx] # 取某一个目录下的所有图片
IndexError: list index out of range
During handling of the above exception, another exception occurred:
Traceback (most recent call last):
  File "/home/hlwang/AVDC_change/flowdiffusion/datasets.py", line 406, in __getitem__
    samples, actions = self.get_samples(idx)
  File "/home/hlwang/AVDC_change/flowdiffusion/datasets.py", line 391, in get_samples
    seq = self.sequences[idx] # 取某一个目录下的所有图片
IndexError: list index out of range
During handling of the above exception, another exception occurred:
Traceback (most recent call last):
  File "/home/hlwang/AVDC_change/flowdiffusion/datasets.py", line 406, in __getitem__
    samples, actions = self.get_samples(idx)
  File "/home/hlwang/AVDC_change/flowdiffusion/datasets.py", line 391, in get_samples
    seq = self.sequences[idx] # 取某一个目录下的所有图片
IndexError: list index out of range
During handling of the above exception, another exception occurred:
Traceback (most recent call last):
  File "/home/hlwang/AVDC_change/flowdiffusion/datasets.py", line 406, in __getitem__
    samples, actions = self.get_samples(idx)
  File "/home/hlwang/AVDC_change/flowdiffusion/datasets.py", line 391, in get_samples
    seq = self.sequences[idx] # 取某一个目录下的所有图片
IndexError: list index out of range
During handling of the above exception, another exception occurred:
Traceback (most recent call last):
  File "/home/hlwang/AVDC_change/flowdiffusion/datasets.py", line 406, in __getitem__
    samples, actions = self.get_samples(idx)
  File "/home/hlwang/AVDC_change/flowdiffusion/datasets.py", line 391, in get_samples
    seq = self.sequences[idx] # 取某一个目录下的所有图片
IndexError: list index out of range
During handling of the above exception, another exception occurred:
Traceback (most recent call last):
  File "/home/hlwang/AVDC_change/flowdiffusion/datasets.py", line 406, in __getitem__
    samples, actions = self.get_samples(idx)
  File "/home/hlwang/AVDC_change/flowdiffusion/datasets.py", line 391, in get_samples
    seq = self.sequences[idx] # 取某一个目录下的所有图片
IndexError: list index out of range
During handling of the above exception, another exception occurred:
Traceback (most recent call last):
  File "/home/hlwang/AVDC_change/flowdiffusion/datasets.py", line 406, in __getitem__
    samples, actions = self.get_samples(idx)
  File "/home/hlwang/AVDC_change/flowdiffusion/datasets.py", line 391, in get_samples
    seq = self.sequences[idx] # 取某一个目录下的所有图片
IndexError: list index out of range
During handling of the above exception, another exception occurred:
Traceback (most recent call last):
  File "/home/hlwang/AVDC_change/flowdiffusion/datasets.py", line 406, in __getitem__
    samples, actions = self.get_samples(idx)
  File "/home/hlwang/AVDC_change/flowdiffusion/datasets.py", line 391, in get_samples
    seq = self.sequences[idx] # 取某一个目录下的所有图片
IndexError: list index out of range
During handling of the above exception, another exception occurred:
Traceback (most recent call last):
  File "/home/hlwang/AVDC_change/flowdiffusion/datasets.py", line 406, in __getitem__
    samples, actions = self.get_samples(idx)
  File "/home/hlwang/AVDC_change/flowdiffusion/datasets.py", line 391, in get_samples
    seq = self.sequences[idx] # 取某一个目录下的所有图片
IndexError: list index out of range
During handling of the above exception, another exception occurred:
Traceback (most recent call last):
  File "/home/hlwang/AVDC_change/flowdiffusion/datasets.py", line 406, in __getitem__
    samples, actions = self.get_samples(idx)
  File "/home/hlwang/AVDC_change/flowdiffusion/datasets.py", line 391, in get_samples
    seq = self.sequences[idx] # 取某一个目录下的所有图片
IndexError: list index out of range
During handling of the above exception, another exception occurred:
Traceback (most recent call last):
  File "/home/hlwang/AVDC_change/flowdiffusion/datasets.py", line 406, in __getitem__
    samples, actions = self.get_samples(idx)
  File "/home/hlwang/AVDC_change/flowdiffusion/datasets.py", line 391, in get_samples
    seq = self.sequences[idx] # 取某一个目录下的所有图片
IndexError: list index out of range
During handling of the above exception, another exception occurred:
Traceback (most recent call last):
  File "/home/hlwang/AVDC_change/flowdiffusion/datasets.py", line 406, in __getitem__
    samples, actions = self.get_samples(idx)
  File "/home/hlwang/AVDC_change/flowdiffusion/datasets.py", line 391, in get_samples
    seq = self.sequences[idx] # 取某一个目录下的所有图片
IndexError: list index out of range
During handling of the above exception, another exception occurred:
Traceback (most recent call last):
  File "/home/hlwang/AVDC_change/flowdiffusion/datasets.py", line 406, in __getitem__
    samples, actions = self.get_samples(idx)
  File "/home/hlwang/AVDC_change/flowdiffusion/datasets.py", line 391, in get_samples
    seq = self.sequences[idx] # 取某一个目录下的所有图片
IndexError: list index out of range
During handling of the above exception, another exception occurred:
Traceback (most recent call last):
  File "/home/hlwang/AVDC_change/flowdiffusion/datasets.py", line 406, in __getitem__
    samples, actions = self.get_samples(idx)
  File "/home/hlwang/AVDC_change/flowdiffusion/datasets.py", line 391, in get_samples
    seq = self.sequences[idx] # 取某一个目录下的所有图片
IndexError: list index out of range
During handling of the above exception, another exception occurred:
Traceback (most recent call last):
  File "/home/hlwang/AVDC_change/flowdiffusion/datasets.py", line 406, in __getitem__
    samples, actions = self.get_samples(idx)
  File "/home/hlwang/AVDC_change/flowdiffusion/datasets.py", line 391, in get_samples
    seq = self.sequences[idx] # 取某一个目录下的所有图片
IndexError: list index out of range
During handling of the above exception, another exception occurred:
Traceback (most recent call last):
  File "/home/hlwang/AVDC_change/flowdiffusion/datasets.py", line 406, in __getitem__
    samples, actions = self.get_samples(idx)
  File "/home/hlwang/AVDC_change/flowdiffusion/datasets.py", line 391, in get_samples
    seq = self.sequences[idx] # 取某一个目录下的所有图片
IndexError: list index out of range
During handling of the above exception, another exception occurred:
Traceback (most recent call last):
  File "/home/hlwang/AVDC_change/flowdiffusion/datasets.py", line 406, in __getitem__
    samples, actions = self.get_samples(idx)
  File "/home/hlwang/AVDC_change/flowdiffusion/datasets.py", line 391, in get_samples
    seq = self.sequences[idx] # 取某一个目录下的所有图片
IndexError: list index out of range
During handling of the above exception, another exception occurred:
Traceback (most recent call last):
  File "/home/hlwang/AVDC_change/flowdiffusion/datasets.py", line 406, in __getitem__
    samples, actions = self.get_samples(idx)
  File "/home/hlwang/AVDC_change/flowdiffusion/datasets.py", line 391, in get_samples
    seq = self.sequences[idx] # 取某一个目录下的所有图片
IndexError: list index out of range
During handling of the above exception, another exception occurred:
Traceback (most recent call last):
  File "/home/hlwang/AVDC_change/flowdiffusion/datasets.py", line 406, in __getitem__
    samples, actions = self.get_samples(idx)
  File "/home/hlwang/AVDC_change/flowdiffusion/datasets.py", line 391, in get_samples
    seq = self.sequences[idx] # 取某一个目录下的所有图片
IndexError: list index out of range
During handling of the above exception, another exception occurred:
Traceback (most recent call last):
  File "/home/hlwang/AVDC_change/flowdiffusion/datasets.py", line 406, in __getitem__
    samples, actions = self.get_samples(idx)
  File "/home/hlwang/AVDC_change/flowdiffusion/datasets.py", line 391, in get_samples
    seq = self.sequences[idx] # 取某一个目录下的所有图片
IndexError: list index out of range
During handling of the above exception, another exception occurred:
Traceback (most recent call last):
  File "/home/hlwang/AVDC_change/flowdiffusion/datasets.py", line 406, in __getitem__
    samples, actions = self.get_samples(idx)
  File "/home/hlwang/AVDC_change/flowdiffusion/datasets.py", line 391, in get_samples
    seq = self.sequences[idx] # 取某一个目录下的所有图片
IndexError: list index out of range
During handling of the above exception, another exception occurred:
Traceback (most recent call last):
  File "/home/hlwang/AVDC_change/flowdiffusion/datasets.py", line 406, in __getitem__
    samples, actions = self.get_samples(idx)
  File "/home/hlwang/AVDC_change/flowdiffusion/datasets.py", line 391, in get_samples
    seq = self.sequences[idx] # 取某一个目录下的所有图片
IndexError: list index out of range
During handling of the above exception, another exception occurred:
Traceback (most recent call last):
  File "/home/hlwang/AVDC_change/flowdiffusion/datasets.py", line 406, in __getitem__
    samples, actions = self.get_samples(idx)
  File "/home/hlwang/AVDC_change/flowdiffusion/datasets.py", line 391, in get_samples
    seq = self.sequences[idx] # 取某一个目录下的所有图片
IndexError: list index out of range
During handling of the above exception, another exception occurred:
Traceback (most recent call last):
  File "/home/hlwang/AVDC_change/flowdiffusion/datasets.py", line 406, in __getitem__
    samples, actions = self.get_samples(idx)
  File "/home/hlwang/AVDC_change/flowdiffusion/datasets.py", line 391, in get_samples
    seq = self.sequences[idx] # 取某一个目录下的所有图片
IndexError: list index out of range
During handling of the above exception, another exception occurred:
Traceback (most recent call last):
  File "/home/hlwang/AVDC_change/flowdiffusion/datasets.py", line 406, in __getitem__
    samples, actions = self.get_samples(idx)
  File "/home/hlwang/AVDC_change/flowdiffusion/datasets.py", line 391, in get_samples
    seq = self.sequences[idx] # 取某一个目录下的所有图片
IndexError: list index out of range
During handling of the above exception, another exception occurred:
Traceback (most recent call last):
  File "/home/hlwang/AVDC_change/flowdiffusion/datasets.py", line 406, in __getitem__
    samples, actions = self.get_samples(idx)
  File "/home/hlwang/AVDC_change/flowdiffusion/datasets.py", line 391, in get_samples
    seq = self.sequences[idx] # 取某一个目录下的所有图片
IndexError: list index out of range
During handling of the above exception, another exception occurred:
Traceback (most recent call last):
  File "/home/hlwang/AVDC_change/flowdiffusion/datasets.py", line 406, in __getitem__
    samples, actions = self.get_samples(idx)
  File "/home/hlwang/AVDC_change/flowdiffusion/datasets.py", line 391, in get_samples
    seq = self.sequences[idx] # 取某一个目录下的所有图片
IndexError: list index out of range
During handling of the above exception, another exception occurred:
Traceback (most recent call last):
  File "/home/hlwang/AVDC_change/flowdiffusion/datasets.py", line 406, in __getitem__
    samples, actions = self.get_samples(idx)
  File "/home/hlwang/AVDC_change/flowdiffusion/datasets.py", line 391, in get_samples
    seq = self.sequences[idx] # 取某一个目录下的所有图片
IndexError: list index out of range
During handling of the above exception, another exception occurred:
Traceback (most recent call last):
  File "/home/hlwang/AVDC_change/flowdiffusion/datasets.py", line 406, in __getitem__
    samples, actions = self.get_samples(idx)
  File "/home/hlwang/AVDC_change/flowdiffusion/datasets.py", line 391, in get_samples
    seq = self.sequences[idx] # 取某一个目录下的所有图片
IndexError: list index out of range
During handling of the above exception, another exception occurred:
Traceback (most recent call last):
  File "/home/hlwang/AVDC_change/flowdiffusion/datasets.py", line 406, in __getitem__
    samples, actions = self.get_samples(idx)
  File "/home/hlwang/AVDC_change/flowdiffusion/datasets.py", line 391, in get_samples
    seq = self.sequences[idx] # 取某一个目录下的所有图片
IndexError: list index out of range
During handling of the above exception, another exception occurred:
Traceback (most recent call last):
  File "/home/hlwang/AVDC_change/flowdiffusion/datasets.py", line 406, in __getitem__
    samples, actions = self.get_samples(idx)
  File "/home/hlwang/AVDC_change/flowdiffusion/datasets.py", line 391, in get_samples
    seq = self.sequences[idx] # 取某一个目录下的所有图片
IndexError: list index out of range
During handling of the above exception, another exception occurred:
Traceback (most recent call last):
  File "/home/hlwang/AVDC_change/flowdiffusion/datasets.py", line 406, in __getitem__
    samples, actions = self.get_samples(idx)
  File "/home/hlwang/AVDC_change/flowdiffusion/datasets.py", line 391, in get_samples
    seq = self.sequences[idx] # 取某一个目录下的所有图片
IndexError: list index out of range
During handling of the above exception, another exception occurred:
Traceback (most recent call last):
  File "/home/hlwang/AVDC_change/flowdiffusion/datasets.py", line 406, in __getitem__
    samples, actions = self.get_samples(idx)
  File "/home/hlwang/AVDC_change/flowdiffusion/datasets.py", line 391, in get_samples
    seq = self.sequences[idx] # 取某一个目录下的所有图片
IndexError: list index out of range
During handling of the above exception, another exception occurred:
Traceback (most recent call last):
  File "/home/hlwang/AVDC_change/flowdiffusion/datasets.py", line 406, in __getitem__
    samples, actions = self.get_samples(idx)
  File "/home/hlwang/AVDC_change/flowdiffusion/datasets.py", line 391, in get_samples
    seq = self.sequences[idx] # 取某一个目录下的所有图片
IndexError: list index out of range
During handling of the above exception, another exception occurred:
Traceback (most recent call last):
  File "/home/hlwang/AVDC_change/flowdiffusion/datasets.py", line 406, in __getitem__
    samples, actions = self.get_samples(idx)
  File "/home/hlwang/AVDC_change/flowdiffusion/datasets.py", line 391, in get_samples
    seq = self.sequences[idx] # 取某一个目录下的所有图片
IndexError: list index out of range
During handling of the above exception, another exception occurred:
Traceback (most recent call last):
  File "/home/hlwang/AVDC_change/flowdiffusion/datasets.py", line 406, in __getitem__
    samples, actions = self.get_samples(idx)
  File "/home/hlwang/AVDC_change/flowdiffusion/datasets.py", line 391, in get_samples
    seq = self.sequences[idx] # 取某一个目录下的所有图片
IndexError: list index out of range
During handling of the above exception, another exception occurred:
Traceback (most recent call last):
  File "/home/hlwang/AVDC_change/flowdiffusion/datasets.py", line 406, in __getitem__
    samples, actions = self.get_samples(idx)
  File "/home/hlwang/AVDC_change/flowdiffusion/datasets.py", line 391, in get_samples
    seq = self.sequences[idx] # 取某一个目录下的所有图片
IndexError: list index out of range
During handling of the above exception, another exception occurred:
Traceback (most recent call last):
  File "/home/hlwang/AVDC_change/flowdiffusion/datasets.py", line 406, in __getitem__
    samples, actions = self.get_samples(idx)
  File "/home/hlwang/AVDC_change/flowdiffusion/datasets.py", line 391, in get_samples
    seq = self.sequences[idx] # 取某一个目录下的所有图片
IndexError: list index out of range
During handling of the above exception, another exception occurred:
Traceback (most recent call last):
  File "/home/hlwang/AVDC_change/flowdiffusion/datasets.py", line 406, in __getitem__
    samples, actions = self.get_samples(idx)
  File "/home/hlwang/AVDC_change/flowdiffusion/datasets.py", line 391, in get_samples
    seq = self.sequences[idx] # 取某一个目录下的所有图片
IndexError: list index out of range
During handling of the above exception, another exception occurred:
Traceback (most recent call last):
  File "/home/hlwang/AVDC_change/flowdiffusion/datasets.py", line 406, in __getitem__
    samples, actions = self.get_samples(idx)
  File "/home/hlwang/AVDC_change/flowdiffusion/datasets.py", line 391, in get_samples
    seq = self.sequences[idx] # 取某一个目录下的所有图片
IndexError: list index out of range
During handling of the above exception, another exception occurred:
Traceback (most recent call last):
  File "/home/hlwang/AVDC_change/flowdiffusion/datasets.py", line 406, in __getitem__
    samples, actions = self.get_samples(idx)
  File "/home/hlwang/AVDC_change/flowdiffusion/datasets.py", line 391, in get_samples
    seq = self.sequences[idx] # 取某一个目录下的所有图片
IndexError: list index out of range
During handling of the above exception, another exception occurred:
Traceback (most recent call last):
  File "/home/hlwang/AVDC_change/flowdiffusion/datasets.py", line 406, in __getitem__
    samples, actions = self.get_samples(idx)
  File "/home/hlwang/AVDC_change/flowdiffusion/datasets.py", line 391, in get_samples
    seq = self.sequences[idx] # 取某一个目录下的所有图片
IndexError: list index out of range
During handling of the above exception, another exception occurred:
Traceback (most recent call last):
  File "/home/hlwang/AVDC_change/flowdiffusion/datasets.py", line 406, in __getitem__
    samples, actions = self.get_samples(idx)
  File "/home/hlwang/AVDC_change/flowdiffusion/datasets.py", line 391, in get_samples
    seq = self.sequences[idx] # 取某一个目录下的所有图片
IndexError: list index out of range
During handling of the above exception, another exception occurred:
Traceback (most recent call last):
  File "/home/hlwang/AVDC_change/flowdiffusion/datasets.py", line 406, in __getitem__
    samples, actions = self.get_samples(idx)
  File "/home/hlwang/AVDC_change/flowdiffusion/datasets.py", line 391, in get_samples
    seq = self.sequences[idx] # 取某一个目录下的所有图片
IndexError: list index out of range
During handling of the above exception, another exception occurred:
Traceback (most recent call last):
  File "/home/hlwang/AVDC_change/flowdiffusion/datasets.py", line 406, in __getitem__
    samples, actions = self.get_samples(idx)
  File "/home/hlwang/AVDC_change/flowdiffusion/datasets.py", line 391, in get_samples
    seq = self.sequences[idx] # 取某一个目录下的所有图片
IndexError: list index out of range
During handling of the above exception, another exception occurred:
Traceback (most recent call last):
  File "/home/hlwang/AVDC_change/flowdiffusion/datasets.py", line 406, in __getitem__
    samples, actions = self.get_samples(idx)
  File "/home/hlwang/AVDC_change/flowdiffusion/datasets.py", line 391, in get_samples
    seq = self.sequences[idx] # 取某一个目录下的所有图片
IndexError: list index out of range
During handling of the above exception, another exception occurred:
Traceback (most recent call last):
  File "/home/hlwang/AVDC_change/flowdiffusion/datasets.py", line 406, in __getitem__
    samples, actions = self.get_samples(idx)
  File "/home/hlwang/AVDC_change/flowdiffusion/datasets.py", line 391, in get_samples
    seq = self.sequences[idx] # 取某一个目录下的所有图片
IndexError: list index out of range
During handling of the above exception, another exception occurred:
Traceback (most recent call last):
  File "/home/hlwang/AVDC_change/flowdiffusion/datasets.py", line 406, in __getitem__
    samples, actions = self.get_samples(idx)
  File "/home/hlwang/AVDC_change/flowdiffusion/datasets.py", line 391, in get_samples
    seq = self.sequences[idx] # 取某一个目录下的所有图片
IndexError: list index out of range
During handling of the above exception, another exception occurred:
Traceback (most recent call last):
  File "/home/hlwang/AVDC_change/flowdiffusion/datasets.py", line 406, in __getitem__
    samples, actions = self.get_samples(idx)
  File "/home/hlwang/AVDC_change/flowdiffusion/datasets.py", line 391, in get_samples
    seq = self.sequences[idx] # 取某一个目录下的所有图片
IndexError: list index out of range
During handling of the above exception, another exception occurred:
Traceback (most recent call last):
  File "/home/hlwang/AVDC_change/flowdiffusion/datasets.py", line 406, in __getitem__
    samples, actions = self.get_samples(idx)
  File "/home/hlwang/AVDC_change/flowdiffusion/datasets.py", line 391, in get_samples
    seq = self.sequences[idx] # 取某一个目录下的所有图片
IndexError: list index out of range
During handling of the above exception, another exception occurred:
Traceback (most recent call last):
  File "/home/hlwang/AVDC_change/flowdiffusion/datasets.py", line 406, in __getitem__
    samples, actions = self.get_samples(idx)
  File "/home/hlwang/AVDC_change/flowdiffusion/datasets.py", line 391, in get_samples
    seq = self.sequences[idx] # 取某一个目录下的所有图片
IndexError: list index out of range
During handling of the above exception, another exception occurred:
Traceback (most recent call last):
  File "/home/hlwang/AVDC_change/flowdiffusion/datasets.py", line 406, in __getitem__
    samples, actions = self.get_samples(idx)
  File "/home/hlwang/AVDC_change/flowdiffusion/datasets.py", line 391, in get_samples
    seq = self.sequences[idx] # 取某一个目录下的所有图片
IndexError: list index out of range
During handling of the above exception, another exception occurred:
Traceback (most recent call last):
  File "/home/hlwang/AVDC_change/flowdiffusion/datasets.py", line 406, in __getitem__
    samples, actions = self.get_samples(idx)
  File "/home/hlwang/AVDC_change/flowdiffusion/datasets.py", line 391, in get_samples
    seq = self.sequences[idx] # 取某一个目录下的所有图片
IndexError: list index out of range
During handling of the above exception, another exception occurred:
Traceback (most recent call last):
  File "/home/hlwang/AVDC_change/flowdiffusion/datasets.py", line 406, in __getitem__
    samples, actions = self.get_samples(idx)
  File "/home/hlwang/AVDC_change/flowdiffusion/datasets.py", line 391, in get_samples
    seq = self.sequences[idx] # 取某一个目录下的所有图片
IndexError: list index out of range
During handling of the above exception, another exception occurred:
Traceback (most recent call last):
  File "/home/hlwang/AVDC_change/flowdiffusion/datasets.py", line 406, in __getitem__
    samples, actions = self.get_samples(idx)
  File "/home/hlwang/AVDC_change/flowdiffusion/datasets.py", line 391, in get_samples
    seq = self.sequences[idx] # 取某一个目录下的所有图片
IndexError: list index out of range
During handling of the above exception, another exception occurred:
Traceback (most recent call last):
  File "/home/hlwang/AVDC_change/flowdiffusion/datasets.py", line 406, in __getitem__
    samples, actions = self.get_samples(idx)
  File "/home/hlwang/AVDC_change/flowdiffusion/datasets.py", line 391, in get_samples
    seq = self.sequences[idx] # 取某一个目录下的所有图片
IndexError: list index out of range
During handling of the above exception, another exception occurred:
Traceback (most recent call last):
  File "/home/hlwang/AVDC_change/flowdiffusion/datasets.py", line 406, in __getitem__
    samples, actions = self.get_samples(idx)
  File "/home/hlwang/AVDC_change/flowdiffusion/datasets.py", line 391, in get_samples
    seq = self.sequences[idx] # 取某一个目录下的所有图片
IndexError: list index out of range
During handling of the above exception, another exception occurred:
Traceback (most recent call last):
  File "/home/hlwang/AVDC_change/flowdiffusion/datasets.py", line 406, in __getitem__
    samples, actions = self.get_samples(idx)
  File "/home/hlwang/AVDC_change/flowdiffusion/datasets.py", line 391, in get_samples
    seq = self.sequences[idx] # 取某一个目录下的所有图片
IndexError: list index out of range
During handling of the above exception, another exception occurred:
Traceback (most recent call last):
  File "/home/hlwang/AVDC_change/flowdiffusion/datasets.py", line 406, in __getitem__
    samples, actions = self.get_samples(idx)
  File "/home/hlwang/AVDC_change/flowdiffusion/datasets.py", line 391, in get_samples
    seq = self.sequences[idx] # 取某一个目录下的所有图片
IndexError: list index out of range
During handling of the above exception, another exception occurred:
Traceback (most recent call last):
  File "/home/hlwang/AVDC_change/flowdiffusion/datasets.py", line 406, in __getitem__
    samples, actions = self.get_samples(idx)
  File "/home/hlwang/AVDC_change/flowdiffusion/datasets.py", line 391, in get_samples
    seq = self.sequences[idx] # 取某一个目录下的所有图片
IndexError: list index out of range
During handling of the above exception, another exception occurred:
Traceback (most recent call last):
  File "/home/hlwang/AVDC_change/flowdiffusion/datasets.py", line 406, in __getitem__
    samples, actions = self.get_samples(idx)
  File "/home/hlwang/AVDC_change/flowdiffusion/datasets.py", line 391, in get_samples
    seq = self.sequences[idx] # 取某一个目录下的所有图片
IndexError: list index out of range
During handling of the above exception, another exception occurred:
Traceback (most recent call last):
  File "/home/hlwang/AVDC_change/flowdiffusion/datasets.py", line 406, in __getitem__
    samples, actions = self.get_samples(idx)
  File "/home/hlwang/AVDC_change/flowdiffusion/datasets.py", line 391, in get_samples
    seq = self.sequences[idx] # 取某一个目录下的所有图片
IndexError: list index out of range
During handling of the above exception, another exception occurred:
Traceback (most recent call last):
  File "/home/hlwang/AVDC_change/flowdiffusion/datasets.py", line 406, in __getitem__
    samples, actions = self.get_samples(idx)
  File "/home/hlwang/AVDC_change/flowdiffusion/datasets.py", line 391, in get_samples
    seq = self.sequences[idx] # 取某一个目录下的所有图片
IndexError: list index out of range
During handling of the above exception, another exception occurred:
Traceback (most recent call last):
  File "/home/hlwang/AVDC_change/flowdiffusion/datasets.py", line 406, in __getitem__
    samples, actions = self.get_samples(idx)
  File "/home/hlwang/AVDC_change/flowdiffusion/datasets.py", line 391, in get_samples
    seq = self.sequences[idx] # 取某一个目录下的所有图片
IndexError: list index out of range
During handling of the above exception, another exception occurred:
Traceback (most recent call last):
  File "/home/hlwang/AVDC_change/flowdiffusion/datasets.py", line 406, in __getitem__
    samples, actions = self.get_samples(idx)
  File "/home/hlwang/AVDC_change/flowdiffusion/datasets.py", line 391, in get_samples
    seq = self.sequences[idx] # 取某一个目录下的所有图片
IndexError: list index out of range
During handling of the above exception, another exception occurred:
Traceback (most recent call last):
  File "/home/hlwang/AVDC_change/flowdiffusion/datasets.py", line 406, in __getitem__
    samples, actions = self.get_samples(idx)
  File "/home/hlwang/AVDC_change/flowdiffusion/datasets.py", line 391, in get_samples
    seq = self.sequences[idx] # 取某一个目录下的所有图片
IndexError: list index out of range
During handling of the above exception, another exception occurred:
Traceback (most recent call last):
  File "/home/hlwang/AVDC_change/flowdiffusion/datasets.py", line 406, in __getitem__
    samples, actions = self.get_samples(idx)
  File "/home/hlwang/AVDC_change/flowdiffusion/datasets.py", line 391, in get_samples
    seq = self.sequences[idx] # 取某一个目录下的所有图片
IndexError: list index out of range
During handling of the above exception, another exception occurred:
Traceback (most recent call last):
  File "/home/hlwang/AVDC_change/flowdiffusion/datasets.py", line 406, in __getitem__
    samples, actions = self.get_samples(idx)
  File "/home/hlwang/AVDC_change/flowdiffusion/datasets.py", line 391, in get_samples
    seq = self.sequences[idx] # 取某一个目录下的所有图片
IndexError: list index out of range
During handling of the above exception, another exception occurred:
Traceback (most recent call last):
  File "/home/hlwang/AVDC_change/flowdiffusion/datasets.py", line 406, in __getitem__
    samples, actions = self.get_samples(idx)
  File "/home/hlwang/AVDC_change/flowdiffusion/datasets.py", line 391, in get_samples
    seq = self.sequences[idx] # 取某一个目录下的所有图片
IndexError: list index out of range
During handling of the above exception, another exception occurred:
Traceback (most recent call last):
  File "/home/hlwang/AVDC_change/flowdiffusion/datasets.py", line 406, in __getitem__
    samples, actions = self.get_samples(idx)
  File "/home/hlwang/AVDC_change/flowdiffusion/datasets.py", line 391, in get_samples
    seq = self.sequences[idx] # 取某一个目录下的所有图片
IndexError: list index out of range
During handling of the above exception, another exception occurred:
Traceback (most recent call last):
  File "/home/hlwang/AVDC_change/flowdiffusion/datasets.py", line 406, in __getitem__
    samples, actions = self.get_samples(idx)
  File "/home/hlwang/AVDC_change/flowdiffusion/datasets.py", line 391, in get_samples
    seq = self.sequences[idx] # 取某一个目录下的所有图片
IndexError: list index out of range
During handling of the above exception, another exception occurred:
Traceback (most recent call last):
  File "/home/hlwang/AVDC_change/flowdiffusion/datasets.py", line 406, in __getitem__
    samples, actions = self.get_samples(idx)
  File "/home/hlwang/AVDC_change/flowdiffusion/datasets.py", line 391, in get_samples
    seq = self.sequences[idx] # 取某一个目录下的所有图片
IndexError: list index out of range
During handling of the above exception, another exception occurred:
Traceback (most recent call last):
  File "/home/hlwang/AVDC_change/flowdiffusion/datasets.py", line 406, in __getitem__
    samples, actions = self.get_samples(idx)
  File "/home/hlwang/AVDC_change/flowdiffusion/datasets.py", line 391, in get_samples
    seq = self.sequences[idx] # 取某一个目录下的所有图片
IndexError: list index out of range
During handling of the above exception, another exception occurred:
Traceback (most recent call last):
  File "/home/hlwang/AVDC_change/flowdiffusion/datasets.py", line 406, in __getitem__
    samples, actions = self.get_samples(idx)
  File "/home/hlwang/AVDC_change/flowdiffusion/datasets.py", line 391, in get_samples
    seq = self.sequences[idx] # 取某一个目录下的所有图片
IndexError: list index out of range
During handling of the above exception, another exception occurred:
Traceback (most recent call last):
  File "/home/hlwang/AVDC_change/flowdiffusion/datasets.py", line 406, in __getitem__
    samples, actions = self.get_samples(idx)
  File "/home/hlwang/AVDC_change/flowdiffusion/datasets.py", line 391, in get_samples
    seq = self.sequences[idx] # 取某一个目录下的所有图片
IndexError: list index out of range
During handling of the above exception, another exception occurred:
Traceback (most recent call last):
  File "/home/hlwang/AVDC_change/flowdiffusion/datasets.py", line 406, in __getitem__
    samples, actions = self.get_samples(idx)
  File "/home/hlwang/AVDC_change/flowdiffusion/datasets.py", line 391, in get_samples
    seq = self.sequences[idx] # 取某一个目录下的所有图片
IndexError: list index out of range
During handling of the above exception, another exception occurred:
Traceback (most recent call last):
  File "/home/hlwang/AVDC_change/flowdiffusion/datasets.py", line 406, in __getitem__
    samples, actions = self.get_samples(idx)
  File "/home/hlwang/AVDC_change/flowdiffusion/datasets.py", line 391, in get_samples
    seq = self.sequences[idx] # 取某一个目录下的所有图片
IndexError: list index out of range
During handling of the above exception, another exception occurred:
Traceback (most recent call last):
  File "/home/hlwang/AVDC_change/flowdiffusion/datasets.py", line 406, in __getitem__
    samples, actions = self.get_samples(idx)
  File "/home/hlwang/AVDC_change/flowdiffusion/datasets.py", line 391, in get_samples
    seq = self.sequences[idx] # 取某一个目录下的所有图片
IndexError: list index out of range
During handling of the above exception, another exception occurred:
Traceback (most recent call last):
  File "/home/hlwang/AVDC_change/flowdiffusion/datasets.py", line 406, in __getitem__
    samples, actions = self.get_samples(idx)
  File "/home/hlwang/AVDC_change/flowdiffusion/datasets.py", line 391, in get_samples
    seq = self.sequences[idx] # 取某一个目录下的所有图片
IndexError: list index out of range
During handling of the above exception, another exception occurred:
Traceback (most recent call last):
  File "/home/hlwang/AVDC_change/flowdiffusion/datasets.py", line 406, in __getitem__
    samples, actions = self.get_samples(idx)
  File "/home/hlwang/AVDC_change/flowdiffusion/datasets.py", line 391, in get_samples
    seq = self.sequences[idx] # 取某一个目录下的所有图片
IndexError: list index out of range
During handling of the above exception, another exception occurred:
Traceback (most recent call last):
  File "/home/hlwang/AVDC_change/flowdiffusion/datasets.py", line 406, in __getitem__
    samples, actions = self.get_samples(idx)
  File "/home/hlwang/AVDC_change/flowdiffusion/datasets.py", line 391, in get_samples
    seq = self.sequences[idx] # 取某一个目录下的所有图片
IndexError: list index out of range
During handling of the above exception, another exception occurred:
Traceback (most recent call last):
  File "/home/hlwang/AVDC_change/flowdiffusion/datasets.py", line 406, in __getitem__
    samples, actions = self.get_samples(idx)
  File "/home/hlwang/AVDC_change/flowdiffusion/datasets.py", line 391, in get_samples
    seq = self.sequences[idx] # 取某一个目录下的所有图片
IndexError: list index out of range
During handling of the above exception, another exception occurred:
Traceback (most recent call last):
  File "/home/hlwang/AVDC_change/flowdiffusion/datasets.py", line 406, in __getitem__
    samples, actions = self.get_samples(idx)
  File "/home/hlwang/AVDC_change/flowdiffusion/datasets.py", line 391, in get_samples
    seq = self.sequences[idx] # 取某一个目录下的所有图片
IndexError: list index out of range
During handling of the above exception, another exception occurred:
Traceback (most recent call last):
  File "/home/hlwang/AVDC_change/flowdiffusion/datasets.py", line 406, in __getitem__
    samples, actions = self.get_samples(idx)
  File "/home/hlwang/AVDC_change/flowdiffusion/datasets.py", line 391, in get_samples
    seq = self.sequences[idx] # 取某一个目录下的所有图片
IndexError: list index out of range
During handling of the above exception, another exception occurred:
Traceback (most recent call last):
  File "/home/hlwang/AVDC_change/flowdiffusion/datasets.py", line 406, in __getitem__
    samples, actions = self.get_samples(idx)
  File "/home/hlwang/AVDC_change/flowdiffusion/datasets.py", line 391, in get_samples
    seq = self.sequences[idx] # 取某一个目录下的所有图片
IndexError: list index out of range
During handling of the above exception, another exception occurred:
Traceback (most recent call last):
  File "/home/hlwang/AVDC_change/flowdiffusion/datasets.py", line 406, in __getitem__
    samples, actions = self.get_samples(idx)
  File "/home/hlwang/AVDC_change/flowdiffusion/datasets.py", line 391, in get_samples
    seq = self.sequences[idx] # 取某一个目录下的所有图片
IndexError: list index out of range
During handling of the above exception, another exception occurred:
Traceback (most recent call last):
  File "/home/hlwang/AVDC_change/flowdiffusion/datasets.py", line 406, in __getitem__
    samples, actions = self.get_samples(idx)
  File "/home/hlwang/AVDC_change/flowdiffusion/datasets.py", line 391, in get_samples
    seq = self.sequences[idx] # 取某一个目录下的所有图片
IndexError: list index out of range
During handling of the above exception, another exception occurred:
Traceback (most recent call last):
  File "/home/hlwang/AVDC_change/flowdiffusion/datasets.py", line 406, in __getitem__
    samples, actions = self.get_samples(idx)
  File "/home/hlwang/AVDC_change/flowdiffusion/datasets.py", line 391, in get_samples
    seq = self.sequences[idx] # 取某一个目录下的所有图片
IndexError: list index out of range
During handling of the above exception, another exception occurred:
Traceback (most recent call last):
  File "/home/hlwang/AVDC_change/flowdiffusion/datasets.py", line 406, in __getitem__
    samples, actions = self.get_samples(idx)
  File "/home/hlwang/AVDC_change/flowdiffusion/datasets.py", line 391, in get_samples
    seq = self.sequences[idx] # 取某一个目录下的所有图片
IndexError: list index out of range
During handling of the above exception, another exception occurred:
Traceback (most recent call last):
  File "/home/hlwang/AVDC_change/flowdiffusion/datasets.py", line 406, in __getitem__
    samples, actions = self.get_samples(idx)
  File "/home/hlwang/AVDC_change/flowdiffusion/datasets.py", line 391, in get_samples
    seq = self.sequences[idx] # 取某一个目录下的所有图片
IndexError: list index out of range
During handling of the above exception, another exception occurred:
Traceback (most recent call last):
  File "/home/hlwang/AVDC_change/flowdiffusion/datasets.py", line 406, in __getitem__
    samples, actions = self.get_samples(idx)
  File "/home/hlwang/AVDC_change/flowdiffusion/datasets.py", line 391, in get_samples
    seq = self.sequences[idx] # 取某一个目录下的所有图片
IndexError: list index out of range
During handling of the above exception, another exception occurred:
Traceback (most recent call last):
  File "/home/hlwang/AVDC_change/flowdiffusion/datasets.py", line 406, in __getitem__
    samples, actions = self.get_samples(idx)
  File "/home/hlwang/AVDC_change/flowdiffusion/datasets.py", line 391, in get_samples
    seq = self.sequences[idx] # 取某一个目录下的所有图片
IndexError: list index out of range
During handling of the above exception, another exception occurred:
Traceback (most recent call last):
  File "/home/hlwang/AVDC_change/flowdiffusion/datasets.py", line 406, in __getitem__
    samples, actions = self.get_samples(idx)
  File "/home/hlwang/AVDC_change/flowdiffusion/datasets.py", line 391, in get_samples
    seq = self.sequences[idx] # 取某一个目录下的所有图片
IndexError: list index out of range
During handling of the above exception, another exception occurred:
Traceback (most recent call last):
  File "/home/hlwang/AVDC_change/flowdiffusion/datasets.py", line 406, in __getitem__
    samples, actions = self.get_samples(idx)
  File "/home/hlwang/AVDC_change/flowdiffusion/datasets.py", line 391, in get_samples
    seq = self.sequences[idx] # 取某一个目录下的所有图片
IndexError: list index out of range
During handling of the above exception, another exception occurred:
Traceback (most recent call last):
  File "/home/hlwang/AVDC_change/flowdiffusion/datasets.py", line 406, in __getitem__
    samples, actions = self.get_samples(idx)
  File "/home/hlwang/AVDC_change/flowdiffusion/datasets.py", line 391, in get_samples
    seq = self.sequences[idx] # 取某一个目录下的所有图片
IndexError: list index out of range
During handling of the above exception, another exception occurred:
Traceback (most recent call last):
  File "/home/hlwang/AVDC_change/flowdiffusion/datasets.py", line 406, in __getitem__
    samples, actions = self.get_samples(idx)
  File "/home/hlwang/AVDC_change/flowdiffusion/datasets.py", line 391, in get_samples
    seq = self.sequences[idx] # 取某一个目录下的所有图片
IndexError: list index out of range
During handling of the above exception, another exception occurred:
Traceback (most recent call last):
  File "/home/hlwang/AVDC_change/flowdiffusion/datasets.py", line 406, in __getitem__
    samples, actions = self.get_samples(idx)
  File "/home/hlwang/AVDC_change/flowdiffusion/datasets.py", line 391, in get_samples
    seq = self.sequences[idx] # 取某一个目录下的所有图片
IndexError: list index out of range
During handling of the above exception, another exception occurred:
Traceback (most recent call last):
  File "/home/hlwang/AVDC_change/flowdiffusion/datasets.py", line 406, in __getitem__
    samples, actions = self.get_samples(idx)
  File "/home/hlwang/AVDC_change/flowdiffusion/datasets.py", line 391, in get_samples
    seq = self.sequences[idx] # 取某一个目录下的所有图片
IndexError: list index out of range
During handling of the above exception, another exception occurred:
Traceback (most recent call last):
  File "/home/hlwang/AVDC_change/flowdiffusion/datasets.py", line 406, in __getitem__
    samples, actions = self.get_samples(idx)
  File "/home/hlwang/AVDC_change/flowdiffusion/datasets.py", line 391, in get_samples
    seq = self.sequences[idx] # 取某一个目录下的所有图片
IndexError: list index out of range
During handling of the above exception, another exception occurred:
Traceback (most recent call last):
  File "/home/hlwang/AVDC_change/flowdiffusion/datasets.py", line 406, in __getitem__
    samples, actions = self.get_samples(idx)
  File "/home/hlwang/AVDC_change/flowdiffusion/datasets.py", line 391, in get_samples
    seq = self.sequences[idx] # 取某一个目录下的所有图片
IndexError: list index out of range
During handling of the above exception, another exception occurred:
Traceback (most recent call last):
  File "/home/hlwang/AVDC_change/flowdiffusion/datasets.py", line 406, in __getitem__
    samples, actions = self.get_samples(idx)
  File "/home/hlwang/AVDC_change/flowdiffusion/datasets.py", line 391, in get_samples
    seq = self.sequences[idx] # 取某一个目录下的所有图片
IndexError: list index out of range
During handling of the above exception, another exception occurred:
Traceback (most recent call last):
  File "/home/hlwang/AVDC_change/flowdiffusion/datasets.py", line 406, in __getitem__
    samples, actions = self.get_samples(idx)
  File "/home/hlwang/AVDC_change/flowdiffusion/datasets.py", line 391, in get_samples
    seq = self.sequences[idx] # 取某一个目录下的所有图片
IndexError: list index out of range
During handling of the above exception, another exception occurred:
Traceback (most recent call last):
  File "/home/hlwang/AVDC_change/flowdiffusion/datasets.py", line 406, in __getitem__
    samples, actions = self.get_samples(idx)
  File "/home/hlwang/AVDC_change/flowdiffusion/datasets.py", line 391, in get_samples
    seq = self.sequences[idx] # 取某一个目录下的所有图片
IndexError: list index out of range
During handling of the above exception, another exception occurred:
Traceback (most recent call last):
  File "/home/hlwang/AVDC_change/flowdiffusion/datasets.py", line 406, in __getitem__
    samples, actions = self.get_samples(idx)
  File "/home/hlwang/AVDC_change/flowdiffusion/datasets.py", line 391, in get_samples
    seq = self.sequences[idx] # 取某一个目录下的所有图片
IndexError: list index out of range
During handling of the above exception, another exception occurred:
Traceback (most recent call last):
  File "/home/hlwang/AVDC_change/flowdiffusion/datasets.py", line 406, in __getitem__
    samples, actions = self.get_samples(idx)
  File "/home/hlwang/AVDC_change/flowdiffusion/datasets.py", line 391, in get_samples
    seq = self.sequences[idx] # 取某一个目录下的所有图片
IndexError: list index out of range
During handling of the above exception, another exception occurred:
Traceback (most recent call last):
  File "/home/hlwang/AVDC_change/flowdiffusion/datasets.py", line 406, in __getitem__
    samples, actions = self.get_samples(idx)
  File "/home/hlwang/AVDC_change/flowdiffusion/datasets.py", line 391, in get_samples
    seq = self.sequences[idx] # 取某一个目录下的所有图片
IndexError: list index out of range
During handling of the above exception, another exception occurred:
Traceback (most recent call last):
  File "/home/hlwang/AVDC_change/flowdiffusion/datasets.py", line 406, in __getitem__
    samples, actions = self.get_samples(idx)
  File "/home/hlwang/AVDC_change/flowdiffusion/datasets.py", line 391, in get_samples
    seq = self.sequences[idx] # 取某一个目录下的所有图片
IndexError: list index out of range
During handling of the above exception, another exception occurred:
Traceback (most recent call last):
  File "/home/hlwang/AVDC_change/flowdiffusion/datasets.py", line 406, in __getitem__
    samples, actions = self.get_samples(idx)
  File "/home/hlwang/AVDC_change/flowdiffusion/datasets.py", line 391, in get_samples
    seq = self.sequences[idx] # 取某一个目录下的所有图片
IndexError: list index out of range
During handling of the above exception, another exception occurred:
Traceback (most recent call last):
  File "/home/hlwang/AVDC_change/flowdiffusion/datasets.py", line 406, in __getitem__
    samples, actions = self.get_samples(idx)
  File "/home/hlwang/AVDC_change/flowdiffusion/datasets.py", line 391, in get_samples
    seq = self.sequences[idx] # 取某一个目录下的所有图片
IndexError: list index out of range
During handling of the above exception, another exception occurred:
Traceback (most recent call last):
  File "/home/hlwang/AVDC_change/flowdiffusion/datasets.py", line 406, in __getitem__
    samples, actions = self.get_samples(idx)
  File "/home/hlwang/AVDC_change/flowdiffusion/datasets.py", line 391, in get_samples
    seq = self.sequences[idx] # 取某一个目录下的所有图片
IndexError: list index out of range
During handling of the above exception, another exception occurred:
Traceback (most recent call last):
  File "/home/hlwang/AVDC_change/flowdiffusion/datasets.py", line 406, in __getitem__
    samples, actions = self.get_samples(idx)
  File "/home/hlwang/AVDC_change/flowdiffusion/datasets.py", line 391, in get_samples
    seq = self.sequences[idx] # 取某一个目录下的所有图片
IndexError: list index out of range
During handling of the above exception, another exception occurred:
Traceback (most recent call last):
  File "/home/hlwang/AVDC_change/flowdiffusion/datasets.py", line 406, in __getitem__
    samples, actions = self.get_samples(idx)
  File "/home/hlwang/AVDC_change/flowdiffusion/datasets.py", line 391, in get_samples
    seq = self.sequences[idx] # 取某一个目录下的所有图片
IndexError: list index out of range
During handling of the above exception, another exception occurred:
Traceback (most recent call last):
  File "/home/hlwang/AVDC_change/flowdiffusion/datasets.py", line 406, in __getitem__
    samples, actions = self.get_samples(idx)
  File "/home/hlwang/AVDC_change/flowdiffusion/datasets.py", line 391, in get_samples
    seq = self.sequences[idx] # 取某一个目录下的所有图片
IndexError: list index out of range
During handling of the above exception, another exception occurred:
Traceback (most recent call last):
  File "/home/hlwang/AVDC_change/flowdiffusion/datasets.py", line 406, in __getitem__
    samples, actions = self.get_samples(idx)
  File "/home/hlwang/AVDC_change/flowdiffusion/datasets.py", line 391, in get_samples
    seq = self.sequences[idx] # 取某一个目录下的所有图片
IndexError: list index out of range
During handling of the above exception, another exception occurred:
Traceback (most recent call last):
  File "/home/hlwang/AVDC_change/flowdiffusion/datasets.py", line 406, in __getitem__
    samples, actions = self.get_samples(idx)
  File "/home/hlwang/AVDC_change/flowdiffusion/datasets.py", line 391, in get_samples
    seq = self.sequences[idx] # 取某一个目录下的所有图片
IndexError: list index out of range
During handling of the above exception, another exception occurred:
Traceback (most recent call last):
  File "/home/hlwang/AVDC_change/flowdiffusion/datasets.py", line 406, in __getitem__
    samples, actions = self.get_samples(idx)
  File "/home/hlwang/AVDC_change/flowdiffusion/datasets.py", line 391, in get_samples
    seq = self.sequences[idx] # 取某一个目录下的所有图片
IndexError: list index out of range
During handling of the above exception, another exception occurred:
Traceback (most recent call last):
  File "/home/hlwang/AVDC_change/flowdiffusion/datasets.py", line 406, in __getitem__
    samples, actions = self.get_samples(idx)
  File "/home/hlwang/AVDC_change/flowdiffusion/datasets.py", line 391, in get_samples
    seq = self.sequences[idx] # 取某一个目录下的所有图片
IndexError: list index out of range
During handling of the above exception, another exception occurred:
Traceback (most recent call last):
  File "/home/hlwang/AVDC_change/flowdiffusion/datasets.py", line 406, in __getitem__
    samples, actions = self.get_samples(idx)
  File "/home/hlwang/AVDC_change/flowdiffusion/datasets.py", line 391, in get_samples
    seq = self.sequences[idx] # 取某一个目录下的所有图片
IndexError: list index out of range
During handling of the above exception, another exception occurred:
Traceback (most recent call last):
  File "/home/hlwang/AVDC_change/flowdiffusion/datasets.py", line 406, in __getitem__
    samples, actions = self.get_samples(idx)
  File "/home/hlwang/AVDC_change/flowdiffusion/datasets.py", line 391, in get_samples
    seq = self.sequences[idx] # 取某一个目录下的所有图片
IndexError: list index out of range
During handling of the above exception, another exception occurred:
Traceback (most recent call last):
  File "/home/hlwang/AVDC_change/flowdiffusion/datasets.py", line 406, in __getitem__
    samples, actions = self.get_samples(idx)
  File "/home/hlwang/AVDC_change/flowdiffusion/datasets.py", line 391, in get_samples
    seq = self.sequences[idx] # 取某一个目录下的所有图片
IndexError: list index out of range
During handling of the above exception, another exception occurred:
Traceback (most recent call last):
  File "/home/hlwang/AVDC_change/flowdiffusion/datasets.py", line 406, in __getitem__
    samples, actions = self.get_samples(idx)
  File "/home/hlwang/AVDC_change/flowdiffusion/datasets.py", line 391, in get_samples
    seq = self.sequences[idx] # 取某一个目录下的所有图片
IndexError: list index out of range
During handling of the above exception, another exception occurred:
Traceback (most recent call last):
  File "/home/hlwang/AVDC_change/flowdiffusion/datasets.py", line 406, in __getitem__
    samples, actions = self.get_samples(idx)
  File "/home/hlwang/AVDC_change/flowdiffusion/datasets.py", line 391, in get_samples
    seq = self.sequences[idx] # 取某一个目录下的所有图片
IndexError: list index out of range
During handling of the above exception, another exception occurred:
Traceback (most recent call last):
  File "/home/hlwang/AVDC_change/flowdiffusion/datasets.py", line 406, in __getitem__
    samples, actions = self.get_samples(idx)
  File "/home/hlwang/AVDC_change/flowdiffusion/datasets.py", line 391, in get_samples
    seq = self.sequences[idx] # 取某一个目录下的所有图片
IndexError: list index out of range
During handling of the above exception, another exception occurred:
Traceback (most recent call last):
  File "/home/hlwang/AVDC_change/flowdiffusion/datasets.py", line 406, in __getitem__
    samples, actions = self.get_samples(idx)
  File "/home/hlwang/AVDC_change/flowdiffusion/datasets.py", line 391, in get_samples
    seq = self.sequences[idx] # 取某一个目录下的所有图片
IndexError: list index out of range
During handling of the above exception, another exception occurred:
Traceback (most recent call last):
  File "/home/hlwang/AVDC_change/flowdiffusion/datasets.py", line 406, in __getitem__
    samples, actions = self.get_samples(idx)
  File "/home/hlwang/AVDC_change/flowdiffusion/datasets.py", line 391, in get_samples
    seq = self.sequences[idx] # 取某一个目录下的所有图片
IndexError: list index out of range
During handling of the above exception, another exception occurred:
Traceback (most recent call last):
  File "/home/hlwang/AVDC_change/flowdiffusion/datasets.py", line 406, in __getitem__
    samples, actions = self.get_samples(idx)
  File "/home/hlwang/AVDC_change/flowdiffusion/datasets.py", line 391, in get_samples
    seq = self.sequences[idx] # 取某一个目录下的所有图片
IndexError: list index out of range
During handling of the above exception, another exception occurred:
Traceback (most recent call last):
  File "/home/hlwang/AVDC_change/flowdiffusion/datasets.py", line 406, in __getitem__
    samples, actions = self.get_samples(idx)
  File "/home/hlwang/AVDC_change/flowdiffusion/datasets.py", line 391, in get_samples
    seq = self.sequences[idx] # 取某一个目录下的所有图片
IndexError: list index out of range
During handling of the above exception, another exception occurred:
Traceback (most recent call last):
  File "/home/hlwang/AVDC_change/flowdiffusion/datasets.py", line 406, in __getitem__
    samples, actions = self.get_samples(idx)
  File "/home/hlwang/AVDC_change/flowdiffusion/datasets.py", line 391, in get_samples
    seq = self.sequences[idx] # 取某一个目录下的所有图片
IndexError: list index out of range
During handling of the above exception, another exception occurred:
Traceback (most recent call last):
  File "/home/hlwang/AVDC_change/flowdiffusion/datasets.py", line 406, in __getitem__
    samples, actions = self.get_samples(idx)
  File "/home/hlwang/AVDC_change/flowdiffusion/datasets.py", line 391, in get_samples
    seq = self.sequences[idx] # 取某一个目录下的所有图片
IndexError: list index out of range
During handling of the above exception, another exception occurred:
Traceback (most recent call last):
  File "/home/hlwang/AVDC_change/flowdiffusion/datasets.py", line 406, in __getitem__
    samples, actions = self.get_samples(idx)
  File "/home/hlwang/AVDC_change/flowdiffusion/datasets.py", line 391, in get_samples
    seq = self.sequences[idx] # 取某一个目录下的所有图片
IndexError: list index out of range
During handling of the above exception, another exception occurred:
Traceback (most recent call last):
  File "/home/hlwang/AVDC_change/flowdiffusion/datasets.py", line 406, in __getitem__
    samples, actions = self.get_samples(idx)
  File "/home/hlwang/AVDC_change/flowdiffusion/datasets.py", line 391, in get_samples
    seq = self.sequences[idx] # 取某一个目录下的所有图片
IndexError: list index out of range
During handling of the above exception, another exception occurred:
Traceback (most recent call last):
  File "/home/hlwang/AVDC_change/flowdiffusion/datasets.py", line 406, in __getitem__
    samples, actions = self.get_samples(idx)
  File "/home/hlwang/AVDC_change/flowdiffusion/datasets.py", line 391, in get_samples
    seq = self.sequences[idx] # 取某一个目录下的所有图片
IndexError: list index out of range
During handling of the above exception, another exception occurred:
Traceback (most recent call last):
  File "/home/hlwang/AVDC_change/flowdiffusion/datasets.py", line 406, in __getitem__
    samples, actions = self.get_samples(idx)
  File "/home/hlwang/AVDC_change/flowdiffusion/datasets.py", line 391, in get_samples
    seq = self.sequences[idx] # 取某一个目录下的所有图片
IndexError: list index out of range
During handling of the above exception, another exception occurred:
Traceback (most recent call last):
  File "/home/hlwang/AVDC_change/flowdiffusion/datasets.py", line 406, in __getitem__
    samples, actions = self.get_samples(idx)
  File "/home/hlwang/AVDC_change/flowdiffusion/datasets.py", line 391, in get_samples
    seq = self.sequences[idx] # 取某一个目录下的所有图片
IndexError: list index out of range
During handling of the above exception, another exception occurred:
Traceback (most recent call last):
  File "/home/hlwang/AVDC_change/flowdiffusion/datasets.py", line 406, in __getitem__
    samples, actions = self.get_samples(idx)
  File "/home/hlwang/AVDC_change/flowdiffusion/datasets.py", line 391, in get_samples
    seq = self.sequences[idx] # 取某一个目录下的所有图片
IndexError: list index out of range
During handling of the above exception, another exception occurred:
Traceback (most recent call last):
  File "/home/hlwang/AVDC_change/flowdiffusion/datasets.py", line 406, in __getitem__
    samples, actions = self.get_samples(idx)
  File "/home/hlwang/AVDC_change/flowdiffusion/datasets.py", line 391, in get_samples
    seq = self.sequences[idx] # 取某一个目录下的所有图片
IndexError: list index out of range
During handling of the above exception, another exception occurred:
Traceback (most recent call last):
  File "/home/hlwang/AVDC_change/flowdiffusion/datasets.py", line 406, in __getitem__
    samples, actions = self.get_samples(idx)
  File "/home/hlwang/AVDC_change/flowdiffusion/datasets.py", line 391, in get_samples
    seq = self.sequences[idx] # 取某一个目录下的所有图片
IndexError: list index out of range
During handling of the above exception, another exception occurred:
Traceback (most recent call last):
  File "/home/hlwang/AVDC_change/flowdiffusion/datasets.py", line 406, in __getitem__
    samples, actions = self.get_samples(idx)
  File "/home/hlwang/AVDC_change/flowdiffusion/datasets.py", line 391, in get_samples
    seq = self.sequences[idx] # 取某一个目录下的所有图片
IndexError: list index out of range
During handling of the above exception, another exception occurred:
Traceback (most recent call last):
  File "/home/hlwang/AVDC_change/flowdiffusion/datasets.py", line 406, in __getitem__
    samples, actions = self.get_samples(idx)
  File "/home/hlwang/AVDC_change/flowdiffusion/datasets.py", line 391, in get_samples
    seq = self.sequences[idx] # 取某一个目录下的所有图片
IndexError: list index out of range
During handling of the above exception, another exception occurred:
Traceback (most recent call last):
  File "/home/hlwang/AVDC_change/flowdiffusion/datasets.py", line 406, in __getitem__
    samples, actions = self.get_samples(idx)
  File "/home/hlwang/AVDC_change/flowdiffusion/datasets.py", line 391, in get_samples
    seq = self.sequences[idx] # 取某一个目录下的所有图片
IndexError: list index out of range
During handling of the above exception, another exception occurred:
Traceback (most recent call last):
  File "/home/hlwang/AVDC_change/flowdiffusion/datasets.py", line 406, in __getitem__
    samples, actions = self.get_samples(idx)
  File "/home/hlwang/AVDC_change/flowdiffusion/datasets.py", line 391, in get_samples
    seq = self.sequences[idx] # 取某一个目录下的所有图片
IndexError: list index out of range
During handling of the above exception, another exception occurred:
Traceback (most recent call last):
  File "/home/hlwang/AVDC_change/flowdiffusion/datasets.py", line 406, in __getitem__
    samples, actions = self.get_samples(idx)
  File "/home/hlwang/AVDC_change/flowdiffusion/datasets.py", line 391, in get_samples
    seq = self.sequences[idx] # 取某一个目录下的所有图片
IndexError: list index out of range
During handling of the above exception, another exception occurred:
Traceback (most recent call last):
  File "/home/hlwang/AVDC_change/flowdiffusion/datasets.py", line 406, in __getitem__
    samples, actions = self.get_samples(idx)
  File "/home/hlwang/AVDC_change/flowdiffusion/datasets.py", line 391, in get_samples
    seq = self.sequences[idx] # 取某一个目录下的所有图片
IndexError: list index out of range
During handling of the above exception, another exception occurred:
Traceback (most recent call last):
  File "/home/hlwang/AVDC_change/flowdiffusion/datasets.py", line 406, in __getitem__
    samples, actions = self.get_samples(idx)
  File "/home/hlwang/AVDC_change/flowdiffusion/datasets.py", line 391, in get_samples
    seq = self.sequences[idx] # 取某一个目录下的所有图片
IndexError: list index out of range
During handling of the above exception, another exception occurred:
Traceback (most recent call last):
  File "/home/hlwang/AVDC_change/flowdiffusion/datasets.py", line 406, in __getitem__
    samples, actions = self.get_samples(idx)
  File "/home/hlwang/AVDC_change/flowdiffusion/datasets.py", line 391, in get_samples
    seq = self.sequences[idx] # 取某一个目录下的所有图片
IndexError: list index out of range
During handling of the above exception, another exception occurred:
Traceback (most recent call last):
  File "/home/hlwang/AVDC_change/flowdiffusion/datasets.py", line 406, in __getitem__
    samples, actions = self.get_samples(idx)
  File "/home/hlwang/AVDC_change/flowdiffusion/datasets.py", line 391, in get_samples
    seq = self.sequences[idx] # 取某一个目录下的所有图片
IndexError: list index out of range
During handling of the above exception, another exception occurred:
Traceback (most recent call last):
  File "/home/hlwang/AVDC_change/flowdiffusion/datasets.py", line 406, in __getitem__
    samples, actions = self.get_samples(idx)
  File "/home/hlwang/AVDC_change/flowdiffusion/datasets.py", line 391, in get_samples
    seq = self.sequences[idx] # 取某一个目录下的所有图片
IndexError: list index out of range
During handling of the above exception, another exception occurred:
Traceback (most recent call last):
  File "/home/hlwang/AVDC_change/flowdiffusion/datasets.py", line 406, in __getitem__
    samples, actions = self.get_samples(idx)
  File "/home/hlwang/AVDC_change/flowdiffusion/datasets.py", line 391, in get_samples
    seq = self.sequences[idx] # 取某一个目录下的所有图片
IndexError: list index out of range
During handling of the above exception, another exception occurred:
Traceback (most recent call last):
  File "/home/hlwang/AVDC_change/flowdiffusion/datasets.py", line 406, in __getitem__
    samples, actions = self.get_samples(idx)
  File "/home/hlwang/AVDC_change/flowdiffusion/datasets.py", line 391, in get_samples
    seq = self.sequences[idx] # 取某一个目录下的所有图片
IndexError: list index out of range
During handling of the above exception, another exception occurred:
Traceback (most recent call last):
  File "/home/hlwang/AVDC_change/flowdiffusion/datasets.py", line 406, in __getitem__
    samples, actions = self.get_samples(idx)
  File "/home/hlwang/AVDC_change/flowdiffusion/datasets.py", line 391, in get_samples
    seq = self.sequences[idx] # 取某一个目录下的所有图片
IndexError: list index out of range
During handling of the above exception, another exception occurred:
Traceback (most recent call last):
  File "/home/hlwang/AVDC_change/flowdiffusion/datasets.py", line 406, in __getitem__
    samples, actions = self.get_samples(idx)
  File "/home/hlwang/AVDC_change/flowdiffusion/datasets.py", line 391, in get_samples
    seq = self.sequences[idx] # 取某一个目录下的所有图片
IndexError: list index out of range
During handling of the above exception, another exception occurred:
Traceback (most recent call last):
  File "/home/hlwang/AVDC_change/flowdiffusion/datasets.py", line 406, in __getitem__
    samples, actions = self.get_samples(idx)
  File "/home/hlwang/AVDC_change/flowdiffusion/datasets.py", line 391, in get_samples
    seq = self.sequences[idx] # 取某一个目录下的所有图片
IndexError: list index out of range
During handling of the above exception, another exception occurred:
Traceback (most recent call last):
  File "/home/hlwang/AVDC_change/flowdiffusion/datasets.py", line 406, in __getitem__
    samples, actions = self.get_samples(idx)
  File "/home/hlwang/AVDC_change/flowdiffusion/datasets.py", line 391, in get_samples
    seq = self.sequences[idx] # 取某一个目录下的所有图片
IndexError: list index out of range
During handling of the above exception, another exception occurred:
Traceback (most recent call last):
  File "/home/hlwang/AVDC_change/flowdiffusion/datasets.py", line 406, in __getitem__
    samples, actions = self.get_samples(idx)
  File "/home/hlwang/AVDC_change/flowdiffusion/datasets.py", line 391, in get_samples
    seq = self.sequences[idx] # 取某一个目录下的所有图片
IndexError: list index out of range
During handling of the above exception, another exception occurred:
Traceback (most recent call last):
  File "/home/hlwang/AVDC_change/flowdiffusion/datasets.py", line 406, in __getitem__
    samples, actions = self.get_samples(idx)
  File "/home/hlwang/AVDC_change/flowdiffusion/datasets.py", line 391, in get_samples
    seq = self.sequences[idx] # 取某一个目录下的所有图片
IndexError: list index out of range
During handling of the above exception, another exception occurred:
Traceback (most recent call last):
  File "/home/hlwang/AVDC_change/flowdiffusion/datasets.py", line 406, in __getitem__
    samples, actions = self.get_samples(idx)
  File "/home/hlwang/AVDC_change/flowdiffusion/datasets.py", line 391, in get_samples
    seq = self.sequences[idx] # 取某一个目录下的所有图片
IndexError: list index out of range
During handling of the above exception, another exception occurred:
Traceback (most recent call last):
  File "/home/hlwang/AVDC_change/flowdiffusion/datasets.py", line 406, in __getitem__
    samples, actions = self.get_samples(idx)
  File "/home/hlwang/AVDC_change/flowdiffusion/datasets.py", line 391, in get_samples
    seq = self.sequences[idx] # 取某一个目录下的所有图片
IndexError: list index out of range
During handling of the above exception, another exception occurred:
Traceback (most recent call last):
  File "/home/hlwang/AVDC_change/flowdiffusion/datasets.py", line 406, in __getitem__
    samples, actions = self.get_samples(idx)
  File "/home/hlwang/AVDC_change/flowdiffusion/datasets.py", line 391, in get_samples
    seq = self.sequences[idx] # 取某一个目录下的所有图片
IndexError: list index out of range
During handling of the above exception, another exception occurred:
Traceback (most recent call last):
  File "/home/hlwang/AVDC_change/flowdiffusion/datasets.py", line 406, in __getitem__
    samples, actions = self.get_samples(idx)
  File "/home/hlwang/AVDC_change/flowdiffusion/datasets.py", line 391, in get_samples
    seq = self.sequences[idx] # 取某一个目录下的所有图片
IndexError: list index out of range
During handling of the above exception, another exception occurred:
Traceback (most recent call last):
  File "/home/hlwang/AVDC_change/flowdiffusion/datasets.py", line 406, in __getitem__
    samples, actions = self.get_samples(idx)
  File "/home/hlwang/AVDC_change/flowdiffusion/datasets.py", line 391, in get_samples
    seq = self.sequences[idx] # 取某一个目录下的所有图片
IndexError: list index out of range
During handling of the above exception, another exception occurred:
Traceback (most recent call last):
  File "/home/hlwang/AVDC_change/flowdiffusion/datasets.py", line 406, in __getitem__
    samples, actions = self.get_samples(idx)
  File "/home/hlwang/AVDC_change/flowdiffusion/datasets.py", line 391, in get_samples
    seq = self.sequences[idx] # 取某一个目录下的所有图片
IndexError: list index out of range
During handling of the above exception, another exception occurred:
Traceback (most recent call last):
  File "/home/hlwang/AVDC_change/flowdiffusion/datasets.py", line 406, in __getitem__
    samples, actions = self.get_samples(idx)
  File "/home/hlwang/AVDC_change/flowdiffusion/datasets.py", line 391, in get_samples
    seq = self.sequences[idx] # 取某一个目录下的所有图片
IndexError: list index out of range
During handling of the above exception, another exception occurred:
Traceback (most recent call last):
  File "/home/hlwang/AVDC_change/flowdiffusion/datasets.py", line 406, in __getitem__
    samples, actions = self.get_samples(idx)
  File "/home/hlwang/AVDC_change/flowdiffusion/datasets.py", line 391, in get_samples
    seq = self.sequences[idx] # 取某一个目录下的所有图片
IndexError: list index out of range
During handling of the above exception, another exception occurred:
Traceback (most recent call last):
  File "/home/hlwang/AVDC_change/flowdiffusion/datasets.py", line 406, in __getitem__
    samples, actions = self.get_samples(idx)
  File "/home/hlwang/AVDC_change/flowdiffusion/datasets.py", line 391, in get_samples
    seq = self.sequences[idx] # 取某一个目录下的所有图片
IndexError: list index out of range
During handling of the above exception, another exception occurred:
Traceback (most recent call last):
  File "/home/hlwang/AVDC_change/flowdiffusion/datasets.py", line 406, in __getitem__
    samples, actions = self.get_samples(idx)
  File "/home/hlwang/AVDC_change/flowdiffusion/datasets.py", line 391, in get_samples
    seq = self.sequences[idx] # 取某一个目录下的所有图片
IndexError: list index out of range
During handling of the above exception, another exception occurred:
Traceback (most recent call last):
  File "/home/hlwang/AVDC_change/flowdiffusion/datasets.py", line 406, in __getitem__
    samples, actions = self.get_samples(idx)
  File "/home/hlwang/AVDC_change/flowdiffusion/datasets.py", line 391, in get_samples
    seq = self.sequences[idx] # 取某一个目录下的所有图片
IndexError: list index out of range
During handling of the above exception, another exception occurred:
Traceback (most recent call last):
  File "/home/hlwang/AVDC_change/flowdiffusion/datasets.py", line 406, in __getitem__
    samples, actions = self.get_samples(idx)
  File "/home/hlwang/AVDC_change/flowdiffusion/datasets.py", line 391, in get_samples
    seq = self.sequences[idx] # 取某一个目录下的所有图片
IndexError: list index out of range
During handling of the above exception, another exception occurred:
Traceback (most recent call last):
  File "/home/hlwang/AVDC_change/flowdiffusion/datasets.py", line 406, in __getitem__
    samples, actions = self.get_samples(idx)
  File "/home/hlwang/AVDC_change/flowdiffusion/datasets.py", line 391, in get_samples
    seq = self.sequences[idx] # 取某一个目录下的所有图片
IndexError: list index out of range
During handling of the above exception, another exception occurred:
Traceback (most recent call last):
  File "/home/hlwang/AVDC_change/flowdiffusion/datasets.py", line 406, in __getitem__
    samples, actions = self.get_samples(idx)
  File "/home/hlwang/AVDC_change/flowdiffusion/datasets.py", line 391, in get_samples
    seq = self.sequences[idx] # 取某一个目录下的所有图片
IndexError: list index out of range
During handling of the above exception, another exception occurred:
Traceback (most recent call last):
  File "/home/hlwang/AVDC_change/flowdiffusion/datasets.py", line 406, in __getitem__
    samples, actions = self.get_samples(idx)
  File "/home/hlwang/AVDC_change/flowdiffusion/datasets.py", line 391, in get_samples
    seq = self.sequences[idx] # 取某一个目录下的所有图片
IndexError: list index out of range
During handling of the above exception, another exception occurred:
Traceback (most recent call last):
  File "/home/hlwang/AVDC_change/flowdiffusion/datasets.py", line 406, in __getitem__
    samples, actions = self.get_samples(idx)
  File "/home/hlwang/AVDC_change/flowdiffusion/datasets.py", line 391, in get_samples
    seq = self.sequences[idx] # 取某一个目录下的所有图片
IndexError: list index out of range
During handling of the above exception, another exception occurred:
Traceback (most recent call last):
  File "/home/hlwang/AVDC_change/flowdiffusion/datasets.py", line 406, in __getitem__
    samples, actions = self.get_samples(idx)
  File "/home/hlwang/AVDC_change/flowdiffusion/datasets.py", line 391, in get_samples
    seq = self.sequences[idx] # 取某一个目录下的所有图片
IndexError: list index out of range
During handling of the above exception, another exception occurred:
Traceback (most recent call last):
  File "/home/hlwang/AVDC_change/flowdiffusion/datasets.py", line 406, in __getitem__
    samples, actions = self.get_samples(idx)
  File "/home/hlwang/AVDC_change/flowdiffusion/datasets.py", line 391, in get_samples
    seq = self.sequences[idx] # 取某一个目录下的所有图片
IndexError: list index out of range
During handling of the above exception, another exception occurred:
Traceback (most recent call last):
  File "/home/hlwang/AVDC_change/flowdiffusion/datasets.py", line 406, in __getitem__
    samples, actions = self.get_samples(idx)
  File "/home/hlwang/AVDC_change/flowdiffusion/datasets.py", line 391, in get_samples
    seq = self.sequences[idx] # 取某一个目录下的所有图片
IndexError: list index out of range
During handling of the above exception, another exception occurred:
Traceback (most recent call last):
  File "/home/hlwang/AVDC_change/flowdiffusion/datasets.py", line 406, in __getitem__
    samples, actions = self.get_samples(idx)
  File "/home/hlwang/AVDC_change/flowdiffusion/datasets.py", line 391, in get_samples
    seq = self.sequences[idx] # 取某一个目录下的所有图片
IndexError: list index out of range
During handling of the above exception, another exception occurred:
Traceback (most recent call last):
  File "/home/hlwang/AVDC_change/flowdiffusion/datasets.py", line 406, in __getitem__
    samples, actions = self.get_samples(idx)
  File "/home/hlwang/AVDC_change/flowdiffusion/datasets.py", line 391, in get_samples
    seq = self.sequences[idx] # 取某一个目录下的所有图片
IndexError: list index out of range
During handling of the above exception, another exception occurred:
Traceback (most recent call last):
  File "/home/hlwang/AVDC_change/flowdiffusion/datasets.py", line 406, in __getitem__
    samples, actions = self.get_samples(idx)
  File "/home/hlwang/AVDC_change/flowdiffusion/datasets.py", line 391, in get_samples
    seq = self.sequences[idx] # 取某一个目录下的所有图片
IndexError: list index out of range
During handling of the above exception, another exception occurred:
Traceback (most recent call last):
  File "/home/hlwang/AVDC_change/flowdiffusion/datasets.py", line 406, in __getitem__
    samples, actions = self.get_samples(idx)
  File "/home/hlwang/AVDC_change/flowdiffusion/datasets.py", line 391, in get_samples
    seq = self.sequences[idx] # 取某一个目录下的所有图片
IndexError: list index out of range
During handling of the above exception, another exception occurred:
Traceback (most recent call last):
  File "/home/hlwang/AVDC_change/flowdiffusion/datasets.py", line 406, in __getitem__
    samples, actions = self.get_samples(idx)
  File "/home/hlwang/AVDC_change/flowdiffusion/datasets.py", line 391, in get_samples
    seq = self.sequences[idx] # 取某一个目录下的所有图片
IndexError: list index out of range
During handling of the above exception, another exception occurred:
Traceback (most recent call last):
  File "/home/hlwang/AVDC_change/flowdiffusion/datasets.py", line 406, in __getitem__
    samples, actions = self.get_samples(idx)
  File "/home/hlwang/AVDC_change/flowdiffusion/datasets.py", line 391, in get_samples
    seq = self.sequences[idx] # 取某一个目录下的所有图片
IndexError: list index out of range
During handling of the above exception, another exception occurred:
Traceback (most recent call last):
  File "/home/hlwang/AVDC_change/flowdiffusion/datasets.py", line 406, in __getitem__
    samples, actions = self.get_samples(idx)
  File "/home/hlwang/AVDC_change/flowdiffusion/datasets.py", line 391, in get_samples
    seq = self.sequences[idx] # 取某一个目录下的所有图片
IndexError: list index out of range
During handling of the above exception, another exception occurred:
Traceback (most recent call last):
  File "/home/hlwang/AVDC_change/flowdiffusion/datasets.py", line 406, in __getitem__
    samples, actions = self.get_samples(idx)
  File "/home/hlwang/AVDC_change/flowdiffusion/datasets.py", line 391, in get_samples
    seq = self.sequences[idx] # 取某一个目录下的所有图片
IndexError: list index out of range
During handling of the above exception, another exception occurred:
Traceback (most recent call last):
  File "/home/hlwang/AVDC_change/flowdiffusion/datasets.py", line 406, in __getitem__
    samples, actions = self.get_samples(idx)
  File "/home/hlwang/AVDC_change/flowdiffusion/datasets.py", line 391, in get_samples
    seq = self.sequences[idx] # 取某一个目录下的所有图片
IndexError: list index out of range
During handling of the above exception, another exception occurred:
Traceback (most recent call last):
  File "/home/hlwang/AVDC_change/flowdiffusion/datasets.py", line 406, in __getitem__
    samples, actions = self.get_samples(idx)
  File "/home/hlwang/AVDC_change/flowdiffusion/datasets.py", line 391, in get_samples
    seq = self.sequences[idx] # 取某一个目录下的所有图片
IndexError: list index out of range
During handling of the above exception, another exception occurred:
Traceback (most recent call last):
  File "/home/hlwang/AVDC_change/flowdiffusion/datasets.py", line 406, in __getitem__
    samples, actions = self.get_samples(idx)
  File "/home/hlwang/AVDC_change/flowdiffusion/datasets.py", line 391, in get_samples
    seq = self.sequences[idx] # 取某一个目录下的所有图片
IndexError: list index out of range
During handling of the above exception, another exception occurred:
Traceback (most recent call last):
  File "/home/hlwang/AVDC_change/flowdiffusion/datasets.py", line 406, in __getitem__
    samples, actions = self.get_samples(idx)
  File "/home/hlwang/AVDC_change/flowdiffusion/datasets.py", line 391, in get_samples
    seq = self.sequences[idx] # 取某一个目录下的所有图片
IndexError: list index out of range
During handling of the above exception, another exception occurred:
Traceback (most recent call last):
  File "/home/hlwang/AVDC_change/flowdiffusion/datasets.py", line 406, in __getitem__
    samples, actions = self.get_samples(idx)
  File "/home/hlwang/AVDC_change/flowdiffusion/datasets.py", line 391, in get_samples
    seq = self.sequences[idx] # 取某一个目录下的所有图片
IndexError: list index out of range
During handling of the above exception, another exception occurred:
Traceback (most recent call last):
  File "/home/hlwang/AVDC_change/flowdiffusion/datasets.py", line 406, in __getitem__
    samples, actions = self.get_samples(idx)
  File "/home/hlwang/AVDC_change/flowdiffusion/datasets.py", line 391, in get_samples
    seq = self.sequences[idx] # 取某一个目录下的所有图片
IndexError: list index out of range
During handling of the above exception, another exception occurred:
Traceback (most recent call last):
  File "/home/hlwang/AVDC_change/flowdiffusion/datasets.py", line 406, in __getitem__
    samples, actions = self.get_samples(idx)
  File "/home/hlwang/AVDC_change/flowdiffusion/datasets.py", line 391, in get_samples
    seq = self.sequences[idx] # 取某一个目录下的所有图片
IndexError: list index out of range
During handling of the above exception, another exception occurred:
Traceback (most recent call last):
  File "/home/hlwang/AVDC_change/flowdiffusion/datasets.py", line 406, in __getitem__
    samples, actions = self.get_samples(idx)
  File "/home/hlwang/AVDC_change/flowdiffusion/datasets.py", line 391, in get_samples
    seq = self.sequences[idx] # 取某一个目录下的所有图片
IndexError: list index out of range
During handling of the above exception, another exception occurred:
Traceback (most recent call last):
  File "/home/hlwang/AVDC_change/flowdiffusion/datasets.py", line 406, in __getitem__
    samples, actions = self.get_samples(idx)
  File "/home/hlwang/AVDC_change/flowdiffusion/datasets.py", line 391, in get_samples
    seq = self.sequences[idx] # 取某一个目录下的所有图片
IndexError: list index out of range
During handling of the above exception, another exception occurred:
Traceback (most recent call last):
  File "/home/hlwang/AVDC_change/flowdiffusion/datasets.py", line 406, in __getitem__
    samples, actions = self.get_samples(idx)
  File "/home/hlwang/AVDC_change/flowdiffusion/datasets.py", line 391, in get_samples
    seq = self.sequences[idx] # 取某一个目录下的所有图片
IndexError: list index out of range
During handling of the above exception, another exception occurred:
Traceback (most recent call last):
  File "/home/hlwang/AVDC_change/flowdiffusion/datasets.py", line 406, in __getitem__
    samples, actions = self.get_samples(idx)
  File "/home/hlwang/AVDC_change/flowdiffusion/datasets.py", line 391, in get_samples
    seq = self.sequences[idx] # 取某一个目录下的所有图片
IndexError: list index out of range
During handling of the above exception, another exception occurred:
Traceback (most recent call last):
  File "/home/hlwang/AVDC_change/flowdiffusion/datasets.py", line 406, in __getitem__
    samples, actions = self.get_samples(idx)
  File "/home/hlwang/AVDC_change/flowdiffusion/datasets.py", line 391, in get_samples
    seq = self.sequences[idx] # 取某一个目录下的所有图片
IndexError: list index out of range
During handling of the above exception, another exception occurred:
Traceback (most recent call last):
  File "/home/hlwang/AVDC_change/flowdiffusion/datasets.py", line 406, in __getitem__
    samples, actions = self.get_samples(idx)
  File "/home/hlwang/AVDC_change/flowdiffusion/datasets.py", line 391, in get_samples
    seq = self.sequences[idx] # 取某一个目录下的所有图片
IndexError: list index out of range
During handling of the above exception, another exception occurred:
Traceback (most recent call last):
  File "/home/hlwang/AVDC_change/flowdiffusion/datasets.py", line 406, in __getitem__
    samples, actions = self.get_samples(idx)
  File "/home/hlwang/AVDC_change/flowdiffusion/datasets.py", line 391, in get_samples
    seq = self.sequences[idx] # 取某一个目录下的所有图片
IndexError: list index out of range
During handling of the above exception, another exception occurred:
Traceback (most recent call last):
  File "/home/hlwang/AVDC_change/flowdiffusion/datasets.py", line 406, in __getitem__
    samples, actions = self.get_samples(idx)
  File "/home/hlwang/AVDC_change/flowdiffusion/datasets.py", line 391, in get_samples
    seq = self.sequences[idx] # 取某一个目录下的所有图片
IndexError: list index out of range
During handling of the above exception, another exception occurred:
Traceback (most recent call last):
  File "/home/hlwang/AVDC_change/flowdiffusion/datasets.py", line 406, in __getitem__
    samples, actions = self.get_samples(idx)
  File "/home/hlwang/AVDC_change/flowdiffusion/datasets.py", line 391, in get_samples
    seq = self.sequences[idx] # 取某一个目录下的所有图片
IndexError: list index out of range
During handling of the above exception, another exception occurred:
Traceback (most recent call last):
  File "/home/hlwang/AVDC_change/flowdiffusion/datasets.py", line 406, in __getitem__
    samples, actions = self.get_samples(idx)
  File "/home/hlwang/AVDC_change/flowdiffusion/datasets.py", line 391, in get_samples
    seq = self.sequences[idx] # 取某一个目录下的所有图片
IndexError: list index out of range
During handling of the above exception, another exception occurred:
Traceback (most recent call last):
  File "/home/hlwang/AVDC_change/flowdiffusion/datasets.py", line 406, in __getitem__
    samples, actions = self.get_samples(idx)
  File "/home/hlwang/AVDC_change/flowdiffusion/datasets.py", line 391, in get_samples
    seq = self.sequences[idx] # 取某一个目录下的所有图片
IndexError: list index out of range
During handling of the above exception, another exception occurred:
Traceback (most recent call last):
  File "/home/hlwang/AVDC_change/flowdiffusion/datasets.py", line 406, in __getitem__
    samples, actions = self.get_samples(idx)
  File "/home/hlwang/AVDC_change/flowdiffusion/datasets.py", line 391, in get_samples
    seq = self.sequences[idx] # 取某一个目录下的所有图片
IndexError: list index out of range
During handling of the above exception, another exception occurred:
Traceback (most recent call last):
  File "/home/hlwang/AVDC_change/flowdiffusion/datasets.py", line 406, in __getitem__
    samples, actions = self.get_samples(idx)
  File "/home/hlwang/AVDC_change/flowdiffusion/datasets.py", line 391, in get_samples
    seq = self.sequences[idx] # 取某一个目录下的所有图片
IndexError: list index out of range
During handling of the above exception, another exception occurred:
Traceback (most recent call last):
  File "/home/hlwang/AVDC_change/flowdiffusion/datasets.py", line 406, in __getitem__
    samples, actions = self.get_samples(idx)
  File "/home/hlwang/AVDC_change/flowdiffusion/datasets.py", line 391, in get_samples
    seq = self.sequences[idx] # 取某一个目录下的所有图片
IndexError: list index out of range
During handling of the above exception, another exception occurred:
Traceback (most recent call last):
  File "/home/hlwang/AVDC_change/flowdiffusion/datasets.py", line 406, in __getitem__
    samples, actions = self.get_samples(idx)
  File "/home/hlwang/AVDC_change/flowdiffusion/datasets.py", line 391, in get_samples
    seq = self.sequences[idx] # 取某一个目录下的所有图片
IndexError: list index out of range
During handling of the above exception, another exception occurred:
Traceback (most recent call last):
  File "/home/hlwang/AVDC_change/flowdiffusion/datasets.py", line 406, in __getitem__
    samples, actions = self.get_samples(idx)
  File "/home/hlwang/AVDC_change/flowdiffusion/datasets.py", line 391, in get_samples
    seq = self.sequences[idx] # 取某一个目录下的所有图片
IndexError: list index out of range
During handling of the above exception, another exception occurred:
Traceback (most recent call last):
  File "/home/hlwang/AVDC_change/flowdiffusion/datasets.py", line 406, in __getitem__
    samples, actions = self.get_samples(idx)
  File "/home/hlwang/AVDC_change/flowdiffusion/datasets.py", line 391, in get_samples
    seq = self.sequences[idx] # 取某一个目录下的所有图片
IndexError: list index out of range
During handling of the above exception, another exception occurred:
Traceback (most recent call last):
  File "/home/hlwang/AVDC_change/flowdiffusion/datasets.py", line 406, in __getitem__
    samples, actions = self.get_samples(idx)
  File "/home/hlwang/AVDC_change/flowdiffusion/datasets.py", line 391, in get_samples
    seq = self.sequences[idx] # 取某一个目录下的所有图片
IndexError: list index out of range
During handling of the above exception, another exception occurred:
Traceback (most recent call last):
  File "/home/hlwang/AVDC_change/flowdiffusion/datasets.py", line 406, in __getitem__
    samples, actions = self.get_samples(idx)
  File "/home/hlwang/AVDC_change/flowdiffusion/datasets.py", line 391, in get_samples
    seq = self.sequences[idx] # 取某一个目录下的所有图片
IndexError: list index out of range
During handling of the above exception, another exception occurred:
Traceback (most recent call last):
  File "/home/hlwang/AVDC_change/flowdiffusion/datasets.py", line 406, in __getitem__
    samples, actions = self.get_samples(idx)
  File "/home/hlwang/AVDC_change/flowdiffusion/datasets.py", line 391, in get_samples
    seq = self.sequences[idx] # 取某一个目录下的所有图片
IndexError: list index out of range
During handling of the above exception, another exception occurred:
Traceback (most recent call last):
  File "/home/hlwang/AVDC_change/flowdiffusion/datasets.py", line 406, in __getitem__
    samples, actions = self.get_samples(idx)
  File "/home/hlwang/AVDC_change/flowdiffusion/datasets.py", line 391, in get_samples
    seq = self.sequences[idx] # 取某一个目录下的所有图片
IndexError: list index out of range
During handling of the above exception, another exception occurred:
Traceback (most recent call last):
  File "/home/hlwang/AVDC_change/flowdiffusion/datasets.py", line 406, in __getitem__
    samples, actions = self.get_samples(idx)
  File "/home/hlwang/AVDC_change/flowdiffusion/datasets.py", line 391, in get_samples
    seq = self.sequences[idx] # 取某一个目录下的所有图片
IndexError: list index out of range
During handling of the above exception, another exception occurred:
Traceback (most recent call last):
  File "/home/hlwang/AVDC_change/flowdiffusion/datasets.py", line 406, in __getitem__
    samples, actions = self.get_samples(idx)
  File "/home/hlwang/AVDC_change/flowdiffusion/datasets.py", line 391, in get_samples
    seq = self.sequences[idx] # 取某一个目录下的所有图片
IndexError: list index out of range
During handling of the above exception, another exception occurred:
Traceback (most recent call last):
  File "/home/hlwang/AVDC_change/flowdiffusion/datasets.py", line 406, in __getitem__
    samples, actions = self.get_samples(idx)
  File "/home/hlwang/AVDC_change/flowdiffusion/datasets.py", line 391, in get_samples
    seq = self.sequences[idx] # 取某一个目录下的所有图片
IndexError: list index out of range
During handling of the above exception, another exception occurred:
Traceback (most recent call last):
  File "/home/hlwang/AVDC_change/flowdiffusion/datasets.py", line 406, in __getitem__
    samples, actions = self.get_samples(idx)
  File "/home/hlwang/AVDC_change/flowdiffusion/datasets.py", line 391, in get_samples
    seq = self.sequences[idx] # 取某一个目录下的所有图片
IndexError: list index out of range
During handling of the above exception, another exception occurred:
Traceback (most recent call last):
  File "/home/hlwang/AVDC_change/flowdiffusion/datasets.py", line 406, in __getitem__
    samples, actions = self.get_samples(idx)
  File "/home/hlwang/AVDC_change/flowdiffusion/datasets.py", line 391, in get_samples
    seq = self.sequences[idx] # 取某一个目录下的所有图片
IndexError: list index out of range
During handling of the above exception, another exception occurred:
Traceback (most recent call last):
  File "/home/hlwang/AVDC_change/flowdiffusion/datasets.py", line 406, in __getitem__
    samples, actions = self.get_samples(idx)
  File "/home/hlwang/AVDC_change/flowdiffusion/datasets.py", line 391, in get_samples
    seq = self.sequences[idx] # 取某一个目录下的所有图片
IndexError: list index out of range
During handling of the above exception, another exception occurred:
Traceback (most recent call last):
  File "/home/hlwang/AVDC_change/flowdiffusion/datasets.py", line 406, in __getitem__
    samples, actions = self.get_samples(idx)
  File "/home/hlwang/AVDC_change/flowdiffusion/datasets.py", line 391, in get_samples
    seq = self.sequences[idx] # 取某一个目录下的所有图片
IndexError: list index out of range
During handling of the above exception, another exception occurred:
Traceback (most recent call last):
  File "/home/hlwang/AVDC_change/flowdiffusion/datasets.py", line 406, in __getitem__
    samples, actions = self.get_samples(idx)
  File "/home/hlwang/AVDC_change/flowdiffusion/datasets.py", line 391, in get_samples
    seq = self.sequences[idx] # 取某一个目录下的所有图片
IndexError: list index out of range
During handling of the above exception, another exception occurred:
Traceback (most recent call last):
  File "/home/hlwang/AVDC_change/flowdiffusion/datasets.py", line 406, in __getitem__
    samples, actions = self.get_samples(idx)
  File "/home/hlwang/AVDC_change/flowdiffusion/datasets.py", line 391, in get_samples
    seq = self.sequences[idx] # 取某一个目录下的所有图片
IndexError: list index out of range
During handling of the above exception, another exception occurred:
Traceback (most recent call last):
  File "/home/hlwang/AVDC_change/flowdiffusion/datasets.py", line 406, in __getitem__
    samples, actions = self.get_samples(idx)
  File "/home/hlwang/AVDC_change/flowdiffusion/datasets.py", line 391, in get_samples
    seq = self.sequences[idx] # 取某一个目录下的所有图片
IndexError: list index out of range
During handling of the above exception, another exception occurred:
Traceback (most recent call last):
  File "/home/hlwang/AVDC_change/flowdiffusion/datasets.py", line 406, in __getitem__
    samples, actions = self.get_samples(idx)
  File "/home/hlwang/AVDC_change/flowdiffusion/datasets.py", line 391, in get_samples
    seq = self.sequences[idx] # 取某一个目录下的所有图片
IndexError: list index out of range
During handling of the above exception, another exception occurred:
Traceback (most recent call last):
  File "/home/hlwang/AVDC_change/flowdiffusion/datasets.py", line 406, in __getitem__
    samples, actions = self.get_samples(idx)
  File "/home/hlwang/AVDC_change/flowdiffusion/datasets.py", line 391, in get_samples
    seq = self.sequences[idx] # 取某一个目录下的所有图片
IndexError: list index out of range
During handling of the above exception, another exception occurred:
Traceback (most recent call last):
  File "/home/hlwang/AVDC_change/flowdiffusion/datasets.py", line 406, in __getitem__
    samples, actions = self.get_samples(idx)
  File "/home/hlwang/AVDC_change/flowdiffusion/datasets.py", line 391, in get_samples
    seq = self.sequences[idx] # 取某一个目录下的所有图片
IndexError: list index out of range
During handling of the above exception, another exception occurred:
Traceback (most recent call last):
  File "/home/hlwang/AVDC_change/flowdiffusion/datasets.py", line 406, in __getitem__
    samples, actions = self.get_samples(idx)
  File "/home/hlwang/AVDC_change/flowdiffusion/datasets.py", line 391, in get_samples
    seq = self.sequences[idx] # 取某一个目录下的所有图片
IndexError: list index out of range
During handling of the above exception, another exception occurred:
Traceback (most recent call last):
  File "/home/hlwang/AVDC_change/flowdiffusion/datasets.py", line 406, in __getitem__
    samples, actions = self.get_samples(idx)
  File "/home/hlwang/AVDC_change/flowdiffusion/datasets.py", line 391, in get_samples
    seq = self.sequences[idx] # 取某一个目录下的所有图片
IndexError: list index out of range
During handling of the above exception, another exception occurred:
Traceback (most recent call last):
  File "/home/hlwang/AVDC_change/flowdiffusion/datasets.py", line 406, in __getitem__
    samples, actions = self.get_samples(idx)
  File "/home/hlwang/AVDC_change/flowdiffusion/datasets.py", line 391, in get_samples
    seq = self.sequences[idx] # 取某一个目录下的所有图片
IndexError: list index out of range
During handling of the above exception, another exception occurred:
Traceback (most recent call last):
  File "/home/hlwang/AVDC_change/flowdiffusion/datasets.py", line 406, in __getitem__
    samples, actions = self.get_samples(idx)
  File "/home/hlwang/AVDC_change/flowdiffusion/datasets.py", line 391, in get_samples
    seq = self.sequences[idx] # 取某一个目录下的所有图片
IndexError: list index out of range
During handling of the above exception, another exception occurred:
Traceback (most recent call last):
  File "/home/hlwang/AVDC_change/flowdiffusion/datasets.py", line 406, in __getitem__
    samples, actions = self.get_samples(idx)
  File "/home/hlwang/AVDC_change/flowdiffusion/datasets.py", line 391, in get_samples
    seq = self.sequences[idx] # 取某一个目录下的所有图片
IndexError: list index out of range
During handling of the above exception, another exception occurred:
Traceback (most recent call last):
  File "/home/hlwang/AVDC_change/flowdiffusion/datasets.py", line 406, in __getitem__
    samples, actions = self.get_samples(idx)
  File "/home/hlwang/AVDC_change/flowdiffusion/datasets.py", line 391, in get_samples
    seq = self.sequences[idx] # 取某一个目录下的所有图片
IndexError: list index out of range
During handling of the above exception, another exception occurred:
Traceback (most recent call last):
  File "/home/hlwang/AVDC_change/flowdiffusion/datasets.py", line 406, in __getitem__
    samples, actions = self.get_samples(idx)
  File "/home/hlwang/AVDC_change/flowdiffusion/datasets.py", line 391, in get_samples
    seq = self.sequences[idx] # 取某一个目录下的所有图片
IndexError: list index out of range
During handling of the above exception, another exception occurred:
Traceback (most recent call last):
  File "/home/hlwang/AVDC_change/flowdiffusion/datasets.py", line 406, in __getitem__
    samples, actions = self.get_samples(idx)
  File "/home/hlwang/AVDC_change/flowdiffusion/datasets.py", line 391, in get_samples
    seq = self.sequences[idx] # 取某一个目录下的所有图片
IndexError: list index out of range
During handling of the above exception, another exception occurred:
Traceback (most recent call last):
  File "/home/hlwang/AVDC_change/flowdiffusion/datasets.py", line 406, in __getitem__
    samples, actions = self.get_samples(idx)
  File "/home/hlwang/AVDC_change/flowdiffusion/datasets.py", line 391, in get_samples
    seq = self.sequences[idx] # 取某一个目录下的所有图片
IndexError: list index out of range
During handling of the above exception, another exception occurred:
Traceback (most recent call last):
  File "/home/hlwang/AVDC_change/flowdiffusion/datasets.py", line 406, in __getitem__
    samples, actions = self.get_samples(idx)
  File "/home/hlwang/AVDC_change/flowdiffusion/datasets.py", line 391, in get_samples
    seq = self.sequences[idx] # 取某一个目录下的所有图片
IndexError: list index out of range
During handling of the above exception, another exception occurred:
Traceback (most recent call last):
  File "/home/hlwang/AVDC_change/flowdiffusion/datasets.py", line 406, in __getitem__
    samples, actions = self.get_samples(idx)
  File "/home/hlwang/AVDC_change/flowdiffusion/datasets.py", line 391, in get_samples
    seq = self.sequences[idx] # 取某一个目录下的所有图片
IndexError: list index out of range
During handling of the above exception, another exception occurred:
Traceback (most recent call last):
  File "/home/hlwang/AVDC_change/flowdiffusion/datasets.py", line 406, in __getitem__
    samples, actions = self.get_samples(idx)
  File "/home/hlwang/AVDC_change/flowdiffusion/datasets.py", line 391, in get_samples
    seq = self.sequences[idx] # 取某一个目录下的所有图片
IndexError: list index out of range
During handling of the above exception, another exception occurred:
Traceback (most recent call last):
  File "/home/hlwang/AVDC_change/flowdiffusion/datasets.py", line 406, in __getitem__
    samples, actions = self.get_samples(idx)
  File "/home/hlwang/AVDC_change/flowdiffusion/datasets.py", line 391, in get_samples
    seq = self.sequences[idx] # 取某一个目录下的所有图片
IndexError: list index out of range
During handling of the above exception, another exception occurred:
Traceback (most recent call last):
  File "/home/hlwang/AVDC_change/flowdiffusion/datasets.py", line 406, in __getitem__
    samples, actions = self.get_samples(idx)
  File "/home/hlwang/AVDC_change/flowdiffusion/datasets.py", line 391, in get_samples
    seq = self.sequences[idx] # 取某一个目录下的所有图片
IndexError: list index out of range
During handling of the above exception, another exception occurred:
Traceback (most recent call last):
  File "/home/hlwang/AVDC_change/flowdiffusion/datasets.py", line 406, in __getitem__
    samples, actions = self.get_samples(idx)
  File "/home/hlwang/AVDC_change/flowdiffusion/datasets.py", line 391, in get_samples
    seq = self.sequences[idx] # 取某一个目录下的所有图片
IndexError: list index out of range
During handling of the above exception, another exception occurred:
Traceback (most recent call last):
  File "/home/hlwang/AVDC_change/flowdiffusion/datasets.py", line 406, in __getitem__
    samples, actions = self.get_samples(idx)
  File "/home/hlwang/AVDC_change/flowdiffusion/datasets.py", line 391, in get_samples
    seq = self.sequences[idx] # 取某一个目录下的所有图片
IndexError: list index out of range
During handling of the above exception, another exception occurred:
Traceback (most recent call last):
  File "/home/hlwang/AVDC_change/flowdiffusion/datasets.py", line 406, in __getitem__
    samples, actions = self.get_samples(idx)
  File "/home/hlwang/AVDC_change/flowdiffusion/datasets.py", line 391, in get_samples
    seq = self.sequences[idx] # 取某一个目录下的所有图片
IndexError: list index out of range
During handling of the above exception, another exception occurred:
Traceback (most recent call last):
  File "/home/hlwang/AVDC_change/flowdiffusion/datasets.py", line 406, in __getitem__
    samples, actions = self.get_samples(idx)
  File "/home/hlwang/AVDC_change/flowdiffusion/datasets.py", line 391, in get_samples
    seq = self.sequences[idx] # 取某一个目录下的所有图片
IndexError: list index out of range
During handling of the above exception, another exception occurred:
Traceback (most recent call last):
  File "/home/hlwang/AVDC_change/flowdiffusion/datasets.py", line 406, in __getitem__
    samples, actions = self.get_samples(idx)
  File "/home/hlwang/AVDC_change/flowdiffusion/datasets.py", line 391, in get_samples
    seq = self.sequences[idx] # 取某一个目录下的所有图片
IndexError: list index out of range
During handling of the above exception, another exception occurred:
Traceback (most recent call last):
  File "/home/hlwang/AVDC_change/flowdiffusion/datasets.py", line 406, in __getitem__
    samples, actions = self.get_samples(idx)
  File "/home/hlwang/AVDC_change/flowdiffusion/datasets.py", line 391, in get_samples
    seq = self.sequences[idx] # 取某一个目录下的所有图片
IndexError: list index out of range
During handling of the above exception, another exception occurred:
Traceback (most recent call last):
  File "/home/hlwang/AVDC_change/flowdiffusion/datasets.py", line 406, in __getitem__
    samples, actions = self.get_samples(idx)
  File "/home/hlwang/AVDC_change/flowdiffusion/datasets.py", line 391, in get_samples
    seq = self.sequences[idx] # 取某一个目录下的所有图片
IndexError: list index out of range
During handling of the above exception, another exception occurred:
Traceback (most recent call last):
  File "/home/hlwang/AVDC_change/flowdiffusion/datasets.py", line 406, in __getitem__
    samples, actions = self.get_samples(idx)
  File "/home/hlwang/AVDC_change/flowdiffusion/datasets.py", line 391, in get_samples
    seq = self.sequences[idx] # 取某一个目录下的所有图片
IndexError: list index out of range
During handling of the above exception, another exception occurred:
Traceback (most recent call last):
  File "/home/hlwang/AVDC_change/flowdiffusion/datasets.py", line 406, in __getitem__
    samples, actions = self.get_samples(idx)
  File "/home/hlwang/AVDC_change/flowdiffusion/datasets.py", line 391, in get_samples
    seq = self.sequences[idx] # 取某一个目录下的所有图片
IndexError: list index out of range
During handling of the above exception, another exception occurred:
Traceback (most recent call last):
  File "/home/hlwang/AVDC_change/flowdiffusion/datasets.py", line 406, in __getitem__
    samples, actions = self.get_samples(idx)
  File "/home/hlwang/AVDC_change/flowdiffusion/datasets.py", line 391, in get_samples
    seq = self.sequences[idx] # 取某一个目录下的所有图片
IndexError: list index out of range
During handling of the above exception, another exception occurred:
Traceback (most recent call last):
  File "/home/hlwang/AVDC_change/flowdiffusion/datasets.py", line 406, in __getitem__
    samples, actions = self.get_samples(idx)
  File "/home/hlwang/AVDC_change/flowdiffusion/datasets.py", line 391, in get_samples
    seq = self.sequences[idx] # 取某一个目录下的所有图片
IndexError: list index out of range
During handling of the above exception, another exception occurred:
Traceback (most recent call last):
  File "/home/hlwang/AVDC_change/flowdiffusion/datasets.py", line 406, in __getitem__
    samples, actions = self.get_samples(idx)
  File "/home/hlwang/AVDC_change/flowdiffusion/datasets.py", line 391, in get_samples
    seq = self.sequences[idx] # 取某一个目录下的所有图片
IndexError: list index out of range
During handling of the above exception, another exception occurred:
Traceback (most recent call last):
  File "/home/hlwang/AVDC_change/flowdiffusion/datasets.py", line 406, in __getitem__
    samples, actions = self.get_samples(idx)
  File "/home/hlwang/AVDC_change/flowdiffusion/datasets.py", line 391, in get_samples
    seq = self.sequences[idx] # 取某一个目录下的所有图片
IndexError: list index out of range
During handling of the above exception, another exception occurred:
Traceback (most recent call last):
  File "/home/hlwang/AVDC_change/flowdiffusion/datasets.py", line 406, in __getitem__
    samples, actions = self.get_samples(idx)
  File "/home/hlwang/AVDC_change/flowdiffusion/datasets.py", line 391, in get_samples
    seq = self.sequences[idx] # 取某一个目录下的所有图片
IndexError: list index out of range
During handling of the above exception, another exception occurred:
Traceback (most recent call last):
  File "/home/hlwang/AVDC_change/flowdiffusion/datasets.py", line 406, in __getitem__
    samples, actions = self.get_samples(idx)
  File "/home/hlwang/AVDC_change/flowdiffusion/datasets.py", line 391, in get_samples
    seq = self.sequences[idx] # 取某一个目录下的所有图片
IndexError: list index out of range
During handling of the above exception, another exception occurred:
Traceback (most recent call last):
  File "/home/hlwang/AVDC_change/flowdiffusion/datasets.py", line 406, in __getitem__
    samples, actions = self.get_samples(idx)
  File "/home/hlwang/AVDC_change/flowdiffusion/datasets.py", line 391, in get_samples
    seq = self.sequences[idx] # 取某一个目录下的所有图片
IndexError: list index out of range
During handling of the above exception, another exception occurred:
Traceback (most recent call last):
  File "/home/hlwang/AVDC_change/flowdiffusion/datasets.py", line 406, in __getitem__
    samples, actions = self.get_samples(idx)
  File "/home/hlwang/AVDC_change/flowdiffusion/datasets.py", line 391, in get_samples
    seq = self.sequences[idx] # 取某一个目录下的所有图片
IndexError: list index out of range
During handling of the above exception, another exception occurred:
Traceback (most recent call last):
  File "/home/hlwang/AVDC_change/flowdiffusion/datasets.py", line 406, in __getitem__
    samples, actions = self.get_samples(idx)
  File "/home/hlwang/AVDC_change/flowdiffusion/datasets.py", line 391, in get_samples
    seq = self.sequences[idx] # 取某一个目录下的所有图片
IndexError: list index out of range
During handling of the above exception, another exception occurred:
Traceback (most recent call last):
  File "/home/hlwang/AVDC_change/flowdiffusion/datasets.py", line 406, in __getitem__
    samples, actions = self.get_samples(idx)
  File "/home/hlwang/AVDC_change/flowdiffusion/datasets.py", line 391, in get_samples
    seq = self.sequences[idx] # 取某一个目录下的所有图片
IndexError: list index out of range
During handling of the above exception, another exception occurred:
Traceback (most recent call last):
  File "/home/hlwang/AVDC_change/flowdiffusion/datasets.py", line 406, in __getitem__
    samples, actions = self.get_samples(idx)
  File "/home/hlwang/AVDC_change/flowdiffusion/datasets.py", line 391, in get_samples
    seq = self.sequences[idx] # 取某一个目录下的所有图片
IndexError: list index out of range
During handling of the above exception, another exception occurred:
Traceback (most recent call last):
  File "/home/hlwang/AVDC_change/flowdiffusion/datasets.py", line 406, in __getitem__
    samples, actions = self.get_samples(idx)
  File "/home/hlwang/AVDC_change/flowdiffusion/datasets.py", line 391, in get_samples
    seq = self.sequences[idx] # 取某一个目录下的所有图片
IndexError: list index out of range
During handling of the above exception, another exception occurred:
Traceback (most recent call last):
  File "/home/hlwang/AVDC_change/flowdiffusion/datasets.py", line 406, in __getitem__
    samples, actions = self.get_samples(idx)
  File "/home/hlwang/AVDC_change/flowdiffusion/datasets.py", line 391, in get_samples
    seq = self.sequences[idx] # 取某一个目录下的所有图片
IndexError: list index out of range
During handling of the above exception, another exception occurred:
Traceback (most recent call last):
  File "/home/hlwang/AVDC_change/flowdiffusion/datasets.py", line 406, in __getitem__
    samples, actions = self.get_samples(idx)
  File "/home/hlwang/AVDC_change/flowdiffusion/datasets.py", line 391, in get_samples
    seq = self.sequences[idx] # 取某一个目录下的所有图片
IndexError: list index out of range
During handling of the above exception, another exception occurred:
Traceback (most recent call last):
  File "/home/hlwang/AVDC_change/flowdiffusion/datasets.py", line 406, in __getitem__
    samples, actions = self.get_samples(idx)
  File "/home/hlwang/AVDC_change/flowdiffusion/datasets.py", line 391, in get_samples
    seq = self.sequences[idx] # 取某一个目录下的所有图片
IndexError: list index out of range
During handling of the above exception, another exception occurred:
Traceback (most recent call last):
  File "/home/hlwang/AVDC_change/flowdiffusion/datasets.py", line 406, in __getitem__
    samples, actions = self.get_samples(idx)
  File "/home/hlwang/AVDC_change/flowdiffusion/datasets.py", line 391, in get_samples
    seq = self.sequences[idx] # 取某一个目录下的所有图片
IndexError: list index out of range
During handling of the above exception, another exception occurred:
Traceback (most recent call last):
  File "/home/hlwang/AVDC_change/flowdiffusion/datasets.py", line 406, in __getitem__
    samples, actions = self.get_samples(idx)
  File "/home/hlwang/AVDC_change/flowdiffusion/datasets.py", line 391, in get_samples
    seq = self.sequences[idx] # 取某一个目录下的所有图片
IndexError: list index out of range
During handling of the above exception, another exception occurred:
Traceback (most recent call last):
  File "/home/hlwang/AVDC_change/flowdiffusion/datasets.py", line 406, in __getitem__
    samples, actions = self.get_samples(idx)
  File "/home/hlwang/AVDC_change/flowdiffusion/datasets.py", line 391, in get_samples
    seq = self.sequences[idx] # 取某一个目录下的所有图片
IndexError: list index out of range
During handling of the above exception, another exception occurred:
Traceback (most recent call last):
  File "/home/hlwang/AVDC_change/flowdiffusion/datasets.py", line 406, in __getitem__
    samples, actions = self.get_samples(idx)
  File "/home/hlwang/AVDC_change/flowdiffusion/datasets.py", line 391, in get_samples
    seq = self.sequences[idx] # 取某一个目录下的所有图片
IndexError: list index out of range
During handling of the above exception, another exception occurred:
Traceback (most recent call last):
  File "/home/hlwang/AVDC_change/flowdiffusion/datasets.py", line 406, in __getitem__
    samples, actions = self.get_samples(idx)
  File "/home/hlwang/AVDC_change/flowdiffusion/datasets.py", line 391, in get_samples
    seq = self.sequences[idx] # 取某一个目录下的所有图片
IndexError: list index out of range
During handling of the above exception, another exception occurred:
Traceback (most recent call last):
  File "/home/hlwang/AVDC_change/flowdiffusion/datasets.py", line 406, in __getitem__
    samples, actions = self.get_samples(idx)
  File "/home/hlwang/AVDC_change/flowdiffusion/datasets.py", line 391, in get_samples
    seq = self.sequences[idx] # 取某一个目录下的所有图片
IndexError: list index out of range
During handling of the above exception, another exception occurred:
Traceback (most recent call last):
  File "/home/hlwang/AVDC_change/flowdiffusion/datasets.py", line 406, in __getitem__
    samples, actions = self.get_samples(idx)
  File "/home/hlwang/AVDC_change/flowdiffusion/datasets.py", line 391, in get_samples
    seq = self.sequences[idx] # 取某一个目录下的所有图片
IndexError: list index out of range
During handling of the above exception, another exception occurred:
Traceback (most recent call last):
  File "/home/hlwang/AVDC_change/flowdiffusion/datasets.py", line 406, in __getitem__
    samples, actions = self.get_samples(idx)
  File "/home/hlwang/AVDC_change/flowdiffusion/datasets.py", line 391, in get_samples
    seq = self.sequences[idx] # 取某一个目录下的所有图片
IndexError: list index out of range
During handling of the above exception, another exception occurred:
Traceback (most recent call last):
  File "/home/hlwang/AVDC_change/flowdiffusion/datasets.py", line 406, in __getitem__
    samples, actions = self.get_samples(idx)
  File "/home/hlwang/AVDC_change/flowdiffusion/datasets.py", line 391, in get_samples
    seq = self.sequences[idx] # 取某一个目录下的所有图片
IndexError: list index out of range
During handling of the above exception, another exception occurred:
Traceback (most recent call last):
  File "/home/hlwang/AVDC_change/flowdiffusion/datasets.py", line 406, in __getitem__
    samples, actions = self.get_samples(idx)
  File "/home/hlwang/AVDC_change/flowdiffusion/datasets.py", line 391, in get_samples
    seq = self.sequences[idx] # 取某一个目录下的所有图片
IndexError: list index out of range
During handling of the above exception, another exception occurred:
Traceback (most recent call last):
  File "/home/hlwang/AVDC_change/flowdiffusion/datasets.py", line 406, in __getitem__
    samples, actions = self.get_samples(idx)
  File "/home/hlwang/AVDC_change/flowdiffusion/datasets.py", line 391, in get_samples
    seq = self.sequences[idx] # 取某一个目录下的所有图片
IndexError: list index out of range
During handling of the above exception, another exception occurred:
Traceback (most recent call last):
  File "/home/hlwang/AVDC_change/flowdiffusion/datasets.py", line 406, in __getitem__
    samples, actions = self.get_samples(idx)
  File "/home/hlwang/AVDC_change/flowdiffusion/datasets.py", line 391, in get_samples
    seq = self.sequences[idx] # 取某一个目录下的所有图片
IndexError: list index out of range
During handling of the above exception, another exception occurred:
Traceback (most recent call last):
  File "/home/hlwang/AVDC_change/flowdiffusion/datasets.py", line 406, in __getitem__
    samples, actions = self.get_samples(idx)
  File "/home/hlwang/AVDC_change/flowdiffusion/datasets.py", line 391, in get_samples
    seq = self.sequences[idx] # 取某一个目录下的所有图片
IndexError: list index out of range
During handling of the above exception, another exception occurred:
Traceback (most recent call last):
  File "/home/hlwang/AVDC_change/flowdiffusion/datasets.py", line 406, in __getitem__
    samples, actions = self.get_samples(idx)
  File "/home/hlwang/AVDC_change/flowdiffusion/datasets.py", line 391, in get_samples
    seq = self.sequences[idx] # 取某一个目录下的所有图片
IndexError: list index out of range
During handling of the above exception, another exception occurred:
Traceback (most recent call last):
  File "/home/hlwang/AVDC_change/flowdiffusion/datasets.py", line 406, in __getitem__
    samples, actions = self.get_samples(idx)
  File "/home/hlwang/AVDC_change/flowdiffusion/datasets.py", line 391, in get_samples
    seq = self.sequences[idx] # 取某一个目录下的所有图片
IndexError: list index out of range
During handling of the above exception, another exception occurred:
Traceback (most recent call last):
  File "/home/hlwang/AVDC_change/flowdiffusion/datasets.py", line 406, in __getitem__
    samples, actions = self.get_samples(idx)
  File "/home/hlwang/AVDC_change/flowdiffusion/datasets.py", line 391, in get_samples
    seq = self.sequences[idx] # 取某一个目录下的所有图片
IndexError: list index out of range
During handling of the above exception, another exception occurred:
Traceback (most recent call last):
  File "/home/hlwang/AVDC_change/flowdiffusion/datasets.py", line 406, in __getitem__
    samples, actions = self.get_samples(idx)
  File "/home/hlwang/AVDC_change/flowdiffusion/datasets.py", line 391, in get_samples
    seq = self.sequences[idx] # 取某一个目录下的所有图片
IndexError: list index out of range
During handling of the above exception, another exception occurred:
Traceback (most recent call last):
  File "/home/hlwang/AVDC_change/flowdiffusion/datasets.py", line 406, in __getitem__
    samples, actions = self.get_samples(idx)
  File "/home/hlwang/AVDC_change/flowdiffusion/datasets.py", line 391, in get_samples
    seq = self.sequences[idx] # 取某一个目录下的所有图片
IndexError: list index out of range
During handling of the above exception, another exception occurred:
Traceback (most recent call last):
  File "/home/hlwang/AVDC_change/flowdiffusion/datasets.py", line 406, in __getitem__
    samples, actions = self.get_samples(idx)
  File "/home/hlwang/AVDC_change/flowdiffusion/datasets.py", line 391, in get_samples
    seq = self.sequences[idx] # 取某一个目录下的所有图片
IndexError: list index out of range
During handling of the above exception, another exception occurred:
Traceback (most recent call last):
  File "/home/hlwang/AVDC_change/flowdiffusion/datasets.py", line 406, in __getitem__
    samples, actions = self.get_samples(idx)
  File "/home/hlwang/AVDC_change/flowdiffusion/datasets.py", line 391, in get_samples
    seq = self.sequences[idx] # 取某一个目录下的所有图片
IndexError: list index out of range
During handling of the above exception, another exception occurred:
Traceback (most recent call last):
  File "/home/hlwang/AVDC_change/flowdiffusion/datasets.py", line 406, in __getitem__
    samples, actions = self.get_samples(idx)
  File "/home/hlwang/AVDC_change/flowdiffusion/datasets.py", line 391, in get_samples
    seq = self.sequences[idx] # 取某一个目录下的所有图片
IndexError: list index out of range
During handling of the above exception, another exception occurred:
Traceback (most recent call last):
  File "/home/hlwang/AVDC_change/flowdiffusion/datasets.py", line 406, in __getitem__
    samples, actions = self.get_samples(idx)
  File "/home/hlwang/AVDC_change/flowdiffusion/datasets.py", line 391, in get_samples
    seq = self.sequences[idx] # 取某一个目录下的所有图片
IndexError: list index out of range
During handling of the above exception, another exception occurred:
Traceback (most recent call last):
  File "/home/hlwang/AVDC_change/flowdiffusion/datasets.py", line 406, in __getitem__
    samples, actions = self.get_samples(idx)
  File "/home/hlwang/AVDC_change/flowdiffusion/datasets.py", line 391, in get_samples
    seq = self.sequences[idx] # 取某一个目录下的所有图片
IndexError: list index out of range
During handling of the above exception, another exception occurred:
Traceback (most recent call last):
  File "/home/hlwang/AVDC_change/flowdiffusion/datasets.py", line 406, in __getitem__
    samples, actions = self.get_samples(idx)
  File "/home/hlwang/AVDC_change/flowdiffusion/datasets.py", line 391, in get_samples
    seq = self.sequences[idx] # 取某一个目录下的所有图片
IndexError: list index out of range
During handling of the above exception, another exception occurred:
Traceback (most recent call last):
  File "/home/hlwang/AVDC_change/flowdiffusion/datasets.py", line 406, in __getitem__
    samples, actions = self.get_samples(idx)
  File "/home/hlwang/AVDC_change/flowdiffusion/datasets.py", line 391, in get_samples
    seq = self.sequences[idx] # 取某一个目录下的所有图片
IndexError: list index out of range
During handling of the above exception, another exception occurred:
Traceback (most recent call last):
  File "/home/hlwang/AVDC_change/flowdiffusion/datasets.py", line 406, in __getitem__
    samples, actions = self.get_samples(idx)
  File "/home/hlwang/AVDC_change/flowdiffusion/datasets.py", line 391, in get_samples
    seq = self.sequences[idx] # 取某一个目录下的所有图片
IndexError: list index out of range
During handling of the above exception, another exception occurred:
Traceback (most recent call last):
  File "/home/hlwang/AVDC_change/flowdiffusion/datasets.py", line 406, in __getitem__
    samples, actions = self.get_samples(idx)
  File "/home/hlwang/AVDC_change/flowdiffusion/datasets.py", line 391, in get_samples
    seq = self.sequences[idx] # 取某一个目录下的所有图片
IndexError: list index out of range
During handling of the above exception, another exception occurred:
Traceback (most recent call last):
  File "/home/hlwang/AVDC_change/flowdiffusion/datasets.py", line 406, in __getitem__
    samples, actions = self.get_samples(idx)
  File "/home/hlwang/AVDC_change/flowdiffusion/datasets.py", line 391, in get_samples
    seq = self.sequences[idx] # 取某一个目录下的所有图片
IndexError: list index out of range
During handling of the above exception, another exception occurred:
Traceback (most recent call last):
  File "/home/hlwang/AVDC_change/flowdiffusion/datasets.py", line 406, in __getitem__
    samples, actions = self.get_samples(idx)
  File "/home/hlwang/AVDC_change/flowdiffusion/datasets.py", line 391, in get_samples
    seq = self.sequences[idx] # 取某一个目录下的所有图片
IndexError: list index out of range
During handling of the above exception, another exception occurred:
Traceback (most recent call last):
  File "/home/hlwang/AVDC_change/flowdiffusion/datasets.py", line 406, in __getitem__
    samples, actions = self.get_samples(idx)
  File "/home/hlwang/AVDC_change/flowdiffusion/datasets.py", line 391, in get_samples
    seq = self.sequences[idx] # 取某一个目录下的所有图片
IndexError: list index out of range
During handling of the above exception, another exception occurred:
Traceback (most recent call last):
  File "/home/hlwang/AVDC_change/flowdiffusion/datasets.py", line 406, in __getitem__
    samples, actions = self.get_samples(idx)
  File "/home/hlwang/AVDC_change/flowdiffusion/datasets.py", line 391, in get_samples
    seq = self.sequences[idx] # 取某一个目录下的所有图片
IndexError: list index out of range
During handling of the above exception, another exception occurred:
Traceback (most recent call last):
  File "/home/hlwang/AVDC_change/flowdiffusion/datasets.py", line 406, in __getitem__
    samples, actions = self.get_samples(idx)
  File "/home/hlwang/AVDC_change/flowdiffusion/datasets.py", line 391, in get_samples
    seq = self.sequences[idx] # 取某一个目录下的所有图片
IndexError: list index out of range
During handling of the above exception, another exception occurred:
Traceback (most recent call last):
  File "/home/hlwang/AVDC_change/flowdiffusion/datasets.py", line 406, in __getitem__
    samples, actions = self.get_samples(idx)
  File "/home/hlwang/AVDC_change/flowdiffusion/datasets.py", line 391, in get_samples
    seq = self.sequences[idx] # 取某一个目录下的所有图片
IndexError: list index out of range
During handling of the above exception, another exception occurred:
Traceback (most recent call last):
  File "/home/hlwang/AVDC_change/flowdiffusion/datasets.py", line 406, in __getitem__
    samples, actions = self.get_samples(idx)
  File "/home/hlwang/AVDC_change/flowdiffusion/datasets.py", line 391, in get_samples
    seq = self.sequences[idx] # 取某一个目录下的所有图片
IndexError: list index out of range
During handling of the above exception, another exception occurred:
Traceback (most recent call last):
  File "/home/hlwang/AVDC_change/flowdiffusion/datasets.py", line 406, in __getitem__
    samples, actions = self.get_samples(idx)
  File "/home/hlwang/AVDC_change/flowdiffusion/datasets.py", line 391, in get_samples
    seq = self.sequences[idx] # 取某一个目录下的所有图片
IndexError: list index out of range
During handling of the above exception, another exception occurred:
Traceback (most recent call last):
  File "/home/hlwang/AVDC_change/flowdiffusion/datasets.py", line 406, in __getitem__
    samples, actions = self.get_samples(idx)
  File "/home/hlwang/AVDC_change/flowdiffusion/datasets.py", line 391, in get_samples
    seq = self.sequences[idx] # 取某一个目录下的所有图片
IndexError: list index out of range
During handling of the above exception, another exception occurred:
Traceback (most recent call last):
  File "/home/hlwang/AVDC_change/flowdiffusion/datasets.py", line 406, in __getitem__
    samples, actions = self.get_samples(idx)
  File "/home/hlwang/AVDC_change/flowdiffusion/datasets.py", line 391, in get_samples
    seq = self.sequences[idx] # 取某一个目录下的所有图片
IndexError: list index out of range
During handling of the above exception, another exception occurred:
Traceback (most recent call last):
  File "/home/hlwang/AVDC_change/flowdiffusion/datasets.py", line 406, in __getitem__
    samples, actions = self.get_samples(idx)
  File "/home/hlwang/AVDC_change/flowdiffusion/datasets.py", line 391, in get_samples
    seq = self.sequences[idx] # 取某一个目录下的所有图片
IndexError: list index out of range
During handling of the above exception, another exception occurred:
Traceback (most recent call last):
  File "/home/hlwang/AVDC_change/flowdiffusion/datasets.py", line 406, in __getitem__
    samples, actions = self.get_samples(idx)
  File "/home/hlwang/AVDC_change/flowdiffusion/datasets.py", line 391, in get_samples
    seq = self.sequences[idx] # 取某一个目录下的所有图片
IndexError: list index out of range
During handling of the above exception, another exception occurred:
Traceback (most recent call last):
  File "/home/hlwang/AVDC_change/flowdiffusion/datasets.py", line 406, in __getitem__
    samples, actions = self.get_samples(idx)
  File "/home/hlwang/AVDC_change/flowdiffusion/datasets.py", line 391, in get_samples
    seq = self.sequences[idx] # 取某一个目录下的所有图片
IndexError: list index out of range
During handling of the above exception, another exception occurred:
Traceback (most recent call last):
  File "/home/hlwang/AVDC_change/flowdiffusion/datasets.py", line 406, in __getitem__
    samples, actions = self.get_samples(idx)
  File "/home/hlwang/AVDC_change/flowdiffusion/datasets.py", line 391, in get_samples
    seq = self.sequences[idx] # 取某一个目录下的所有图片
IndexError: list index out of range
During handling of the above exception, another exception occurred:
Traceback (most recent call last):
  File "/home/hlwang/AVDC_change/flowdiffusion/datasets.py", line 406, in __getitem__
    samples, actions = self.get_samples(idx)
  File "/home/hlwang/AVDC_change/flowdiffusion/datasets.py", line 391, in get_samples
    seq = self.sequences[idx] # 取某一个目录下的所有图片
IndexError: list index out of range
During handling of the above exception, another exception occurred:
Traceback (most recent call last):
  File "/home/hlwang/AVDC_change/flowdiffusion/datasets.py", line 406, in __getitem__
    samples, actions = self.get_samples(idx)
  File "/home/hlwang/AVDC_change/flowdiffusion/datasets.py", line 391, in get_samples
    seq = self.sequences[idx] # 取某一个目录下的所有图片
IndexError: list index out of range
During handling of the above exception, another exception occurred:
Traceback (most recent call last):
  File "/home/hlwang/AVDC_change/flowdiffusion/datasets.py", line 406, in __getitem__
    samples, actions = self.get_samples(idx)
  File "/home/hlwang/AVDC_change/flowdiffusion/datasets.py", line 391, in get_samples
    seq = self.sequences[idx] # 取某一个目录下的所有图片
IndexError: list index out of range
During handling of the above exception, another exception occurred:
Traceback (most recent call last):
  File "/home/hlwang/AVDC_change/flowdiffusion/datasets.py", line 406, in __getitem__
    samples, actions = self.get_samples(idx)
  File "/home/hlwang/AVDC_change/flowdiffusion/datasets.py", line 391, in get_samples
    seq = self.sequences[idx] # 取某一个目录下的所有图片
IndexError: list index out of range
During handling of the above exception, another exception occurred:
Traceback (most recent call last):
  File "/home/hlwang/AVDC_change/flowdiffusion/datasets.py", line 406, in __getitem__
    samples, actions = self.get_samples(idx)
  File "/home/hlwang/AVDC_change/flowdiffusion/datasets.py", line 391, in get_samples
    seq = self.sequences[idx] # 取某一个目录下的所有图片
IndexError: list index out of range
During handling of the above exception, another exception occurred:
Traceback (most recent call last):
  File "/home/hlwang/AVDC_change/flowdiffusion/datasets.py", line 406, in __getitem__
    samples, actions = self.get_samples(idx)
  File "/home/hlwang/AVDC_change/flowdiffusion/datasets.py", line 391, in get_samples
    seq = self.sequences[idx] # 取某一个目录下的所有图片
IndexError: list index out of range
During handling of the above exception, another exception occurred:
Traceback (most recent call last):
  File "/home/hlwang/AVDC_change/flowdiffusion/datasets.py", line 406, in __getitem__
    samples, actions = self.get_samples(idx)
  File "/home/hlwang/AVDC_change/flowdiffusion/datasets.py", line 391, in get_samples
    seq = self.sequences[idx] # 取某一个目录下的所有图片
IndexError: list index out of range
During handling of the above exception, another exception occurred:
Traceback (most recent call last):
  File "/home/hlwang/AVDC_change/flowdiffusion/datasets.py", line 406, in __getitem__
    samples, actions = self.get_samples(idx)
  File "/home/hlwang/AVDC_change/flowdiffusion/datasets.py", line 391, in get_samples
    seq = self.sequences[idx] # 取某一个目录下的所有图片
IndexError: list index out of range
During handling of the above exception, another exception occurred:
Traceback (most recent call last):
  File "/home/hlwang/AVDC_change/flowdiffusion/datasets.py", line 406, in __getitem__
    samples, actions = self.get_samples(idx)
  File "/home/hlwang/AVDC_change/flowdiffusion/datasets.py", line 391, in get_samples
    seq = self.sequences[idx] # 取某一个目录下的所有图片
IndexError: list index out of range
During handling of the above exception, another exception occurred:
Traceback (most recent call last):
  File "/home/hlwang/AVDC_change/flowdiffusion/datasets.py", line 406, in __getitem__
    samples, actions = self.get_samples(idx)
  File "/home/hlwang/AVDC_change/flowdiffusion/datasets.py", line 391, in get_samples
    seq = self.sequences[idx] # 取某一个目录下的所有图片
IndexError: list index out of range
During handling of the above exception, another exception occurred:
Traceback (most recent call last):
  File "/home/hlwang/AVDC_change/flowdiffusion/datasets.py", line 406, in __getitem__
    samples, actions = self.get_samples(idx)
  File "/home/hlwang/AVDC_change/flowdiffusion/datasets.py", line 391, in get_samples
    seq = self.sequences[idx] # 取某一个目录下的所有图片
IndexError: list index out of range
During handling of the above exception, another exception occurred:
Traceback (most recent call last):
  File "/home/hlwang/AVDC_change/flowdiffusion/datasets.py", line 406, in __getitem__
    samples, actions = self.get_samples(idx)
  File "/home/hlwang/AVDC_change/flowdiffusion/datasets.py", line 391, in get_samples
    seq = self.sequences[idx] # 取某一个目录下的所有图片
IndexError: list index out of range
During handling of the above exception, another exception occurred:
Traceback (most recent call last):
  File "/home/hlwang/AVDC_change/flowdiffusion/datasets.py", line 406, in __getitem__
    samples, actions = self.get_samples(idx)
  File "/home/hlwang/AVDC_change/flowdiffusion/datasets.py", line 391, in get_samples
    seq = self.sequences[idx] # 取某一个目录下的所有图片
IndexError: list index out of range
During handling of the above exception, another exception occurred:
Traceback (most recent call last):
  File "/home/hlwang/AVDC_change/flowdiffusion/datasets.py", line 406, in __getitem__
    samples, actions = self.get_samples(idx)
  File "/home/hlwang/AVDC_change/flowdiffusion/datasets.py", line 391, in get_samples
    seq = self.sequences[idx] # 取某一个目录下的所有图片
IndexError: list index out of range
During handling of the above exception, another exception occurred:
Traceback (most recent call last):
  File "/home/hlwang/AVDC_change/flowdiffusion/datasets.py", line 406, in __getitem__
    samples, actions = self.get_samples(idx)
  File "/home/hlwang/AVDC_change/flowdiffusion/datasets.py", line 391, in get_samples
    seq = self.sequences[idx] # 取某一个目录下的所有图片
IndexError: list index out of range
During handling of the above exception, another exception occurred:
Traceback (most recent call last):
  File "/home/hlwang/AVDC_change/flowdiffusion/datasets.py", line 406, in __getitem__
    samples, actions = self.get_samples(idx)
  File "/home/hlwang/AVDC_change/flowdiffusion/datasets.py", line 391, in get_samples
    seq = self.sequences[idx] # 取某一个目录下的所有图片
IndexError: list index out of range
During handling of the above exception, another exception occurred:
Traceback (most recent call last):
  File "/home/hlwang/AVDC_change/flowdiffusion/datasets.py", line 406, in __getitem__
    samples, actions = self.get_samples(idx)
  File "/home/hlwang/AVDC_change/flowdiffusion/datasets.py", line 391, in get_samples
    seq = self.sequences[idx] # 取某一个目录下的所有图片
IndexError: list index out of range
During handling of the above exception, another exception occurred:
Traceback (most recent call last):
  File "/home/hlwang/AVDC_change/flowdiffusion/datasets.py", line 406, in __getitem__
    samples, actions = self.get_samples(idx)
  File "/home/hlwang/AVDC_change/flowdiffusion/datasets.py", line 391, in get_samples
    seq = self.sequences[idx] # 取某一个目录下的所有图片
IndexError: list index out of range
During handling of the above exception, another exception occurred:
Traceback (most recent call last):
  File "/home/hlwang/AVDC_change/flowdiffusion/datasets.py", line 406, in __getitem__
    samples, actions = self.get_samples(idx)
  File "/home/hlwang/AVDC_change/flowdiffusion/datasets.py", line 391, in get_samples
    seq = self.sequences[idx] # 取某一个目录下的所有图片
IndexError: list index out of range
During handling of the above exception, another exception occurred:
Traceback (most recent call last):
  File "/home/hlwang/AVDC_change/flowdiffusion/datasets.py", line 406, in __getitem__
    samples, actions = self.get_samples(idx)
  File "/home/hlwang/AVDC_change/flowdiffusion/datasets.py", line 391, in get_samples
    seq = self.sequences[idx] # 取某一个目录下的所有图片
IndexError: list index out of range
During handling of the above exception, another exception occurred:
Traceback (most recent call last):
  File "/home/hlwang/AVDC_change/flowdiffusion/datasets.py", line 406, in __getitem__
    samples, actions = self.get_samples(idx)
  File "/home/hlwang/AVDC_change/flowdiffusion/datasets.py", line 391, in get_samples
    seq = self.sequences[idx] # 取某一个目录下的所有图片
IndexError: list index out of range
During handling of the above exception, another exception occurred:
Traceback (most recent call last):
  File "/home/hlwang/AVDC_change/flowdiffusion/datasets.py", line 406, in __getitem__
    samples, actions = self.get_samples(idx)
  File "/home/hlwang/AVDC_change/flowdiffusion/datasets.py", line 391, in get_samples
    seq = self.sequences[idx] # 取某一个目录下的所有图片
IndexError: list index out of range
During handling of the above exception, another exception occurred:
Traceback (most recent call last):
  File "/home/hlwang/AVDC_change/flowdiffusion/datasets.py", line 406, in __getitem__
    samples, actions = self.get_samples(idx)
  File "/home/hlwang/AVDC_change/flowdiffusion/datasets.py", line 391, in get_samples
    seq = self.sequences[idx] # 取某一个目录下的所有图片
IndexError: list index out of range
During handling of the above exception, another exception occurred:
Traceback (most recent call last):
  File "/home/hlwang/AVDC_change/flowdiffusion/datasets.py", line 406, in __getitem__
    samples, actions = self.get_samples(idx)
  File "/home/hlwang/AVDC_change/flowdiffusion/datasets.py", line 391, in get_samples
    seq = self.sequences[idx] # 取某一个目录下的所有图片
IndexError: list index out of range
During handling of the above exception, another exception occurred:
Traceback (most recent call last):
  File "/home/hlwang/AVDC_change/flowdiffusion/datasets.py", line 406, in __getitem__
    samples, actions = self.get_samples(idx)
  File "/home/hlwang/AVDC_change/flowdiffusion/datasets.py", line 391, in get_samples
    seq = self.sequences[idx] # 取某一个目录下的所有图片
IndexError: list index out of range
During handling of the above exception, another exception occurred:
Traceback (most recent call last):
  File "/home/hlwang/AVDC_change/flowdiffusion/datasets.py", line 406, in __getitem__
    samples, actions = self.get_samples(idx)
  File "/home/hlwang/AVDC_change/flowdiffusion/datasets.py", line 391, in get_samples
    seq = self.sequences[idx] # 取某一个目录下的所有图片
IndexError: list index out of range
During handling of the above exception, another exception occurred:
Traceback (most recent call last):
  File "/home/hlwang/AVDC_change/flowdiffusion/datasets.py", line 406, in __getitem__
    samples, actions = self.get_samples(idx)
  File "/home/hlwang/AVDC_change/flowdiffusion/datasets.py", line 391, in get_samples
    seq = self.sequences[idx] # 取某一个目录下的所有图片
IndexError: list index out of range
During handling of the above exception, another exception occurred:
Traceback (most recent call last):
  File "/home/hlwang/AVDC_change/flowdiffusion/datasets.py", line 406, in __getitem__
    samples, actions = self.get_samples(idx)
  File "/home/hlwang/AVDC_change/flowdiffusion/datasets.py", line 391, in get_samples
    seq = self.sequences[idx] # 取某一个目录下的所有图片
IndexError: list index out of range
During handling of the above exception, another exception occurred:
Traceback (most recent call last):
  File "/home/hlwang/AVDC_change/flowdiffusion/datasets.py", line 406, in __getitem__
    samples, actions = self.get_samples(idx)
  File "/home/hlwang/AVDC_change/flowdiffusion/datasets.py", line 391, in get_samples
    seq = self.sequences[idx] # 取某一个目录下的所有图片
IndexError: list index out of range
During handling of the above exception, another exception occurred:
Traceback (most recent call last):
  File "/home/hlwang/AVDC_change/flowdiffusion/datasets.py", line 406, in __getitem__
    samples, actions = self.get_samples(idx)
  File "/home/hlwang/AVDC_change/flowdiffusion/datasets.py", line 391, in get_samples
    seq = self.sequences[idx] # 取某一个目录下的所有图片
IndexError: list index out of range
During handling of the above exception, another exception occurred:
Traceback (most recent call last):
  File "/home/hlwang/AVDC_change/flowdiffusion/datasets.py", line 406, in __getitem__
    samples, actions = self.get_samples(idx)
  File "/home/hlwang/AVDC_change/flowdiffusion/datasets.py", line 391, in get_samples
    seq = self.sequences[idx] # 取某一个目录下的所有图片
IndexError: list index out of range
During handling of the above exception, another exception occurred:
Traceback (most recent call last):
  File "/home/hlwang/AVDC_change/flowdiffusion/datasets.py", line 406, in __getitem__
    samples, actions = self.get_samples(idx)
  File "/home/hlwang/AVDC_change/flowdiffusion/datasets.py", line 391, in get_samples
    seq = self.sequences[idx] # 取某一个目录下的所有图片
IndexError: list index out of range
During handling of the above exception, another exception occurred:
Traceback (most recent call last):
  File "/home/hlwang/AVDC_change/flowdiffusion/datasets.py", line 406, in __getitem__
    samples, actions = self.get_samples(idx)
  File "/home/hlwang/AVDC_change/flowdiffusion/datasets.py", line 391, in get_samples
    seq = self.sequences[idx] # 取某一个目录下的所有图片
IndexError: list index out of range
During handling of the above exception, another exception occurred:
Traceback (most recent call last):
  File "/home/hlwang/AVDC_change/flowdiffusion/datasets.py", line 406, in __getitem__
    samples, actions = self.get_samples(idx)
  File "/home/hlwang/AVDC_change/flowdiffusion/datasets.py", line 391, in get_samples
    seq = self.sequences[idx] # 取某一个目录下的所有图片
IndexError: list index out of range
During handling of the above exception, another exception occurred:
Traceback (most recent call last):
  File "/home/hlwang/AVDC_change/flowdiffusion/datasets.py", line 406, in __getitem__
    samples, actions = self.get_samples(idx)
  File "/home/hlwang/AVDC_change/flowdiffusion/datasets.py", line 391, in get_samples
    seq = self.sequences[idx] # 取某一个目录下的所有图片
IndexError: list index out of range
During handling of the above exception, another exception occurred:
Traceback (most recent call last):
  File "/home/hlwang/AVDC_change/flowdiffusion/datasets.py", line 406, in __getitem__
    samples, actions = self.get_samples(idx)
  File "/home/hlwang/AVDC_change/flowdiffusion/datasets.py", line 391, in get_samples
    seq = self.sequences[idx] # 取某一个目录下的所有图片
IndexError: list index out of range
During handling of the above exception, another exception occurred:
Traceback (most recent call last):
  File "/home/hlwang/AVDC_change/flowdiffusion/datasets.py", line 406, in __getitem__
    samples, actions = self.get_samples(idx)
  File "/home/hlwang/AVDC_change/flowdiffusion/datasets.py", line 391, in get_samples
    seq = self.sequences[idx] # 取某一个目录下的所有图片
IndexError: list index out of range
During handling of the above exception, another exception occurred:
Traceback (most recent call last):
  File "/home/hlwang/AVDC_change/flowdiffusion/datasets.py", line 406, in __getitem__
    samples, actions = self.get_samples(idx)
  File "/home/hlwang/AVDC_change/flowdiffusion/datasets.py", line 391, in get_samples
    seq = self.sequences[idx] # 取某一个目录下的所有图片
IndexError: list index out of range
During handling of the above exception, another exception occurred:
Traceback (most recent call last):
  File "/home/hlwang/AVDC_change/flowdiffusion/datasets.py", line 406, in __getitem__
    samples, actions = self.get_samples(idx)
  File "/home/hlwang/AVDC_change/flowdiffusion/datasets.py", line 391, in get_samples
    seq = self.sequences[idx] # 取某一个目录下的所有图片
IndexError: list index out of range
During handling of the above exception, another exception occurred:
Traceback (most recent call last):
  File "/home/hlwang/AVDC_change/flowdiffusion/datasets.py", line 406, in __getitem__
    samples, actions = self.get_samples(idx)
  File "/home/hlwang/AVDC_change/flowdiffusion/datasets.py", line 391, in get_samples
    seq = self.sequences[idx] # 取某一个目录下的所有图片
IndexError: list index out of range
During handling of the above exception, another exception occurred:
Traceback (most recent call last):
  File "/home/hlwang/AVDC_change/flowdiffusion/datasets.py", line 406, in __getitem__
    samples, actions = self.get_samples(idx)
  File "/home/hlwang/AVDC_change/flowdiffusion/datasets.py", line 391, in get_samples
    seq = self.sequences[idx] # 取某一个目录下的所有图片
IndexError: list index out of range
During handling of the above exception, another exception occurred:
Traceback (most recent call last):
  File "/home/hlwang/AVDC_change/flowdiffusion/datasets.py", line 406, in __getitem__
    samples, actions = self.get_samples(idx)
  File "/home/hlwang/AVDC_change/flowdiffusion/datasets.py", line 391, in get_samples
    seq = self.sequences[idx] # 取某一个目录下的所有图片
IndexError: list index out of range
During handling of the above exception, another exception occurred:
Traceback (most recent call last):
  File "/home/hlwang/AVDC_change/flowdiffusion/datasets.py", line 406, in __getitem__
    samples, actions = self.get_samples(idx)
  File "/home/hlwang/AVDC_change/flowdiffusion/datasets.py", line 391, in get_samples
    seq = self.sequences[idx] # 取某一个目录下的所有图片
IndexError: list index out of range
During handling of the above exception, another exception occurred:
Traceback (most recent call last):
  File "/home/hlwang/AVDC_change/flowdiffusion/datasets.py", line 406, in __getitem__
    samples, actions = self.get_samples(idx)
  File "/home/hlwang/AVDC_change/flowdiffusion/datasets.py", line 391, in get_samples
    seq = self.sequences[idx] # 取某一个目录下的所有图片
IndexError: list index out of range
During handling of the above exception, another exception occurred:
Traceback (most recent call last):
  File "/home/hlwang/AVDC_change/flowdiffusion/datasets.py", line 406, in __getitem__
    samples, actions = self.get_samples(idx)
  File "/home/hlwang/AVDC_change/flowdiffusion/datasets.py", line 391, in get_samples
    seq = self.sequences[idx] # 取某一个目录下的所有图片
IndexError: list index out of range
During handling of the above exception, another exception occurred:
Traceback (most recent call last):
  File "/home/hlwang/AVDC_change/flowdiffusion/datasets.py", line 406, in __getitem__
    samples, actions = self.get_samples(idx)
  File "/home/hlwang/AVDC_change/flowdiffusion/datasets.py", line 391, in get_samples
    seq = self.sequences[idx] # 取某一个目录下的所有图片
IndexError: list index out of range
During handling of the above exception, another exception occurred:
Traceback (most recent call last):
  File "/home/hlwang/AVDC_change/flowdiffusion/datasets.py", line 406, in __getitem__
    samples, actions = self.get_samples(idx)
  File "/home/hlwang/AVDC_change/flowdiffusion/datasets.py", line 391, in get_samples
    seq = self.sequences[idx] # 取某一个目录下的所有图片
IndexError: list index out of range
During handling of the above exception, another exception occurred:
Traceback (most recent call last):
  File "/home/hlwang/AVDC_change/flowdiffusion/datasets.py", line 406, in __getitem__
    samples, actions = self.get_samples(idx)
  File "/home/hlwang/AVDC_change/flowdiffusion/datasets.py", line 391, in get_samples
    seq = self.sequences[idx] # 取某一个目录下的所有图片
IndexError: list index out of range
During handling of the above exception, another exception occurred:
Traceback (most recent call last):
  File "/home/hlwang/AVDC_change/flowdiffusion/datasets.py", line 406, in __getitem__
    samples, actions = self.get_samples(idx)
  File "/home/hlwang/AVDC_change/flowdiffusion/datasets.py", line 391, in get_samples
    seq = self.sequences[idx] # 取某一个目录下的所有图片
IndexError: list index out of range
During handling of the above exception, another exception occurred:
Traceback (most recent call last):
  File "/home/hlwang/AVDC_change/flowdiffusion/datasets.py", line 406, in __getitem__
    samples, actions = self.get_samples(idx)
  File "/home/hlwang/AVDC_change/flowdiffusion/datasets.py", line 391, in get_samples
    seq = self.sequences[idx] # 取某一个目录下的所有图片
IndexError: list index out of range
During handling of the above exception, another exception occurred:
Traceback (most recent call last):
  File "/home/hlwang/AVDC_change/flowdiffusion/datasets.py", line 406, in __getitem__
    samples, actions = self.get_samples(idx)
  File "/home/hlwang/AVDC_change/flowdiffusion/datasets.py", line 391, in get_samples
    seq = self.sequences[idx] # 取某一个目录下的所有图片
IndexError: list index out of range
During handling of the above exception, another exception occurred:
Traceback (most recent call last):
  File "/home/hlwang/AVDC_change/flowdiffusion/datasets.py", line 406, in __getitem__
    samples, actions = self.get_samples(idx)
  File "/home/hlwang/AVDC_change/flowdiffusion/datasets.py", line 391, in get_samples
    seq = self.sequences[idx] # 取某一个目录下的所有图片
IndexError: list index out of range
During handling of the above exception, another exception occurred:
Traceback (most recent call last):
  File "/home/hlwang/AVDC_change/flowdiffusion/datasets.py", line 406, in __getitem__
    samples, actions = self.get_samples(idx)
  File "/home/hlwang/AVDC_change/flowdiffusion/datasets.py", line 391, in get_samples
    seq = self.sequences[idx] # 取某一个目录下的所有图片
IndexError: list index out of range
During handling of the above exception, another exception occurred:
Traceback (most recent call last):
  File "/home/hlwang/AVDC_change/flowdiffusion/datasets.py", line 406, in __getitem__
    samples, actions = self.get_samples(idx)
  File "/home/hlwang/AVDC_change/flowdiffusion/datasets.py", line 391, in get_samples
    seq = self.sequences[idx] # 取某一个目录下的所有图片
IndexError: list index out of range
During handling of the above exception, another exception occurred:
Traceback (most recent call last):
  File "/home/hlwang/AVDC_change/flowdiffusion/datasets.py", line 406, in __getitem__
    samples, actions = self.get_samples(idx)
  File "/home/hlwang/AVDC_change/flowdiffusion/datasets.py", line 391, in get_samples
    seq = self.sequences[idx] # 取某一个目录下的所有图片
IndexError: list index out of range
During handling of the above exception, another exception occurred:
Traceback (most recent call last):
  File "/home/hlwang/AVDC_change/flowdiffusion/datasets.py", line 406, in __getitem__
    samples, actions = self.get_samples(idx)
  File "/home/hlwang/AVDC_change/flowdiffusion/datasets.py", line 391, in get_samples
    seq = self.sequences[idx] # 取某一个目录下的所有图片
IndexError: list index out of range
During handling of the above exception, another exception occurred:
Traceback (most recent call last):
  File "/home/hlwang/AVDC_change/flowdiffusion/datasets.py", line 406, in __getitem__
    samples, actions = self.get_samples(idx)
  File "/home/hlwang/AVDC_change/flowdiffusion/datasets.py", line 391, in get_samples
    seq = self.sequences[idx] # 取某一个目录下的所有图片
IndexError: list index out of range
During handling of the above exception, another exception occurred:
Traceback (most recent call last):
  File "/home/hlwang/AVDC_change/flowdiffusion/datasets.py", line 406, in __getitem__
    samples, actions = self.get_samples(idx)
  File "/home/hlwang/AVDC_change/flowdiffusion/datasets.py", line 391, in get_samples
    seq = self.sequences[idx] # 取某一个目录下的所有图片
IndexError: list index out of range
During handling of the above exception, another exception occurred:
Traceback (most recent call last):
  File "/home/hlwang/AVDC_change/flowdiffusion/datasets.py", line 406, in __getitem__
    samples, actions = self.get_samples(idx)
  File "/home/hlwang/AVDC_change/flowdiffusion/datasets.py", line 391, in get_samples
    seq = self.sequences[idx] # 取某一个目录下的所有图片
IndexError: list index out of range
During handling of the above exception, another exception occurred:
Traceback (most recent call last):
  File "/home/hlwang/AVDC_change/flowdiffusion/datasets.py", line 406, in __getitem__
    samples, actions = self.get_samples(idx)
  File "/home/hlwang/AVDC_change/flowdiffusion/datasets.py", line 391, in get_samples
    seq = self.sequences[idx] # 取某一个目录下的所有图片
IndexError: list index out of range
During handling of the above exception, another exception occurred:
Traceback (most recent call last):
  File "/home/hlwang/AVDC_change/flowdiffusion/datasets.py", line 406, in __getitem__
    samples, actions = self.get_samples(idx)
  File "/home/hlwang/AVDC_change/flowdiffusion/datasets.py", line 391, in get_samples
    seq = self.sequences[idx] # 取某一个目录下的所有图片
IndexError: list index out of range
During handling of the above exception, another exception occurred:
Traceback (most recent call last):
  File "/home/hlwang/AVDC_change/flowdiffusion/datasets.py", line 406, in __getitem__
    samples, actions = self.get_samples(idx)
  File "/home/hlwang/AVDC_change/flowdiffusion/datasets.py", line 391, in get_samples
    seq = self.sequences[idx] # 取某一个目录下的所有图片
IndexError: list index out of range
During handling of the above exception, another exception occurred:
Traceback (most recent call last):
  File "/home/hlwang/AVDC_change/flowdiffusion/datasets.py", line 406, in __getitem__
    samples, actions = self.get_samples(idx)
  File "/home/hlwang/AVDC_change/flowdiffusion/datasets.py", line 391, in get_samples
    seq = self.sequences[idx] # 取某一个目录下的所有图片
IndexError: list index out of range
During handling of the above exception, another exception occurred:
Traceback (most recent call last):
  File "/home/hlwang/AVDC_change/flowdiffusion/datasets.py", line 406, in __getitem__
    samples, actions = self.get_samples(idx)
  File "/home/hlwang/AVDC_change/flowdiffusion/datasets.py", line 391, in get_samples
    seq = self.sequences[idx] # 取某一个目录下的所有图片
IndexError: list index out of range
During handling of the above exception, another exception occurred:
Traceback (most recent call last):
  File "/home/hlwang/AVDC_change/flowdiffusion/datasets.py", line 406, in __getitem__
    samples, actions = self.get_samples(idx)
  File "/home/hlwang/AVDC_change/flowdiffusion/datasets.py", line 391, in get_samples
    seq = self.sequences[idx] # 取某一个目录下的所有图片
IndexError: list index out of range
During handling of the above exception, another exception occurred:
Traceback (most recent call last):
  File "/home/hlwang/AVDC_change/flowdiffusion/datasets.py", line 406, in __getitem__
    samples, actions = self.get_samples(idx)
  File "/home/hlwang/AVDC_change/flowdiffusion/datasets.py", line 391, in get_samples
    seq = self.sequences[idx] # 取某一个目录下的所有图片
IndexError: list index out of range
During handling of the above exception, another exception occurred:
Traceback (most recent call last):
  File "/home/hlwang/AVDC_change/flowdiffusion/datasets.py", line 406, in __getitem__
    samples, actions = self.get_samples(idx)
  File "/home/hlwang/AVDC_change/flowdiffusion/datasets.py", line 391, in get_samples
    seq = self.sequences[idx] # 取某一个目录下的所有图片
IndexError: list index out of range
During handling of the above exception, another exception occurred:
Traceback (most recent call last):
  File "/home/hlwang/AVDC_change/flowdiffusion/datasets.py", line 406, in __getitem__
    samples, actions = self.get_samples(idx)
  File "/home/hlwang/AVDC_change/flowdiffusion/datasets.py", line 391, in get_samples
    seq = self.sequences[idx] # 取某一个目录下的所有图片
IndexError: list index out of range
During handling of the above exception, another exception occurred:
Traceback (most recent call last):
  File "/home/hlwang/AVDC_change/flowdiffusion/datasets.py", line 406, in __getitem__
    samples, actions = self.get_samples(idx)
  File "/home/hlwang/AVDC_change/flowdiffusion/datasets.py", line 391, in get_samples
    seq = self.sequences[idx] # 取某一个目录下的所有图片
IndexError: list index out of range
During handling of the above exception, another exception occurred:
Traceback (most recent call last):
  File "/home/hlwang/AVDC_change/flowdiffusion/datasets.py", line 406, in __getitem__
    samples, actions = self.get_samples(idx)
  File "/home/hlwang/AVDC_change/flowdiffusion/datasets.py", line 391, in get_samples
    seq = self.sequences[idx] # 取某一个目录下的所有图片
IndexError: list index out of range
During handling of the above exception, another exception occurred:
Traceback (most recent call last):
  File "/home/hlwang/AVDC_change/flowdiffusion/datasets.py", line 406, in __getitem__
    samples, actions = self.get_samples(idx)
  File "/home/hlwang/AVDC_change/flowdiffusion/datasets.py", line 391, in get_samples
    seq = self.sequences[idx] # 取某一个目录下的所有图片
IndexError: list index out of range
During handling of the above exception, another exception occurred:
Traceback (most recent call last):
  File "/home/hlwang/AVDC_change/flowdiffusion/datasets.py", line 406, in __getitem__
    samples, actions = self.get_samples(idx)
  File "/home/hlwang/AVDC_change/flowdiffusion/datasets.py", line 391, in get_samples
    seq = self.sequences[idx] # 取某一个目录下的所有图片
IndexError: list index out of range
During handling of the above exception, another exception occurred:
Traceback (most recent call last):
  File "/home/hlwang/AVDC_change/flowdiffusion/datasets.py", line 406, in __getitem__
    samples, actions = self.get_samples(idx)
  File "/home/hlwang/AVDC_change/flowdiffusion/datasets.py", line 391, in get_samples
    seq = self.sequences[idx] # 取某一个目录下的所有图片
IndexError: list index out of range
During handling of the above exception, another exception occurred:
Traceback (most recent call last):
  File "/home/hlwang/AVDC_change/flowdiffusion/datasets.py", line 406, in __getitem__
    samples, actions = self.get_samples(idx)
  File "/home/hlwang/AVDC_change/flowdiffusion/datasets.py", line 391, in get_samples
    seq = self.sequences[idx] # 取某一个目录下的所有图片
IndexError: list index out of range
During handling of the above exception, another exception occurred:
Traceback (most recent call last):
  File "/home/hlwang/AVDC_change/flowdiffusion/datasets.py", line 406, in __getitem__
    samples, actions = self.get_samples(idx)
  File "/home/hlwang/AVDC_change/flowdiffusion/datasets.py", line 391, in get_samples
    seq = self.sequences[idx] # 取某一个目录下的所有图片
IndexError: list index out of range
During handling of the above exception, another exception occurred:
Traceback (most recent call last):
  File "/home/hlwang/AVDC_change/flowdiffusion/datasets.py", line 406, in __getitem__
    samples, actions = self.get_samples(idx)
  File "/home/hlwang/AVDC_change/flowdiffusion/datasets.py", line 391, in get_samples
    seq = self.sequences[idx] # 取某一个目录下的所有图片
IndexError: list index out of range
During handling of the above exception, another exception occurred:
Traceback (most recent call last):
  File "/home/hlwang/AVDC_change/flowdiffusion/datasets.py", line 406, in __getitem__
    samples, actions = self.get_samples(idx)
  File "/home/hlwang/AVDC_change/flowdiffusion/datasets.py", line 391, in get_samples
    seq = self.sequences[idx] # 取某一个目录下的所有图片
IndexError: list index out of range
During handling of the above exception, another exception occurred:
Traceback (most recent call last):
  File "/home/hlwang/AVDC_change/flowdiffusion/datasets.py", line 406, in __getitem__
    samples, actions = self.get_samples(idx)
  File "/home/hlwang/AVDC_change/flowdiffusion/datasets.py", line 391, in get_samples
    seq = self.sequences[idx] # 取某一个目录下的所有图片
IndexError: list index out of range
During handling of the above exception, another exception occurred:
Traceback (most recent call last):
  File "/home/hlwang/AVDC_change/flowdiffusion/datasets.py", line 406, in __getitem__
    samples, actions = self.get_samples(idx)
  File "/home/hlwang/AVDC_change/flowdiffusion/datasets.py", line 391, in get_samples
    seq = self.sequences[idx] # 取某一个目录下的所有图片
IndexError: list index out of range
During handling of the above exception, another exception occurred:
Traceback (most recent call last):
  File "/home/hlwang/AVDC_change/flowdiffusion/datasets.py", line 406, in __getitem__
    samples, actions = self.get_samples(idx)
  File "/home/hlwang/AVDC_change/flowdiffusion/datasets.py", line 391, in get_samples
    seq = self.sequences[idx] # 取某一个目录下的所有图片
IndexError: list index out of range
During handling of the above exception, another exception occurred:
Traceback (most recent call last):
  File "/home/hlwang/AVDC_change/flowdiffusion/datasets.py", line 406, in __getitem__
    samples, actions = self.get_samples(idx)
  File "/home/hlwang/AVDC_change/flowdiffusion/datasets.py", line 391, in get_samples
    seq = self.sequences[idx] # 取某一个目录下的所有图片
IndexError: list index out of range
During handling of the above exception, another exception occurred:
Traceback (most recent call last):
  File "/home/hlwang/AVDC_change/flowdiffusion/datasets.py", line 406, in __getitem__
    samples, actions = self.get_samples(idx)
  File "/home/hlwang/AVDC_change/flowdiffusion/datasets.py", line 391, in get_samples
    seq = self.sequences[idx] # 取某一个目录下的所有图片
IndexError: list index out of range
During handling of the above exception, another exception occurred:
Traceback (most recent call last):
  File "/home/hlwang/AVDC_change/flowdiffusion/datasets.py", line 406, in __getitem__
    samples, actions = self.get_samples(idx)
  File "/home/hlwang/AVDC_change/flowdiffusion/datasets.py", line 391, in get_samples
    seq = self.sequences[idx] # 取某一个目录下的所有图片
IndexError: list index out of range
During handling of the above exception, another exception occurred:
Traceback (most recent call last):
  File "/home/hlwang/AVDC_change/flowdiffusion/datasets.py", line 406, in __getitem__
    samples, actions = self.get_samples(idx)
  File "/home/hlwang/AVDC_change/flowdiffusion/datasets.py", line 391, in get_samples
    seq = self.sequences[idx] # 取某一个目录下的所有图片
IndexError: list index out of range
During handling of the above exception, another exception occurred:
Traceback (most recent call last):
  File "/home/hlwang/AVDC_change/flowdiffusion/datasets.py", line 406, in __getitem__
    samples, actions = self.get_samples(idx)
  File "/home/hlwang/AVDC_change/flowdiffusion/datasets.py", line 391, in get_samples
    seq = self.sequences[idx] # 取某一个目录下的所有图片
IndexError: list index out of range
During handling of the above exception, another exception occurred:
Traceback (most recent call last):
  File "/home/hlwang/AVDC_change/flowdiffusion/datasets.py", line 406, in __getitem__
    samples, actions = self.get_samples(idx)
  File "/home/hlwang/AVDC_change/flowdiffusion/datasets.py", line 391, in get_samples
    seq = self.sequences[idx] # 取某一个目录下的所有图片
IndexError: list index out of range
During handling of the above exception, another exception occurred:
Traceback (most recent call last):
  File "/home/hlwang/AVDC_change/flowdiffusion/datasets.py", line 406, in __getitem__
    samples, actions = self.get_samples(idx)
  File "/home/hlwang/AVDC_change/flowdiffusion/datasets.py", line 391, in get_samples
    seq = self.sequences[idx] # 取某一个目录下的所有图片
IndexError: list index out of range
During handling of the above exception, another exception occurred:
Traceback (most recent call last):
  File "/home/hlwang/AVDC_change/flowdiffusion/datasets.py", line 406, in __getitem__
    samples, actions = self.get_samples(idx)
  File "/home/hlwang/AVDC_change/flowdiffusion/datasets.py", line 391, in get_samples
    seq = self.sequences[idx] # 取某一个目录下的所有图片
IndexError: list index out of range
During handling of the above exception, another exception occurred:
Traceback (most recent call last):
  File "/home/hlwang/AVDC_change/flowdiffusion/datasets.py", line 406, in __getitem__
    samples, actions = self.get_samples(idx)
  File "/home/hlwang/AVDC_change/flowdiffusion/datasets.py", line 391, in get_samples
    seq = self.sequences[idx] # 取某一个目录下的所有图片
IndexError: list index out of range
During handling of the above exception, another exception occurred:
Traceback (most recent call last):
  File "/home/hlwang/AVDC_change/flowdiffusion/datasets.py", line 406, in __getitem__
    samples, actions = self.get_samples(idx)
  File "/home/hlwang/AVDC_change/flowdiffusion/datasets.py", line 391, in get_samples
    seq = self.sequences[idx] # 取某一个目录下的所有图片
IndexError: list index out of range
During handling of the above exception, another exception occurred:
Traceback (most recent call last):
  File "/home/hlwang/AVDC_change/flowdiffusion/datasets.py", line 406, in __getitem__
    samples, actions = self.get_samples(idx)
  File "/home/hlwang/AVDC_change/flowdiffusion/datasets.py", line 391, in get_samples
    seq = self.sequences[idx] # 取某一个目录下的所有图片
IndexError: list index out of range
During handling of the above exception, another exception occurred:
Traceback (most recent call last):
  File "/home/hlwang/AVDC_change/flowdiffusion/datasets.py", line 406, in __getitem__
    samples, actions = self.get_samples(idx)
  File "/home/hlwang/AVDC_change/flowdiffusion/datasets.py", line 391, in get_samples
    seq = self.sequences[idx] # 取某一个目录下的所有图片
IndexError: list index out of range
During handling of the above exception, another exception occurred:
Traceback (most recent call last):
  File "/home/hlwang/AVDC_change/flowdiffusion/datasets.py", line 406, in __getitem__
    samples, actions = self.get_samples(idx)
  File "/home/hlwang/AVDC_change/flowdiffusion/datasets.py", line 391, in get_samples
    seq = self.sequences[idx] # 取某一个目录下的所有图片
IndexError: list index out of range
During handling of the above exception, another exception occurred:
Traceback (most recent call last):
  File "/home/hlwang/AVDC_change/flowdiffusion/datasets.py", line 406, in __getitem__
    samples, actions = self.get_samples(idx)
  File "/home/hlwang/AVDC_change/flowdiffusion/datasets.py", line 391, in get_samples
    seq = self.sequences[idx] # 取某一个目录下的所有图片
IndexError: list index out of range
During handling of the above exception, another exception occurred:
Traceback (most recent call last):
  File "/home/hlwang/AVDC_change/flowdiffusion/datasets.py", line 406, in __getitem__
    samples, actions = self.get_samples(idx)
  File "/home/hlwang/AVDC_change/flowdiffusion/datasets.py", line 391, in get_samples
    seq = self.sequences[idx] # 取某一个目录下的所有图片
IndexError: list index out of range
During handling of the above exception, another exception occurred:
Traceback (most recent call last):
  File "/home/hlwang/AVDC_change/flowdiffusion/datasets.py", line 406, in __getitem__
    samples, actions = self.get_samples(idx)
  File "/home/hlwang/AVDC_change/flowdiffusion/datasets.py", line 391, in get_samples
    seq = self.sequences[idx] # 取某一个目录下的所有图片
IndexError: list index out of range
During handling of the above exception, another exception occurred:
Traceback (most recent call last):
  File "/home/hlwang/AVDC_change/flowdiffusion/datasets.py", line 406, in __getitem__
    samples, actions = self.get_samples(idx)
  File "/home/hlwang/AVDC_change/flowdiffusion/datasets.py", line 391, in get_samples
    seq = self.sequences[idx] # 取某一个目录下的所有图片
IndexError: list index out of range
During handling of the above exception, another exception occurred:
Traceback (most recent call last):
  File "/home/hlwang/AVDC_change/flowdiffusion/datasets.py", line 406, in __getitem__
    samples, actions = self.get_samples(idx)
  File "/home/hlwang/AVDC_change/flowdiffusion/datasets.py", line 391, in get_samples
    seq = self.sequences[idx] # 取某一个目录下的所有图片
IndexError: list index out of range
During handling of the above exception, another exception occurred:
Traceback (most recent call last):
  File "/home/hlwang/AVDC_change/flowdiffusion/datasets.py", line 406, in __getitem__
    samples, actions = self.get_samples(idx)
  File "/home/hlwang/AVDC_change/flowdiffusion/datasets.py", line 391, in get_samples
    seq = self.sequences[idx] # 取某一个目录下的所有图片
IndexError: list index out of range
During handling of the above exception, another exception occurred:
Traceback (most recent call last):
  File "/home/hlwang/AVDC_change/flowdiffusion/datasets.py", line 406, in __getitem__
    samples, actions = self.get_samples(idx)
  File "/home/hlwang/AVDC_change/flowdiffusion/datasets.py", line 391, in get_samples
    seq = self.sequences[idx] # 取某一个目录下的所有图片
IndexError: list index out of range
During handling of the above exception, another exception occurred:
Traceback (most recent call last):
  File "/home/hlwang/AVDC_change/flowdiffusion/datasets.py", line 406, in __getitem__
    samples, actions = self.get_samples(idx)
  File "/home/hlwang/AVDC_change/flowdiffusion/datasets.py", line 391, in get_samples
    seq = self.sequences[idx] # 取某一个目录下的所有图片
IndexError: list index out of range
During handling of the above exception, another exception occurred:
Traceback (most recent call last):
  File "/home/hlwang/AVDC_change/flowdiffusion/datasets.py", line 406, in __getitem__
    samples, actions = self.get_samples(idx)
  File "/home/hlwang/AVDC_change/flowdiffusion/datasets.py", line 391, in get_samples
    seq = self.sequences[idx] # 取某一个目录下的所有图片
IndexError: list index out of range
During handling of the above exception, another exception occurred:
Traceback (most recent call last):
  File "/home/hlwang/AVDC_change/flowdiffusion/datasets.py", line 406, in __getitem__
    samples, actions = self.get_samples(idx)
  File "/home/hlwang/AVDC_change/flowdiffusion/datasets.py", line 391, in get_samples
    seq = self.sequences[idx] # 取某一个目录下的所有图片
IndexError: list index out of range
During handling of the above exception, another exception occurred:
Traceback (most recent call last):
  File "/home/hlwang/AVDC_change/flowdiffusion/datasets.py", line 406, in __getitem__
    samples, actions = self.get_samples(idx)
  File "/home/hlwang/AVDC_change/flowdiffusion/datasets.py", line 391, in get_samples
    seq = self.sequences[idx] # 取某一个目录下的所有图片
IndexError: list index out of range
During handling of the above exception, another exception occurred:
Traceback (most recent call last):
  File "/home/hlwang/AVDC_change/flowdiffusion/datasets.py", line 406, in __getitem__
    samples, actions = self.get_samples(idx)
  File "/home/hlwang/AVDC_change/flowdiffusion/datasets.py", line 391, in get_samples
    seq = self.sequences[idx] # 取某一个目录下的所有图片
IndexError: list index out of range
During handling of the above exception, another exception occurred:
Traceback (most recent call last):
  File "/home/hlwang/AVDC_change/flowdiffusion/datasets.py", line 406, in __getitem__
    samples, actions = self.get_samples(idx)
  File "/home/hlwang/AVDC_change/flowdiffusion/datasets.py", line 391, in get_samples
    seq = self.sequences[idx] # 取某一个目录下的所有图片
IndexError: list index out of range
During handling of the above exception, another exception occurred:
Traceback (most recent call last):
  File "/home/hlwang/AVDC_change/flowdiffusion/datasets.py", line 406, in __getitem__
    samples, actions = self.get_samples(idx)
  File "/home/hlwang/AVDC_change/flowdiffusion/datasets.py", line 391, in get_samples
    seq = self.sequences[idx] # 取某一个目录下的所有图片
IndexError: list index out of range
During handling of the above exception, another exception occurred:
Traceback (most recent call last):
  File "/home/hlwang/AVDC_change/flowdiffusion/datasets.py", line 406, in __getitem__
    samples, actions = self.get_samples(idx)
  File "/home/hlwang/AVDC_change/flowdiffusion/datasets.py", line 391, in get_samples
    seq = self.sequences[idx] # 取某一个目录下的所有图片
IndexError: list index out of range
During handling of the above exception, another exception occurred:
Traceback (most recent call last):
  File "/home/hlwang/AVDC_change/flowdiffusion/datasets.py", line 406, in __getitem__
    samples, actions = self.get_samples(idx)
  File "/home/hlwang/AVDC_change/flowdiffusion/datasets.py", line 391, in get_samples
    seq = self.sequences[idx] # 取某一个目录下的所有图片
IndexError: list index out of range
During handling of the above exception, another exception occurred:
Traceback (most recent call last):
  File "/home/hlwang/AVDC_change/flowdiffusion/datasets.py", line 406, in __getitem__
    samples, actions = self.get_samples(idx)
  File "/home/hlwang/AVDC_change/flowdiffusion/datasets.py", line 391, in get_samples
    seq = self.sequences[idx] # 取某一个目录下的所有图片
IndexError: list index out of range
During handling of the above exception, another exception occurred:
Traceback (most recent call last):
  File "/home/hlwang/AVDC_change/flowdiffusion/datasets.py", line 406, in __getitem__
    samples, actions = self.get_samples(idx)
  File "/home/hlwang/AVDC_change/flowdiffusion/datasets.py", line 391, in get_samples
    seq = self.sequences[idx] # 取某一个目录下的所有图片
IndexError: list index out of range
During handling of the above exception, another exception occurred:
Traceback (most recent call last):
  File "/home/hlwang/AVDC_change/flowdiffusion/datasets.py", line 406, in __getitem__
    samples, actions = self.get_samples(idx)
  File "/home/hlwang/AVDC_change/flowdiffusion/datasets.py", line 391, in get_samples
    seq = self.sequences[idx] # 取某一个目录下的所有图片
IndexError: list index out of range
During handling of the above exception, another exception occurred:
Traceback (most recent call last):
  File "/home/hlwang/AVDC_change/flowdiffusion/datasets.py", line 406, in __getitem__
    samples, actions = self.get_samples(idx)
  File "/home/hlwang/AVDC_change/flowdiffusion/datasets.py", line 391, in get_samples
    seq = self.sequences[idx] # 取某一个目录下的所有图片
IndexError: list index out of range
During handling of the above exception, another exception occurred:
Traceback (most recent call last):
  File "/home/hlwang/AVDC_change/flowdiffusion/datasets.py", line 406, in __getitem__
    samples, actions = self.get_samples(idx)
  File "/home/hlwang/AVDC_change/flowdiffusion/datasets.py", line 391, in get_samples
    seq = self.sequences[idx] # 取某一个目录下的所有图片
IndexError: list index out of range
During handling of the above exception, another exception occurred:
Traceback (most recent call last):
  File "/home/hlwang/AVDC_change/flowdiffusion/datasets.py", line 406, in __getitem__
    samples, actions = self.get_samples(idx)
  File "/home/hlwang/AVDC_change/flowdiffusion/datasets.py", line 391, in get_samples
    seq = self.sequences[idx] # 取某一个目录下的所有图片
IndexError: list index out of range
During handling of the above exception, another exception occurred:
Traceback (most recent call last):
  File "/home/hlwang/AVDC_change/flowdiffusion/datasets.py", line 406, in __getitem__
    samples, actions = self.get_samples(idx)
  File "/home/hlwang/AVDC_change/flowdiffusion/datasets.py", line 391, in get_samples
    seq = self.sequences[idx] # 取某一个目录下的所有图片
IndexError: list index out of range
During handling of the above exception, another exception occurred:
Traceback (most recent call last):
  File "/home/hlwang/AVDC_change/flowdiffusion/datasets.py", line 406, in __getitem__
    samples, actions = self.get_samples(idx)
  File "/home/hlwang/AVDC_change/flowdiffusion/datasets.py", line 391, in get_samples
    seq = self.sequences[idx] # 取某一个目录下的所有图片
IndexError: list index out of range
During handling of the above exception, another exception occurred:
Traceback (most recent call last):
  File "/home/hlwang/AVDC_change/flowdiffusion/datasets.py", line 406, in __getitem__
    samples, actions = self.get_samples(idx)
  File "/home/hlwang/AVDC_change/flowdiffusion/datasets.py", line 391, in get_samples
    seq = self.sequences[idx] # 取某一个目录下的所有图片
IndexError: list index out of range
During handling of the above exception, another exception occurred:
Traceback (most recent call last):
  File "/home/hlwang/AVDC_change/flowdiffusion/datasets.py", line 406, in __getitem__
    samples, actions = self.get_samples(idx)
  File "/home/hlwang/AVDC_change/flowdiffusion/datasets.py", line 391, in get_samples
    seq = self.sequences[idx] # 取某一个目录下的所有图片
IndexError: list index out of range
During handling of the above exception, another exception occurred:
Traceback (most recent call last):
  File "/home/hlwang/AVDC_change/flowdiffusion/datasets.py", line 406, in __getitem__
    samples, actions = self.get_samples(idx)
  File "/home/hlwang/AVDC_change/flowdiffusion/datasets.py", line 391, in get_samples
    seq = self.sequences[idx] # 取某一个目录下的所有图片
IndexError: list index out of range
During handling of the above exception, another exception occurred:
Traceback (most recent call last):
  File "/home/hlwang/AVDC_change/flowdiffusion/datasets.py", line 406, in __getitem__
    samples, actions = self.get_samples(idx)
  File "/home/hlwang/AVDC_change/flowdiffusion/datasets.py", line 391, in get_samples
    seq = self.sequences[idx] # 取某一个目录下的所有图片
IndexError: list index out of range
During handling of the above exception, another exception occurred:
Traceback (most recent call last):
  File "/home/hlwang/AVDC_change/flowdiffusion/datasets.py", line 406, in __getitem__
    samples, actions = self.get_samples(idx)
  File "/home/hlwang/AVDC_change/flowdiffusion/datasets.py", line 391, in get_samples
    seq = self.sequences[idx] # 取某一个目录下的所有图片
IndexError: list index out of range
During handling of the above exception, another exception occurred:
Traceback (most recent call last):
  File "/home/hlwang/AVDC_change/flowdiffusion/datasets.py", line 406, in __getitem__
    samples, actions = self.get_samples(idx)
  File "/home/hlwang/AVDC_change/flowdiffusion/datasets.py", line 391, in get_samples
    seq = self.sequences[idx] # 取某一个目录下的所有图片
IndexError: list index out of range
During handling of the above exception, another exception occurred:
Traceback (most recent call last):
  File "/home/hlwang/AVDC_change/flowdiffusion/datasets.py", line 406, in __getitem__
    samples, actions = self.get_samples(idx)
  File "/home/hlwang/AVDC_change/flowdiffusion/datasets.py", line 391, in get_samples
    seq = self.sequences[idx] # 取某一个目录下的所有图片
IndexError: list index out of range
During handling of the above exception, another exception occurred:
Traceback (most recent call last):
  File "/home/hlwang/AVDC_change/flowdiffusion/datasets.py", line 406, in __getitem__
    samples, actions = self.get_samples(idx)
  File "/home/hlwang/AVDC_change/flowdiffusion/datasets.py", line 391, in get_samples
    seq = self.sequences[idx] # 取某一个目录下的所有图片
IndexError: list index out of range
During handling of the above exception, another exception occurred:
Traceback (most recent call last):
  File "/home/hlwang/AVDC_change/flowdiffusion/datasets.py", line 406, in __getitem__
    samples, actions = self.get_samples(idx)
  File "/home/hlwang/AVDC_change/flowdiffusion/datasets.py", line 391, in get_samples
    seq = self.sequences[idx] # 取某一个目录下的所有图片
IndexError: list index out of range
During handling of the above exception, another exception occurred:
Traceback (most recent call last):
  File "/home/hlwang/AVDC_change/flowdiffusion/datasets.py", line 406, in __getitem__
    samples, actions = self.get_samples(idx)
  File "/home/hlwang/AVDC_change/flowdiffusion/datasets.py", line 391, in get_samples
    seq = self.sequences[idx] # 取某一个目录下的所有图片
IndexError: list index out of range
During handling of the above exception, another exception occurred:
Traceback (most recent call last):
  File "/home/hlwang/AVDC_change/flowdiffusion/datasets.py", line 406, in __getitem__
    samples, actions = self.get_samples(idx)
  File "/home/hlwang/AVDC_change/flowdiffusion/datasets.py", line 391, in get_samples
    seq = self.sequences[idx] # 取某一个目录下的所有图片
IndexError: list index out of range
During handling of the above exception, another exception occurred:
Traceback (most recent call last):
  File "/home/hlwang/AVDC_change/flowdiffusion/datasets.py", line 406, in __getitem__
    samples, actions = self.get_samples(idx)
  File "/home/hlwang/AVDC_change/flowdiffusion/datasets.py", line 391, in get_samples
    seq = self.sequences[idx] # 取某一个目录下的所有图片
IndexError: list index out of range
During handling of the above exception, another exception occurred:
Traceback (most recent call last):
  File "/home/hlwang/miniconda3/envs/env/lib/python3.9/site-packages/torch/utils/data/_utils/worker.py", line 308, in _worker_loop
    data = fetcher.fetch(index)  # type: ignore[possibly-undefined]
  File "/home/hlwang/miniconda3/envs/env/lib/python3.9/site-packages/torch/utils/data/_utils/fetch.py", line 51, in fetch
    data = [self.dataset[idx] for idx in possibly_batched_index]
  File "/home/hlwang/miniconda3/envs/env/lib/python3.9/site-packages/torch/utils/data/_utils/fetch.py", line 51, in <listcomp>
    data = [self.dataset[idx] for idx in possibly_batched_index]
  File "/home/hlwang/AVDC_change/flowdiffusion/datasets.py", line 406, in __getitem__
    samples, actions = self.get_samples(idx)
  File "/home/hlwang/AVDC_change/flowdiffusion/datasets.py", line 406, in __getitem__
    samples, actions = self.get_samples(idx)
  File "/home/hlwang/AVDC_change/flowdiffusion/datasets.py", line 406, in __getitem__
    samples, actions = self.get_samples(idx)
  [Previous line repeated 95 more times]
  File "/home/hlwang/AVDC_change/flowdiffusion/datasets.py", line 416, in __getitem__
    return self.__getitem__(idx + 1 % self.__len__())
  File "/home/hlwang/AVDC_change/flowdiffusion/datasets.py", line 416, in __getitem__
    return self.__getitem__(idx + 1 % self.__len__())
  File "/home/hlwang/AVDC_change/flowdiffusion/datasets.py", line 416, in __getitem__
    return self.__getitem__(idx + 1 % self.__len__())
  [Previous line repeated 875 more times]
  File "/home/hlwang/AVDC_change/flowdiffusion/datasets.py", line 415, in __getitem__
    print(e)
  File "/home/hlwang/miniconda3/envs/env/lib/python3.9/site-packages/wandb/sdk/lib/redirect.py", line 645, in write
    self._old_write(data)
RecursionError: maximum recursion depth exceeded while calling a Python object